Workbook
Name 슬라이서_프로젝트명: #N/A
Name 품목: [2]구분표!#REF!
Name 품목: '[3]-'!#REF!

Sheet 갑지
A1: ■ 2026년 진행 중인 현장별 스크랩, 폐기물 입고 현황
J2: 46211
A3: NO. | B3: 프로젝트명 | C3: 스크랩 하차지 | E3: 스크랩 소계 | F3: 폐기물 하차지 | H3: 폐기물 소계 | I3: 총 입고량 | J3: 비고
C4: 원방 | D4: 거래처 | F4: 원방 | G4: 거래처
A5: =ROW()-4 -> 1 | B5: LT메탈 남동공장 | C5: =SUMIFS('기타 현장'!$N$4:$N$60,'기타 현장'!$D$4:$D$60,갑지!B5,'기타 현장'!E4:$E$60,"원방") -> 18410 | D5: =SUMIF('기타 현장'!$D$4:$D$60,갑지!B5,'기타 현장'!$N$4:$N$60)-갑지!C5 -> 0 | E5: =D5+C5 -> 18410 | F5: =SUMIFS('폐기물 입고'!$P$4:$P$70,'폐기물 입고'!$E$4:$E$70,갑지!B5,'폐기물 입고'!$G$4:$G$70,"원방") -> 0 | G5: =SUMIF('폐기물 입고'!$E$4:$E$70,갑지!B5,'폐기물 입고'!$P$4:$P$70)-갑지!F5 -> 0 | H5: =SUM(F5:G5) -> 0 | I5: =H5+E5 -> 18410 | J5: 기타 현장
A6: =ROW()-4 -> 2 | B6: 현대제철_대도_당진 | C6: =SUMIFS(스크랩입고량!$N$4:$N$228,스크랩입고량!$D$4:$D$228,갑지!B6,스크랩입고량!$E$4:$E$228,"원방") -> 2258 | D6: =현대_대도_당진!N2-갑지!C6 -> 226050 | E6: =D6+C6 -> 228308 | F6: =SUMIFS('폐기물 입고'!$P$4:$P$70,'폐기물 입고'!$E$4:$E$70,갑지!B6,'폐기물 입고'!$G$4:$G$70,"원방") -> 0 | G6: =SUMIF('폐기물 입고'!$E$4:$E$70,갑지!B6,'폐기물 입고'!$P$4:$P$70)-갑지!F6 -> 0 | H6: =SUM(F6:G6) -> 0 | I6: =H6+E6 -> 228308
A7: =ROW()-4 -> 3 | B7: 선진_식품기계_진천 | C7: =SUMIFS(스크랩입고량!$N$4:$N$228,스크랩입고량!$D$4:$D$228,갑지!B7,스크랩입고량!$E$4:$E$228,"원방") -> 98220 | D7: =선진_진천식품기계!N2-갑지!C7 -> 0 | E7: =D7+C7 -> 98220 | F7: =SUMIFS('폐기물 입고'!$P$4:$P$70,'폐기물 입고'!$E$4:$E$70,갑지!B7,'폐기물 입고'!$G$4:$G$70,"원방") -> 0 | G7: =SUMIF('폐기물 입고'!$E$4:$E$70,갑지!B7,'폐기물 입고'!$P$4:$P$70)-갑지!F7 -> 0 | H7: =SUM(F7:G7) -> 0 | I7: =H7+E7 -> 98220
A8: =ROW()-4 -> 4 | B8: 삼성전자_이텍솔루션_안성 | C8: =SUMIFS(스크랩입고량!$N$4:$N$228,스크랩입고량!$D$4:$D$228,갑지!B8,스크랩입고량!$E$4:$E$228,"원방") -> 118420 | D8: =삼성_이텍솔루션_안성!N2-갑지!C8 -> 0 | E8: =D8+C8 -> 118420 | F8: =SUMIFS('폐기물 입고'!$P$4:$P$70,'폐기물 입고'!$E$4:$E$70,갑지!B8,'폐기물 입고'!$G$4:$G$70,"원방") -> 0 | G8: =SUMIF('폐기물 입고'!$E$4:$E$70,갑지!B8,'폐기물 입고'!$P$4:$P$70)-갑지!F8 -> 0 | H8: =SUM(F8:G8) -> 0 | I8: =H8+E8 -> 118420 | J8: All 설비 반입
A9: =ROW()-4 -> 5 | B9: 포스코_KM_안산 | C9: =SUMIFS(스크랩입고량!$N$4:$N$228,스크랩입고량!$D$4:$D$228,갑지!B9,스크랩입고량!$E$4:$E$228,"원방") -> 84660 | D9: =포스코_KM안산!N2-갑지!C9 -> 1582811 | E9: =D9+C9 -> 1667471 | F9: =SUMIFS('폐기물 입고'!$P$4:$P$70,'폐기물 입고'!$E$4:$E$70,갑지!B9,'폐기물 입고'!$G$4:$G$70,"원방") -> 0 | G9: =SUMIF('폐기물 입고'!$E$4:$E$70,갑지!B9,'폐기물 입고'!$P$4:$P$70)-갑지!F9 -> 189120 | H9: =SUM(F9:G9) -> 189120 | I9: =H9+E9 -> 1856591
A10: =ROW()-4 -> 6 | B10: 동우PL1린텍_크로스_평택 | C10: =SUMIFS(스크랩입고량!$N$4:$N$228,스크랩입고량!$D$4:$D$228,갑지!B10,스크랩입고량!$E$4:$E$228,"원방") -> 9930 | D10: =동우PL1_평택!N2-갑지!C10 -> 104310 | E10: =D10+C10 -> 114240 | F10: =SUMIFS('폐기물 입고'!$P$4:$P$70,'폐기물 입고'!$E$4:$E$70,갑지!B10,'폐기물 입고'!$G$4:$G$70,"원방") -> 13200 | G10: =SUMIF('폐기물 입고'!$E$4:$E$70,갑지!B10,'폐기물 입고'!$P$4:$P$70)-갑지!F10 -> 466610 | H10: =SUM(F10:G10) -> 479810 | I10: =H10+E10 -> 594050
A11: =ROW()-4 -> 7 | B11: 잠실동 실내철거 | C11: =SUMIFS('기타 현장'!$N$4:$N$60,'기타 현장'!$D$4:$D$60,갑지!B11,'기타 현장'!E4:$E$60,"원방") -> 4690 | D11: =SUMIF('기타 현장'!$D$4:$D$60,갑지!B11,'기타 현장'!$N$4:$N$60)-갑지!C11 -> 0 | E11: =D11+C11 -> 4690 | F11: =SUMIFS('폐기물 입고'!$P$4:$P$70,'폐기물 입고'!$E$4:$E$70,갑지!B11,'폐기물 입고'!$G$4:$G$70,"원방") -> 0 | G11: =SUMIF('폐기물 입고'!$E$4:$E$70,갑지!B11,'폐기물 입고'!$P$4:$P$70)-갑지!F11 -> 0 | H11: =SUM(F11:G11) -> 0 | I11: =H11+E11 -> 4690 | J11: 기타 현장
A12: =ROW()-4 -> 8 | B12: LT메탈_인천 | C12: =SUMIFS('기타 현장'!$N$4:$N$60,'기타 현장'!$D$4:$D$60,갑지!B12,'기타 현장'!E4:$E$60,"원방") -> 58770 | D12: =SUMIF('기타 현장'!$D$4:$D$60,갑지!B12,'기타 현장'!$N$4:$N$60)-갑지!C12 -> 0 | E12: =D12+C12 -> 58770 | F12: =SUMIFS('폐기물 입고'!$P$4:$P$70,'폐기물 입고'!$E$4:$E$70,갑지!B12,'폐기물 입고'!$G$4:$G$70,"원방") -> 0 | G12: =SUMIF('폐기물 입고'!$E$4:$E$70,갑지!B12,'폐기물 입고'!$P$4:$P$70)-갑지!F12 -> 0 | H12: =SUM(F12:G12) -> 0 | I12: =H12+E12 -> 58770 | J12: 기타 현장
B13: 종료, 기타 현장 | E13: =스크랩입고량!N2-(갑지!E9+갑지!E10+E7+E8+갑지!E5+갑지!E6+갑지!E11+갑지!E12) -> -47192 | H13: =SUM(F13:G13) -> 0 | I13: =H13+E13 -> -47192
A14: 총 합계 | C14: =SUM(C5:C13) -> 395358 | D14: =SUM(D5:D13) -> 1913171 | E14: =SUM(E5:E13) -> 2261337 | F14: =SUM(F5:F13) -> 13200 | G14: =SUM(G5:G13) -> 655730 | H14: =SUM(H5:H13) -> 668930 | I14: =SUM(I5:I13) -> 2930267
A15: ※ 종료된 현장 제외 | J15: 단위 : kg
B17: ■ 폐기물 프로젝트별 제품 입고량
B19: 프로젝트명 | C19: 동우PL1린텍_크로스_평택 | E19: 프로젝트명 | F19: 포스코_KM_안산
B20: 올바로 | C20: O | E20: 올바로 | F20: O
B22: 제품명 | C22: 합계 : 입고량(kg) | E22: 제품명 | F22: 합계 : 입고량(kg)
B23: 페이퍼허니컴판넬 | C23: 158230 | E23: 폐아스콘 | F23: 34220
B24: 폐콘크리트 | C24: 273390 | E24: 폐콘크리트 | F24: 38560
B25: 폐판넬 | C25: 30570 | E25: 폐판넬 | F25: 17860
B26: 총합계 | C26: 462190 | E26: 폐합성수지 | F26: 29320
E27: 총합계 | F27: 119960
B29: ※ "폐기물 입고" 시트에 추가 시 "갑지"에서 입고량 표 마우스 우측 눌러 "새로고침" 필요함.
B32: ■ 현대제철 철거공사 제품별 스크랩 반입량 | F32: ■ 포스코 STS사업실 안산공장 철거 제품별 스크랩 반입량
B34: =현대_대도_당진!F31 -> 제품 | C34: =현대_대도_당진!G31 -> 반입량(kg) | D34: =현대_대도_당진!H31 -> 비율 | F34: =포스코_KM안산!F117 -> 제품 | G34: =포스코_KM안산!G117 -> 반입량(kg) | H34: =포스코_KM안산!H117 -> 비율
B35: =현대_대도_당진!F32 -> 고철 | C35: =현대_대도_당진!G32 -> 227150 | D35: =현대_대도_당진!H32 -> 0.9949279 | F35: =포스코_KM안산!F118 -> 고철 | G35: =포스코_KM안산!G118 -> 1459940 | H35: =포스코_KM안산!H118 -> 0.87554146
B36: =현대_대도_당진!F33 -> 비철 | C36: =현대_대도_당진!G33 -> 1158 | D36: =현대_대도_당진!H33 -> 0.0050720956 | F36: =포스코_KM안산!F119 -> 스텐 | G36: =포스코_KM안산!G119 -> 17411 | H36: =포스코_KM안산!H119 -> 0.010441561
B37: =현대_대도_당진!F34 -> 합계 | C37: =현대_대도_당진!G34 -> 228308 | D37: =현대_대도_당진!H34 -> 1 | F37: =포스코_KM안산!F120 -> 비철 | G37: =포스코_KM안산!G120 -> 190120 | H37: =포스코_KM안산!H120 -> 0.11401698
F38: =포스코_KM안산!F121 -> 합계 | G38: =포스코_KM안산!G121 -> 0 | H38: =포스코_KM안산!H121 -> 1
B40: ■ 동우 PL1린텍 철거 제품별 스크랩 반입량
B42: =동우PL1_평택!F28 -> 제품 | C42: =동우PL1_평택!G28 -> 반입량(kg) | D42: =동우PL1_평택!H28 -> 비율
B43: =동우PL1_평택!F29 -> 고철 | C43: =동우PL1_평택!G29 -> 107800 | D43: =동우PL1_평택!H29 -> 0.94362745
B44: =동우PL1_평택!F30 -> 비철 | C44: =동우PL1_평택!G30 -> 6440 | D44: =동우PL1_평택!H30 -> 0.056372549
B45: =동우PL1_평택!F31 -> 합계 | C45: =동우PL1_평택!G31 -> 114240 | D45: =동우PL1_평택!H31 -> 1
B48: ■ 기타현장(단발성) 제품별 스크랩 반입량 | H48: ■ 기타현장 제품별 반입량 | J48: ※ 참고용 자료("스크랩 입고량"시트에는 일부 삭제 되어 있음)
B50: 합계 : 입고량(Kg) | C50: 프로젝트명 | H50: 합계 : 입고량(kg) | I50: 프로젝트명
B51: 제품명 | C51: 듀폰_천안 | D51: 에코코리아 | E51: 한성상 | F51: 총합계 | H51: 제품명 | I51: LT메탈 남동공장 | J51: LT메탈_인천 | K51: 삼성_대도_온양 | L51: 삼성바이오_대도_송도 | M51: 잠실동 실내철거 | N51: 총합계
B52: AL A | D52: 1306 | F52: 1306 | H52: 고철(H빔) | K52: 21270 | N52: 21270
...

Sheet 폐기물 입고
A1: □ 2026년 현장 폐기물 입고 현황
O2: =SUBTOTAL(9,O4:O587) -> 0 | P2: =SUBTOTAL(9,P4:P587) -> 668930
A3: NO. | B3: 인수일 | C3: 인계일 | D3: 올바로 | E3: 프로젝트명 | F3: 배출자 | G3: 하차지 | H3: 차종 | I3: 차량번호 | J3: 운전자 | K3: 연락처 | L3: 제품명 | M3: 총중량(kg) | N3: 공차중량(kg) | O3: 감량(kg) | P3: 입고량(kg) | Q3: 비고
A4: =ROW()-3 -> 1 | B4: 46146 | C4: 46146 | E4: 동우PL1린텍_크로스_평택 | F4: 원방 | G4: 주원 | H4: 암롤트럭 | I4: 경기85사3405 | J4: 김태정 | K4: 010-3311-8084 | L4: 폐합성수지 | M4: 25590 | N4: 21170 | P4: =M4-N4 -> 4420 | Q4: 4/30현장출고, 5/4 원방에서 주원 출고, 포스코계근 3,910kg
A5: =ROW()-3 -> 2 | B5: 46146 | C5: 46146 | D5: O | E5: 포스코_KM_안산 | F5: 케이엠티엘에스 | G5: 투플러스 | H5: 암롤트럭 | I5: 86노1445 | J5: 김태정 | K5: 010-3311-8084 | L5: 폐판넬 | M5: 24520 | N5: 20110 | P5: =M5-N5 -> 4410 | Q5: 직납, 포스코 계근 3,600kg
A6: =ROW()-3 -> 3 | B6: 46146 | C6: 46147 | D6: O | E6: 포스코_KM_안산 | F6: 케이엠티엘에스 | G6: 투플러스 | H6: 암롤트럭 | I6: 86노1445 | J6: 김태정 | K6: 010-3311-8084 | L6: 폐판넬 | M6: 25490 | N6: 20800 | P6: =M6-N6 -> 4690 | Q6: 5/4 상차, 포스코계근 5,440kg
A7: =ROW()-3 -> 4 | B7: 46148 | C7: 46148 | D7: O | E7: 포스코_KM_안산 | F7: 케이엠티엘에스 | G7: 투플러스 | H7: 암롤트럭 | I7: 86노1445 | J7: 김태정 | K7: 010-3311-8084 | L7: 폐판넬 | M7: 24220 | N7: 20010 | P7: =M7-N7 -> 4210 | Q7: 직납, 포스코 계근 4,140kg 70kg차이
A8: =ROW()-3 -> 5 | B8: 46149 | C8: 46149 | D8: O | E8: 포스코_KM_안산 | F8: 케이엠티엘에스 | G8: 도솔환경산업 | H8: 암롤트럭 | I8: 86노1445 | J8: 김태정 | K8: 010-3311-8084 | L8: 폐콘크리트 | M8: 35520 | N8: 20940 | P8: =M8-N8 -> 14580 | Q8: 포스코 계근 14,580kg, 내화벽돌
A9: =ROW()-3 -> 6 | B9: 46149 | C9: 46150 | D9: O | E9: 포스코_KM_안산 | F9: 케이엠티엘에스 | G9: 투플러스 | H9: 암롤트럭 | I9: 86노1445 | J9: 김태정 | K9: 010-3311-8084 | L9: 폐판넬 | M9: 24650 | N9: 20100 | P9: =M9-N9 -> 4550 | Q9: 명일 5/8 하차
A10: =ROW()-3 -> 7 | B10: 46153 | C10: 46153 | D10: O | E10: 포스코_KM_안산 | F10: 케이엠티엘에스 | G10: 주원 | H10: 암롤트럭 | I10: 86노1445 | J10: 이민수 | K10: 010-9992-4447 | L10: 폐합성수지 | M10: 33270 | N10: 20920 | P10: =M10-N10 -> 12350 | Q10: 직납, 주원 계근
A11: =ROW()-3 -> 8 | B11: 46154 | C11: 46154 | D11: O | E11: 동우PL1린텍_크로스_평택 | F11: 크로스특수 | G11: 투플러스 | H11: 암롤트럭 | I11: 86노1445 | J11: 이민수 | K11: 010-9992-4447 | L11: 페이퍼허니컴판넬 | M11: 28340 | N11: 20120 | P11: =M11-N11 -> 8220 | Q11: 50루베(m³)직납, 동우 계근 8,220kg
A12: =ROW()-3 -> 9 | B12: 46154 | C12: 46154 | D12: O | E12: 동우PL1린텍_크로스_평택 | F12: 크로스특수 | G12: 투플러스 | H12: 집게차 | I12: 87주8410 | J12: 배민국 | K12: 010-9110-0126 | L12: 페이퍼허니컴판넬 | M12: 19510 | N12: 14080 | P12: =M12-N12 -> 5430 | Q12: 35루베, 직납, 동우 계근 5,420kg
A13: =ROW()-3 -> 10 | B13: 46155 | C13: 46155 | D13: O | E13: 동우PL1린텍_크로스_평택 | F13: 크로스특수 | G13: 투플러스 | H13: 암롤트럭 | I13: 86노1445 | J13: 이민수 | K13: 010-9992-4447 | L13: 페이퍼허니컴판넬 | M13: 27600 | N13: 20160 | P13: =M13-N13 -> 7440 | Q13: 50루베, 직납, 동우 계근 7,440kg
A14: =ROW()-3 -> 11 | B14: 46155 | C14: 46155 | D14: O | E14: 동우PL1린텍_크로스_평택 | F14: 크로스특수 | G14: 투플러스 | H14: 집게차 | I14: 87주8410 | J14: 배민국 | K14: 010-9110-0126 | L14: 페이퍼허니컴판넬 | M14: 18400 | N14: 14080 | P14: =M14-N14 -> 4320 | Q14: 35루베 직납, 동우 계근표 분실
A15: =ROW()-3 -> 12 | B15: 46156 | C15: 46156 | D15: O | E15: 동우PL1린텍_크로스_평택 | F15: 크로스특수 | G15: 투플러스 | H15: 암롤트럭 | I15: 86노1445 | J15: 이민수 | K15: 010-9992-4447 | L15: 페이퍼허니컴판넬 | M15: 27440 | N15: 20160 | P15: =M15-N15 -> 7280 | Q15: 50루베, 직납
A16: =ROW()-3 -> 13 | B16: 46156 | C16: 46156 | D16: O | E16: 동우PL1린텍_크로스_평택 | F16: 크로스특수 | G16: 투플러스 | H16: 집게차 | I16: 87주8410 | J16: 배민국 | K16: 010-9110-0126 | L16: 페이퍼허니컴판넬 | M16: 18560 | N16: 13990 | P16: =M16-N16 -> 4570 | Q16: 35루베 직납, 동우 계근표 분실
... A24: =ROW()-3 -> 21 | B24: 46160 | C24: 46160 | D24: O | E24: 동우PL1린텍_크로스_평택 | F24: 크로스특수 | G24: 도솔환경산업 | H24: 암롤트럭 | I24: 86노1445 | J24: 이민수 | K24: 010-9992-4447 | L24: 폐콘크리트 | M24: 44150 | N24: 20130 | P24: =M24-N24 -> 24020 | Q24: 동우 계근 x, 17루베
A25: =ROW()-3 -> 22 | B25: 46160 | C25: 46160 | D25: O | E25: 동우PL1린텍_크로스_평택 | F25: 크로스특수 | G25: 도솔환경산업 | H25: 방통차 | I25: 충남06노1592 | J25: 전종식 | L25: 폐콘크리트 | M25: 35960 | N25: 14560 | P25: =M25-N25 -> 21400 | Q25: 동우 계근 x
A26: =ROW()-3 -> 23 | B26: 46160 | C26: 46160 | D26: O | E26: 동우PL1린텍_크로스_평택 | F26: 크로스특수 | G26: 도솔환경산업 | H26: 방통차 | I26: 충남06모5639 | J26: 조성환 | L26: 폐콘크리트 | M26: 38690 | N26: 14890 | P26: =M26-N26 -> 23800 | Q26: 동우 계근 x
A27: =ROW()-3 -> 24 | B27: 46160 | C27: 46160 | D27: O | E27: 동우PL1린텍_크로스_평택 | F27: 크로스특수 | G27: 도솔환경산업 | H27: 방통차 | I27: 충남06고1626 | J27: 양명석 | L27: 폐콘크리트 | M27: 35460 | N27: 14660 | P27: =M27-N27 -> 20800 | Q27: 동우 계근 x
A28: =ROW()-3 -> 25 | B28: 46160 | C28: 46160 | D28: O | E28: 동우PL1린텍_크로스_평택 | F28: 크로스특수 | G28: 도솔환경산업 | H28: 방통차 | I28: 충남06노1598 | J28: 임지환 | L28: 폐콘크리트 | M28: 41940 | N28: 15680 | P28: =M28-N28 -> 26260 | Q28: 동우 계근 x
A29: =ROW()-3 -> 26 | B29: 46161 | C29: 46161 | D29: O | E29: 동우PL1린텍_크로스_평택 | F29: 크로스특수 | G29: 도솔환경산업 | H29: 방통차 | I29: 충남06노1592 | J29: 전종식 | L29: 폐콘크리트 | M29: 38290 | N29: 14560 | P29: =M29-N29 -> 23730 | Q29: 동우 계근 x
A30: =ROW()-3 -> 27 | B30: 46161 | C30: 46161 | D30: O | E30: 동우PL1린텍_크로스_평택 | F30: 크로스특수 | G30: 도솔환경산업 | H30: 방통차 | I30: 충남06노1598 | J30: 임지환 | L30: 폐콘크리트 | M30: 39530 | N30: 15680 | P30: =M30-N30 -> 23850 | Q30: 동우 계근 x
A31: =ROW()-3 -> 28 | B31: 46161 | C31: 46161 | D31: O | E31: 동우PL1린텍_크로스_평택 | F31: 크로스특수 | G31: 도솔환경산업 | H31: 방통차 | I31: 충남06고1626 | J31: 양명석 | L31: 폐콘크리트 | M31: 39390 | N31: 14660 | P31: =M31-N31 -> 24730 | Q31: 동우 계근 x
A32: =ROW()-3 -> 29 | B32: 46161 | C32: 46161 | D32: O | E32: 동우PL1린텍_크로스_평택 | F32: 크로스특수 | G32: 도솔환경산업 | H32: 방통차 | I32: 충남06고3191 | J32: 이준호 | L32: 폐콘크리트 | M32: 40120 | N32: 14570 | P32: =M32-N32 -> 25550 | Q32: 동우 계근 x
A33: =ROW()-3 -> 30 | B33: 46161 | C33: 46161 | D33: O | E33: 동우PL1린텍_크로스_평택 | F33: 크로스특수 | G33: 도솔환경산업 | H33: 방통차 | I33: 충남06노1592 | J33: 전종식 | L33: 폐콘크리트 | M33: 37840 | N33: 14560 | P33: =M33-N33 -> 23280 | Q33: 동우 계근 x
A34: =ROW()-3 -> 31 | B34: 46161 | C34: 46161 | D34: O | E34: 동우PL1린텍_크로스_평택 | F34: 크로스특수 | G34: 도솔환경산업 | H34: 방통차 | I34: 충남06노1598 | J34: 임지환 | L34: 폐콘크리트 | M34: 40420 | N34: 15680 | P34: =M34-N34 -> 24740 | Q34: 동우 계근 x
A35: =ROW()-3 -> 32 | B35: 46161 | C35: 46161 | D35: O | E35: 동우PL1린텍_크로스_평택 | F35: 크로스특수 | G35: 도솔환경산업 | H35: 방통차 | I35: 충남06고1626 | J35: 양명석 | L35: 폐콘크리트 | M35: 25890 | N35: 14660 | P35: =M35-N35 -> 11230 | Q35: 동우 계근 x
A36: =ROW()-3 -> 33 | B36: 46161 | C36: 46161 | D36: X | E36: 동우PL1린텍_크로스_평택 | G36: 원방 | H36: 집게차 | I36: 87주8410 | J36: 배민국 | K36: 010-9110-0126 | L36: 폐기물 | M36: 18510 | N36: 15020 | P36: =M36-N36 -> 3490 | Q36: 동우 계근 3,420kg, 5/20 주원으로 출고 예정
A37: =ROW()-3 -> 34 | B37: 46161 | D37: X | E37: 포스코_KM_안산 | G37: 한강그린 | H37: 탱크로리 | I37: 84두0416 | L37: 절연유 | M37: 27820 | N37: 15220 | P37: =M37-N37 -> 12600 | Q37: 무상, 변압기랑 일괄 계산
A38: =ROW()-3 -> 35 | B38: 46163 | C38: 46163 | D38: O | E38: 포스코_KM_안산 | F38: 케이엠티엘에스 | G38: 도솔환경산업 | H38: 암롤트럭 | I38: 86노1445 | J38: 이민수 | K38: 010-9992-4447 | L38: 폐콘크리트 | M38: 44110 | N38: 20130 | P38: =M38-N38 -> 23980 | Q38: 포스코 계근 18,020kg
A39: =ROW()-3 -> 36 | B39: 46164 | C39: 46164 | D39: O | E39: 포스코_KM_안산 | F39: 케이엠티엘에스 | G39: 주원 | H39: 암롤트럭 | I39: 86노1445 | J39: 이민수 | K39: 010-9992-4447 | L39: 폐합성수지 | M39: 37660 | N39: 20690 | P39: =M39-N39 -> 16970 | Q39: 동우 계근 x
A40: =ROW()-3 -> 37 | B40: 46168 | C40: 46168 | D40: X | E40: 동우PL1린텍_크로스_평택 | G40: 원방 | H40: 집게차 | I40: 96거5789 | J40: 배민국 | K40: 010-9110-0126 | L40: 고철 | M40: 19660 | N40: 15080 | P40: =M40-N40 -> 4580 | Q40: 폐기물 1차 4,580kg 하차, 원방 계근
A41: =ROW()-3 -> 38 | B41: 46171 | C41: 46171 | D41: O | E41: 포스코_KM_안산 | F41: 케이엠티엘에스 | G41: 도솔환경산업 | H41: 덤프트럭 | I41: 충남06노1598 | L41: 폐아스콘 | M41: 23000 | N41: 14560 | P41: =M41-N41 -> 8440 | Q41: 도솔 계근
A42: =ROW()-3 -> 39 | B42: 46171 | C42: 46171 | D42: O | E42: 포스코_KM_안산 | F42: 케이엠티엘에스 | G42: 도솔환경산업 | H42: 덤프트럭 | I42: 충남06고1626 | L42: 폐아스콘 | M42: 26910 | N42: 14660 | P42: =M42-N42 -> 12250 | Q42: 도솔 계근
A43: =ROW()-3 -> 40 | B43: 46171 | C43: 46171 | D43: O | E43: 포스코_KM_안산 | F43: 케이엠티엘에스 | G43: 도솔환경산업 | H43: 덤프트럭 | I43: 충남06노1592 | L43: 폐아스콘 | M43: 28090 | N43: 14560 | P43: =M43-N43 -> 13530 | Q43: 도솔 계근
A44: =ROW()-3 -> 41 | B44: 46178 | C44: 46178 | D44: O | E44: 동우PL1린텍_크로스_평택 | F44: 크로스특수 | G44: 투플러스 | H44: 암롤트럭 | I44: 86노1445 | J44: 김현수 | K44: 010-5315-1508 | L44: 페이퍼허니컴판넬 | M44: 29210 | N44: 20890 | P44: =M44-N44 -> 8320 | Q44: 투플 계근, 동우 8,350kg
A45: =ROW()-3 -> 42 | B45: 46178 | C45: 46178 | D45: O | E45: 동우PL1린텍_크로스_평택 | F45: 크로스특수 | G45: 투플러스 | H45: 집게차 | I45: 84나4888 | J45: 이민규 | K45: 010-5899-9660 | L45: 페이퍼허니컴판넬 | M45: 27040 | N45: 21370 | P45: =M45-N45 -> 5670 | Q45: 투플 계근, 동우 5,630kg
A46: =ROW()-3 -> 43 | B46: 46181 | D46: X | E46: 동우PL1린텍_크로스_평택 | G46: 원방 | H46: 집게차 | I46: 87주8410 | J46: 배민국 | K46: 010-9110-0126 | L46: 폐판넬 | M46: 15860 | N46: 14050 | P46: =M46-N46 -> 1810 | Q46: 동우 계근 1,770kg, 6/17 투플 이동
A47: =ROW()-3 -> 44 | B47: 46182 | C47: 46182 | D47: O | E47: 동우PL1린텍_크로스_평택 | F47: 크로스특수 | G47: 투플러스 | H47: 암롤트럭 | I47: 86노1445 | J47: 김현수 | K47: 010-5315-1508 | L47: 페이퍼허니컴판넬 | M47: 30010 | N47: 20160 | P47: =M47-N47 -> 9850 | Q47: 투플 계근, 동우 9,860kg
...

Sheet 스크랩입고량
A1: □ 2026년 현장 스크랩 입고 현황
M2: =SUBTOTAL(9,M4:M275) -> 12673 | N2: =SUBTOTAL(9,N4:N275) -> 2261337 | O2: ※ 비고에서 기타현장, 단발성 현장 검색 가능
A3: NO | B3: NO (2) | C3: 상차일 | D3: 프로젝트명 | E3: 하차지 | F3: 차종 | G3: 차량번호 | H3: 운전자 | I3: 연락처 | J3: 제품명 | K3: 총중량(kg) | L3: 공차중량(kg) | M3: 감량(kg) | N3: 입고량(kg) | O3: 비고
A4: =ROW()-3 -> 1 | C4: 46146 | D4: 포스코_KM_안산 | E4: 선진알앤디 | F4: 집게차 | G4: 87주8410 | H4: 배민국 | I4: 010-9110-0126 | J4: 고철(경B) | K4: 17920 | L4: 14120 | N4: 3800 | O4: 원방에서 계근 후 직납, 포스코 계근과 동일
A5: =ROW()-3 -> 2 | C5: 46146 | D5: 포스코_KM_안산 | E5: 원방 | F5: 카고 | G5: 경기89사3442 | J5: 전선, 신주 | K5: 16250 | L5: 15120 | N5: 1130 | O5: 신주 일부 포함, 포스코 계근 7,060kg
A6: =ROW()-3 -> 3 | C6: 46146 | D6: 포스코_KM_안산 | E6: 원방 | F6: 카고 | G6: 경기89사3442 | J6: 알루미늄 | K6: 12340 | L6: 11610 | M6: 500 | N6: 230 | O6: 양중박스 1개 감량, 분류계근
A7: =ROW()-3 -> 4 | C7: 46146 | D7: 포스코_KM_안산 | E7: 원방 | F7: 카고 | G7: 경기89사3442 | J7: 모터 | K7: 15130 | L7: 8720 | M7: 500 | N7: 5680 | O7: 양중박스, AL 분류계근 건 차감
A8: =ROW()-3 -> 5 | C8: 46147 | D8: 포스코_KM_안산 | E8: 세화철강 | F8: 집게차 | G8: 87주8410 | H8: 배민국 | I8: 010-9110-0126 | J8: 고철(경A) | K8: 17620 | L8: 14220 | N8: 3400 | O8: 세화 계근3,370kg
A9: =ROW()-3 -> 6 | C9: 46148 | D9: 포스코_KM_안산 | E9: 원방 | F9: 카고 | G9: 경북86아9491 | J9: 탱크 | K9: 36330 | L9: 15890 | N9: 20440 | O9: 포스코 계근 20,440kg 동일
A10: =ROW()-3 -> 7 | C10: 46148 | D10: 포스코_KM_안산 | E10: 원방 | F10: 카고 | G10: 경기91사3176 | J10: 탱크 | K10: 26120 | L10: 15780 | N10: 10340 | O10: 포스코계근 10,300kg 40kg 차이
A11: =ROW()-3 -> 8 | C11: 46148 | D11: 포스코_KM_안산 | E11: 원방 | F11: 집게차 | G11: 96거5789 | H11: 배민국 | I11: 010-9110-0126 | J11: 스크랩 | K11: 17640 | L11: 13470 | N11: 4170 | O11: 포스코 계근 4,120kg 50kg 차이, 5/7하차, sus304(1,790kg) 작업철(2,380kg)예상-분류계근 예정
A12: =ROW()-3 -> 9 | C12: 46149 | D12: 포스코_KM_안산 | E12: 원방 | F12: 카고 | G12: 충남80아2457 | H12: 조병순 | I12: 010-8804-1441 | J12: 모터 | K12: 19470 | L12: 9240 | M12: 1000 | N12: 7400 | O12: 전선 분류계근량 1,830kg 차감
A13: =ROW()-3 -> 10 | C13: 46149 | D13: 포스코_KM_안산 | E13: 원방 | F13: 카고 | G13: 충남80아2457 | H13: 조병순 | I13: 010-8804-1441 | J13: 전선 | K13: 13890 | L13: 11560 | M13: 500 | N13: 1830 | O13: 지게차 분류계근
A14: =ROW()-3 -> 11 | C14: 46150 | D14: 기타 현장 | E14: 원방 | F14: 카고 | G14: 대전88아5577 | H14: 우제훈 | I14: 010-5678-7363 | J14: 설비 | K14: 15340 | L14: 8880 | N14: 6460 | O14: LT메탈 남동공장, 파렛트 3개, 설비5ct
A15: =ROW()-3 -> 12 | C15: 46150 | D15: 기타 현장 | E15: 원방 | F15: 카고 | G15: 충남80아3986 | H15: 이창용 | I15: 010-3464-3558 | J15: 설비 | K15: 13640 | L15: 8440 | N15: 5200 | O15: LT메탈 남동공장, 소결로 2ea(2.7t, 3.4t)
A16: =ROW()-3 -> 13 | C16: 46150 | D16: 기타 현장 | E16: 원방 | F16: 카고 | G16: 충남80바3775 | H16: 차상철 | I16: 010-7413-4241 | J16: 설비 | K16: 14310 | L16: 9360 | N16: 4950 | O16: LT메탈 남동공장, 소결로 2ea(2.7t, 3.4t)
A17: =ROW()-3 -> 14 | C17: 46150 | D17: 기타 현장 | E17: 원방 | F17: 카고 | G17: 충남80아3062 | H17: 박오열 | I17: 010-4470-7920 | J17: 스크랩 | K17: 10510 | L17: 8710 | N17: 1800 | O17: LT메탈 남동공장, 잡자재
A18: =ROW()-3 -> 15 | C18: 46151 | D18: 포스코_KM_안산 | E18: 원방 | F18: 카고 | G18: 충남80아2329 | J18: 작업철 | K18: 17840 | L18: 9870 | N18: 7090
A19: =ROW()-3 -> 16 | C19: 46151 | D19: 포스코_KM_안산 | E19: 원방 | F19: 카고 | G19: 충남80아2329 | J19: 신주 | K19: 11850 | L19: 11550 | N19: 300 | O19: 지게차 분류계근
A20: =ROW()-3 -> 17 | C20: 46151 | D20: 포스코_KM_안산 | E20: 원방 | F20: 카고 | G20: 충남80아2329 | J20: 상동 | K20: 11730 | L20: 11550 | N20: 180 | O20: 지게차 분류계근
A21: =ROW()-3 -> 18 | C21: 46151 | D21: 포스코_KM_안산 | E21: 원방 | F21: 카고 | G21: 충남80아2329 | J21: 전선 | K21: 11950 | L21: 11550 | N21: 400 | O21: 지게차 분류계근
A22: =ROW()-3 -> 19 | C22: 46154 | D22: 포스코_KM_안산 | E22: 원방 | F22: 카고 | G22: 충남83아1609 | H22: 심재철 | I22: 010-9390-2824 | J22: 모터 | K22: 15480 | L22: 9520 | M22: 1500 | N22: 2020 | O22: 파란 양중박스 3개, 포스코 계근 5,940kg
A23: =ROW()-3 -> 20 | C23: 46154 | D23: 포스코_KM_안산 | E23: 원방 | F23: 카고 | G23: 충남83아1609 | H23: 심재철 | I23: 010-9390-2824 | J23: 전선 | K23: 11730 | L23: 11520 | N23: 210 | O23: 지게차 분류계근
A24: =ROW()-3 -> 21 | C24: 46154 | D24: 포스코_KM_안산 | E24: 원방 | F24: 카고 | G24: 충남83아1609 | H24: 심재철 | I24: 010-9390-2824 | J24: 전선 등 | K24: 13480 | L24: 11520 | M24: 500 | N24: 1460 | O24: 지게차 분류계근, 고철 일부 포함
A25: =ROW()-3 -> 22 | C25: 46154 | D25: 포스코_KM_안산 | E25: 원방 | F25: 카고 | G25: 충남83아1609 | H25: 심재철 | I25: 010-9390-2824 | J25: 전선 등 | K25: 12790 | L25: 11520 | M25: 500 | N25: 770 | O25: 지게차 분류계근, 고철 일부 포함
A26: =ROW()-3 -> 23 | C26: 46155 | D26: 포스코_KM_안산 | E26: 세화철강 | F26: 방통차 | G26: 경기90자2889 | J26: 고철(중량) | K26: 42920 | L26: 18700 | N26: 24220
A27: =ROW()-3 -> 24 | C27: 46155 | D27: 포스코_KM_안산 | E27: 세화철강 | F27: 방통차 | G27: 경기80바7145 | J27: 고철(중량) | K27: 43200 | L27: 18520 | N27: 24680
A28: =ROW()-3 -> 25 | C28: 46155 | D28: 포스코_KM_안산 | E28: 원방 | F28: 카고 | G28: 충남94바2021 | J28: 작업철 | K28: 12470 | L28: 8030 | M28: 1000 | N28: 2100 | O28: 포스코계근 동일, 전선 차감, 양중박스 2개 감량
A29: =ROW()-3 -> 26 | C29: 46155 | D29: 포스코_KM_안산 | E29: 원방 | F29: 카고 | G29: 충남94바2021 | J29: 전선 | K29: 13390 | L29: 11550 | M29: 500 | N29: 1340 | O29: 지게차 계근, 양중박스 감량
A30: =ROW()-3 -> 27 | C30: 46155 | D30: 포스코_KM_안산 | E30: 세화철강 | F30: 방통차 | G30: 충북91아2060 | J30: 고철(중량) | K30: 43960 | L30: 18140 | N30: 25820
A31: =ROW()-3 -> 28 | C31: 46155 | D31: 포스코_KM_안산 | E31: 세화철강 | F31: 방통차 | G31: 서울82바4890 | J31: 고철(중량) | K31: 43520 | L31: 18460 | N31: 25060
A32: =ROW()-3 -> 29 | C32: 46155 | D32: 포스코_KM_안산 | E32: 세화철강 | F32: 방통차 | G32: 서울88아4910 | J32: 고철(중량) | K32: 43200 | L32: 17940 | N32: 25260
A33: =ROW()-3 -> 30 | C33: 46155 | D33: 포스코_KM_안산 | E33: 세화철강 | F33: 방통차 | G33: 인천80자1904 | H33: 배조성 | I33: 010-4737-6803 | J33: 고철(중량) | K33: 42920 | L33: 18540 | N33: 24380
A34: =ROW()-3 -> 31 | C34: 46155 | D34: 포스코_KM_안산 | E34: 세화철강 | F34: 방통차 | G34: 인천80사7274 | J34: 고철(중량) | K34: 42760 | L34: 18300 | N34: 24460
A35: =ROW()-3 -> 32 | C35: 46155 | D35: 포스코_KM_안산 | E35: 세화철강 | F35: 방통차 | G35: 경기90자2889 | J35: 고철(중량) | K35: 42660 | L35: 18580 | N35: 24080
A36: =ROW()-3 -> 33 | C36: 46155 | D36: 포스코_KM_안산 | E36: 세화철강 | F36: 방통차 | G36: 경기80바7145 | J36: 고철(중량) | K36: 43320 | L36: 18360 | N36: 24960
A37: =ROW()-3 -> 34 | C37: 46155 | D37: 포스코_KM_안산 | E37: 세화철강 | F37: 방통차 | G37: 서울87아8165 | J37: 고철(중량) | K37: 42880 | L37: 18500 | N37: 24380
A38: =ROW()-3 -> 35 | C38: 46156 | D38: 포스코_KM_안산 | E38: 세화철강 | F38: 방통차 | G38: 서울87아8165 | J38: 고철(중량) | K38: 42800 | L38: 18500 | N38: 24300
A39: =ROW()-3 -> 36 | C39: 46156 | D39: 포스코_KM_안산 | E39: 세화철강 | F39: 방통차 | G39: 서울82바4890 | J39: 고철(중량) | K39: 43060 | L39: 18500 | N39: 24560
A40: =ROW()-3 -> 37 | C40: 46156 | D40: 포스코_KM_안산 | E40: 세화철강 | F40: 방통차 | G40: 경기80바7145 | J40: 고철(중량) | K40: 42500 | L40: 18380 | N40: 24120
...

Sheet 현대_대도_당진
A1: □ 현대제철 신규편입 토지 철거공사 스크랩 반입일보 (26/04/21 ~ )
M2: =SUBTOTAL(9,M4:M576) -> 12 | N2: =SUBTOTAL(9,N4:N576) -> 228308
A3: NO (1) | B3: NO (2) | C3: 상차일 | D3: 프로젝트명 | E3: 하차지 | F3: 차종 | G3: 차량번호 | H3: 운전자 | I3: 연락처 | J3: 제품명 | K3: 총중량(kg) | L3: 공차중량(kg) | M3: 감량(kg) | N3: 입고량(kg) | O3: 비고
A4: =ROW()-3 -> 1 | B4: 1 | C4: 46163 | D4: 현대제철_대도_당진 | E4: 원방 | J4: 폐전선 | K4: 11710 | L4: 11590 | M4: 12 | N4: =K4-L4-M4 -> 108 | O4: 파렛트 2개 감량
A5: =ROW()-3 -> 2 | B5: 1 | C5: 46170 | D5: 현대제철_대도_당진 | E5: 세화철강 | F5: 방통차 | G5: 대전87아5426 | J5: 고철(철근) | K5: 37650 | L5: 18760 | N5: =K5-L5-M5 -> 18890 | O5: 송악계량증명소 계근
A6: =ROW()-3 -> 3 | B6: 2 | C6: 46170 | D6: 현대제철_대도_당진 | E6: 세화철강 | F6: 방통차 | G6: 충남94바3226 | H6: 노성래 | I6: 010-5421-2238 | J6: 고철(빔장척) | K6: 30830 | L6: 17780 | N6: =K6-L6-M6 -> 13050 | O6: 송악계량증명소 계근
A7: =ROW()-3 -> 4 | B7: 3 | C7: 46170 | D7: 현대제철_대도_당진 | E7: 세화철강 | F7: 방통차 | G7: 충남82바1054 | H7: 한창용 | I7: 010-2566-7740 | J7: 고철(빔장척) | K7: 28620 | L7: 18050 | N7: =K7-L7-M7 -> 10570 | O7: 송악계량증명소 계근
A8: =ROW()-3 -> 5 | B8: 4 | C8: 46170 | D8: 현대제철_대도_당진 | E8: 세화철강 | F8: 방통차 | G8: 경기96자1089 | H8: 서건식 | I8: 010-9037-6416 | J8: 고철(빔장척) | K8: 30820 | L8: 18780 | N8: =K8-L8-M8 -> 12040 | O8: 송악계량증명소 계근
A9: =ROW()-3 -> 6 | B9: 5 | C9: 46170 | D9: 현대제철_대도_당진 | E9: 세화철강 | F9: 방통차 | G9: 충남80바2810 | H9: 김상철 | I9: 010-7107-6000 | J9: 고철(빔장척) | K9: 29070 | L9: 18800 | N9: =K9-L9-M9 -> 10270 | O9: 송악계량증명소 계근
A10: =ROW()-3 -> 7 | B10: 6 | C10: 46170 | D10: 현대제철_대도_당진 | E10: 세화철강 | F10: 집게차 | G10: 87주8410 | H10: 배민국 | I10: 010-9110-0126 | J10: 고철(경A) | K10: 16320 | L10: 13960 | N10: =K10-L10-M10 -> 2360 | O10: 세화 계근
A11: =ROW()-3 -> 8 | B11: 7-1 | C11: 46170 | D11: 현대제철_대도_당진 | E11: 원방 | F11: 집게차 | G11: 84나4888 | H11: 이민규 | I11: 010-5315-1508 | J11: 고철(경량) | K11: 22640 | L11: 21350 | N11: =K11-L11-M11-190 -> 1100 | O11: 명일 29일 하차, AL B 무게 차감
A12: =ROW()-3 -> 9 | B12: 7-2 | C12: 46170 | D12: 현대제철_대도_당진 | E12: 원방 | F12: 집게차 | G12: 84나4888 | H12: 이민규 | I12: 010-5315-1508 | J12: 알루미늄 B | N12: 190 | O12: 대략 무게
A13: =ROW()-3 -> 10 | B13: 1-1 | C13: 46171 | D13: 현대제철_대도_당진 | E13: 선진알앤디 | F13: 집게차 | G13: 87주8410 | H13: 배민국 | I13: 010-9110-0126 | J13: 고철(경A) | K13: 17950 | L13: 15020 | N13: =K13-L13 -> 2930 | O13: 원방에서 계근 후 직납
A14: =ROW()-3 -> 11 | B14: 1-2 | C14: 46171 | D14: 현대제철_대도_당진 | E14: 원방 | F14: 집게차 | G14: 87주8410 | H14: 배민국 | I14: 010-9110-0126 | J14: 비철 | K14: 15020 | L14: 14400 | N14: =K14-L14 -> 620
A15: =ROW()-3 -> 12 | B15: 1 | C15: 46174 | D15: 현대제철_대도_당진 | E15: 세화철강 | F15: 방통차 | G15: 대전87아5975 | H15: 성태규 | I15: 010-9049-6769 | J15: 고철(철근) | K15: 36790 | L15: 18510 | N15: =K15-L15 -> 18280
A16: =ROW()-3 -> 13 | B16: 2 | C16: 46174 | D16: 현대제철_대도_당진 | E16: 세화철강 | F16: 방통차 | G16: 대전87아5975 | H16: 성태규 | I16: 010-9049-6769 | J16: 고철(중량장척) | K16: 36360 | L16: 18770 | N16: =K16-L16 -> 17590
A17: =ROW()-3 -> 14 | B17: 3 | C17: 46174 | D17: 현대제철_대도_당진 | E17: 세화철강 | F17: 집게차 | G17: 84나4888 | H17: 이민규 | I17: 010-5899-9660 | J17: 고철(경A) | K17: 24620 | L17: 21220 | N17: =K17-L17 -> 3400 | O17: 명일 6/2 하차
A18: =ROW()-3 -> 15 | B18: 1 | C18: 46177 | D18: 현대제철_대도_당진 | E18: 세화철강 | F18: 방통차 | G18: 전북80사5648 | H18: 이윤희 | I18: 010-8770-9101 | J18: 고철(철근) | K18: 39780 | L18: 18570 | N18: =K18-L18 -> 21210 | O18: 송악 계근
A19: =ROW()-3 -> 16 | B19: 2-1 | C19: 46177 | D19: 현대제철_대도_당진 | E19: 선진알앤디 | F19: 집게차 | G19: 84나4888 | H19: 이민규 | I19: 010-8282-5885 | J19: 고철(경량) | K19: 26580 | L19: 21100 | N19: =K19-L19-240 -> 5240 | O19: 선진 계근량 입력
A20: =ROW()-3 -> 17 | B20: 2-2 | C20: 46177 | D20: 현대제철_대도_당진 | E20: 원방 | F20: 집게차 | G20: 84나4888 | H20: 이민규 | I20: 010-8282-5885 | J20: 비철 | N20: 240 | O20: 송악 계근 5,480kg에서 선진 계근량 차감
A21: =ROW()-3 -> 18 | B21: 1 | C21: 46182 | D21: 현대제철_대도_당진 | E21: 세화철강 | F21: 방통차 | G21: 경기90자2889 | J21: 고철(철근) | K21: 37930 | L21: 18530 | N21: =K21-L21 -> 19400
A22: =ROW()-3 -> 19 | B22: 2 | C22: 46182 | D22: 현대제철_대도_당진 | E22: 세화철강 | F22: 방통차 | G22: 충북91아2060 | J22: 고철(철근) | K22: 37530 | L22: 18130 | N22: =K22-L22 -> 19400
A23: =ROW()-3 -> 20 | B23: 1 | C23: 46184 | D23: 현대제철_대도_당진 | E23: 세화철강 | F23: 방통차 | G23: 인천80자1904 | H23: 배조성 | I23: 010-4737-6803 | J23: 고철(철근) | K23: 36780 | L23: 18600 | N23: =K23-L23 -> 18180
A24: =ROW()-3 -> 21 | B24: 2 | C24: 46184 | D24: 현대제철_대도_당진 | E24: 세화철강 | F24: 방통차 | G24: 전남90바1977 | J24: 고철(철근) | K24: 42010 | L24: 18470 | N24: =K24-L24 -> 23540
A25: =ROW()-3 -> 22 | B25: 1 | C25: 46186 | D25: 현대제철_대도_당진 | E25: 세화철강 | F25: 집게차 | G25: 84나4888 | H25: 김현수 | I25: 010-5315-1508 | J25: 고철 | K25: 30870 | L25: 21170 | N25: =K25-L25 -> 9700 | O25: 분류 후 세화 출고
A26: =ROW()-3 -> 23 | N26: =K26-L26 -> 0
A27: =ROW()-3 -> 24 | N27: =K27-L27-M27 -> 0
C29: ■ 현대제철 철거공사 제품별 반입량
C31: 제품명 | D31: 반입량(kg) | F31: 제품 | G31: 반입량(kg) | H31: 비율
C32: 고철 | D32: 9700 | F32: 고철 | G32: =SUM(D32:D37) -> 227150 | H32: =G32/GETPIVOTDATA("입고량(kg)",$C$31) -> 0.9949279
C33: 고철(경A) | D33: 8690 | F33: 비철 | G33: =SUM(D38:D40) -> 1158 | H33: =G33/GETPIVOTDATA("입고량(kg)",$C$31) -> 0.0050720956
C34: 고철(경량) | D34: 6340 | F34: 합계 | G34: =SUM(G30:G33) -> 228308 | H34: =SUM(H30:H33) -> 1
C35: 고철(빔장척) | D35: 45930
C36: 고철(중량장척) | D36: 17590
C37: 고철(철근) | D37: 138900
C38: 비철 | D38: 860
C39: 알루미늄 B | D39: 190
C40: 폐전선 | D40: 108
C41: 총합계 | D41: 228308
C50: ※ 새로고침하면 반출량 업데이트 됨

Sheet 선진_진천식품기계
A1: □ 진천식품기계 반출 스크랩 반입일보 (26/06/26~26/06/27)
M2: =SUBTOTAL(9,M4:M586) -> 0 | N2: =SUBTOTAL(9,N4:N586) -> 98220
A3: NO (1) | B3: NO (2) | C3: 상차일 | D3: 프로젝트명 | E3: 하차지 | F3: 차종 | G3: 차량번호 | H3: 운전자 | I3: 연락처 | J3: 제품명 | K3: 총중량(kg) | L3: 공차중량(kg) | M3: 감량(kg) | N3: 입고량(kg) | O3: 비고
A4: =ROW()-3 -> 1 | B4: 1 | C4: 46199 | D4: 선진_식품기계_진천 | E4: 원방 | F4: 카고 | G4: 경기85자5423 | J4: 설비 스크랩 | K4: 10480 | L4: 8700 | N4: =K4-L4-M4 -> 1780
A5: =ROW()-3 -> 2 | B5: 2 | C5: 46199 | D5: 선진_식품기계_진천 | E5: 원방 | F5: 카고 | G5: 충남83바9206 | J5: 설비 스크랩 | K5: 11350 | L5: 9650 | N5: =K5-L5-M5 -> 1700
A6: =ROW()-3 -> 3 | B6: 3 | C6: 46199 | D6: 선진_식품기계_진천 | E6: 원방 | F6: 카고 | G6: 경기92아7341 | J6: 설비 스크랩 | K6: 10160 | L6: 8090 | N6: =K6-L6-M6 -> 2070
A7: =ROW()-3 -> 4 | B7: 4 | C7: 46199 | D7: 선진_식품기계_진천 | E7: 원방 | F7: 윙바디 | G7: 서울88아9809 | J7: 설비 스크랩 | K7: 13060 | L7: 9930 | N7: =K7-L7-M7 -> 3130
A8: =ROW()-3 -> 5 | B8: 5 | C8: 46199 | D8: 선진_식품기계_진천 | E8: 원방 | F8: 윙바디 | G8: 충남96바2038 | J8: 설비 스크랩 | K8: 13180 | L8: 10340 | N8: =K8-L8-M8 -> 2840
A9: =ROW()-3 -> 6 | B9: 6 | C9: 46199 | D9: 선진_식품기계_진천 | E9: 원방 | F9: 카고 | G9: 충남83아2541 | J9: 설비 스크랩 | K9: 10870 | L9: 8540 | N9: =K9-L9-M9 -> 2330
A10: =ROW()-3 -> 7 | B10: 7 | C10: 46199 | D10: 선진_식품기계_진천 | E10: 원방 | F10: 카고 | G10: 충남80아2618 | J10: 설비 스크랩 | K10: 11860 | L10: 9360 | N10: =K10-L10-M10 -> 2500
A11: =ROW()-3 -> 8 | B11: 8 | C11: 46199 | D11: 선진_식품기계_진천 | E11: 원방 | F11: 카고 | G11: 경기85자5423 | J11: 설비 스크랩 | K11: 10470 | L11: 8670 | N11: =K11-L11-M11 -> 1800
A12: =ROW()-3 -> 9 | B12: 9 | C12: 46199 | D12: 선진_식품기계_진천 | E12: 원방 | F12: 카고 | G12: 충남83바2557 | J12: 설비 스크랩 | K12: 10190 | L12: 7770 | N12: =K12-L12-M12 -> 2420
A13: =ROW()-3 -> 10 | B13: 10 | C13: 46199 | D13: 선진_식품기계_진천 | E13: 원방 | F13: 카고 | G13: 경기92아7341 | J13: 설비 스크랩 | K13: 12720 | L13: 8070 | N13: =K13-L13-M13 -> 4650
A14: =ROW()-3 -> 11 | B14: 11 | C14: 46199 | D14: 선진_식품기계_진천 | E14: 원방 | F14: 카고 | G14: 충남83아2541 | J14: 설비 스크랩 | K14: 15320 | L14: 8520 | N14: =K14-L14-M14 -> 6800
A15: =ROW()-3 -> 12 | B15: 12 | C15: 46199 | D15: 선진_식품기계_진천 | E15: 원방 | F15: 카고 | G15: 충남83아2294 | J15: 설비 스크랩 | K15: 10810 | L15: 7770 | N15: =K15-L15-M15 -> 3040
... A34: =ROW()-3 -> 31 | B34: 7 | C34: 46200 | D34: 선진_식품기계_진천 | E34: 원방 | F34: 카고 | G34: 충남80아2618 | J34: 설비 스크랩 | K34: 10900 | L34: 9290 | N34: =K34-L34-M34 -> 1610
A35: =ROW()-3 -> 32 | N35: =K35-L35-M35 -> 0
A36: =ROW()-3 -> 33 | N36: =K36-L36-M36 -> 0

Sheet 기타 현장
A1: □ 기타 현장 스크랩 반입일보 (26/01/09~ )
M2: =SUBTOTAL(9,M4:M600) -> 3040 | N2: =SUBTOTAL(9,N4:N600) -> 257820
A3: NO (1) | B3: NO (2) | C3: 상차일 | D3: 프로젝트명 | E3: 하차지 | F3: 차종 | G3: 차량번호 | H3: 운전자 | I3: 연락처 | J3: 제품명 | K3: 총중량(kg) | L3: 공차중량(kg) | M3: 감량(kg) | N3: 입고량(kg) | O3: 비고
A4: =ROW()-3 -> 1 | B4: 1 | C4: 46031 | D4: LT메탈_인천 | E4: 원방 | F4: 카고 | G4: 820우7928 | H4: 이원영 | J4: 스크랩 | K4: 5320 | L4: 4160 | N4: 1160 | O4: LT메탈_인천
A5: =ROW()-3 -> 2 | B5: 2 | C5: 46031 | D5: LT메탈_인천 | E5: 원방 | F5: 카고 | G5: 대전88아5577 | J5: 스크랩 | K5: 17580 | L5: 9010 | N5: 8570 | O5: LT메탈_인천
A6: =ROW()-3 -> 3 | B6: 3 | C6: 46031 | D6: LT메탈_인천 | E6: 원방 | F6: 카고 | G6: 인천83바4107 | J6: 스크랩 | K6: 13810 | L6: 8560 | N6: 5250 | O6: LT메탈_인천
A7: =ROW()-3 -> 4 | B7: 4 | C7: 46031 | D7: LT메탈_인천 | E7: 원방 | F7: 카고 | G7: 경기91바3551 | J7: 스크랩 | K7: 14730 | L7: 8310 | N7: 6420 | O7: LT메탈_인천
A8: =ROW()-3 -> 5 | B8: 5 | C8: 46031 | D8: LT메탈_인천 | E8: 원방 | F8: 카고 | G8: 충남80아3749 | J8: 스크랩 | K8: 16550 | L8: 9020 | N8: 7530 | O8: LT메탈_인천
A9: =ROW()-3 -> 6 | B9: 6 | C9: 46031 | D9: LT메탈_인천 | E9: 원방 | F9: 카고 | G9: 경기85자5830 | H9: 최상근 | I9: 010-9395-1276 | J9: 스크랩 | K9: 13110 | L9: 7820 | N9: 5290 | O9: LT메탈_인천
A10: =ROW()-3 -> 7 | B10: 7 | C10: 46031 | D10: LT메탈_인천 | E10: 원방 | F10: 카고 | G10: 81러3615 | H10: 이원영 | J10: 스크랩 | K10: 13350 | L10: 7910 | N10: 5440 | O10: LT메탈_인천
A11: =ROW()-3 -> 8 | B11: 8 | C11: 46031 | D11: LT메탈_인천 | E11: 원방 | F11: 카고 | G11: 충북80아5510 | J11: 스크랩 | K11: 12730 | L11: 7830 | N11: 4900 | O11: LT메탈_인천
A12: =ROW()-3 -> 9 | B12: 9 | C12: 46031 | D12: LT메탈_인천 | E12: 원방 | F12: 카고 | G12: 충남80아3291 | J12: 스크랩 | K12: 12060 | L12: 7960 | N12: 4100 | O12: LT메탈_인천
A13: =ROW()-3 -> 10 | B13: 1 | C13: 46036 | D13: LT메탈_인천 | E13: 원방 | F13: 카고 | G13: 경기91바3430 | H13: 정성순 | I13: 010-2043-8274 | J13: 스크랩 | K13: 12790 | L13: 8860 | N13: 3930 | O13: LT메탈_인천, 폐판넬 상차
A14: =ROW()-3 -> 11 | B14: 2 | C14: 46036 | D14: LT메탈_인천 | E14: 원방 | F14: 카고 | G14: 경기85자5830 | H14: 최상근 | I14: 010-9395-1276 | J14: 스크랩 | K14: 10180 | L14: 7820 | N14: 2360 | O14: LT메탈_인천
A15: =ROW()-3 -> 12 | B15: 3 | C15: 46036 | D15: LT메탈_인천 | E15: 원방 | F15: 카고 | G15: 인천85아3149 | H15: 최수행 | I15: 010-2901-2534 | J15: 스크랩 | K15: 11300 | L15: 8510 | M15: 500 | N15: 2290 | O15: LT메탈_인천, 크로스 양중박스 1개
A16: =ROW()-3 -> 13 | B16: 4 | C16: 46036 | D16: LT메탈_인천 | E16: 원방 | F16: 카고 | G16: 경기93아4888 | H16: 조용수 | I16: 010-3364-3181 | J16: 스크랩 | K16: 11840 | L16: 8810 | M16: 1500 | N16: 1530 | O16: LT메탈_인천, 크로스 양중박스 3개
A17: =ROW()-3 -> 14 | B17: 1 | C17: 46066 | D17: 삼성_대도_온양 | E17: 원방 | F17: 암롤트럭 | G17: 86노1445 | I17: 010-5899-9660 | J17: 스크랩 | K17: 28940 | L17: 20090 | N17: 8850 | O17: 삼성전자 온양사업장 철거
A18: =ROW()-3 -> 15 | B18: 2 | C18: 46066 | D18: 삼성_대도_온양 | E18: 대신에스티에스 | F18: 집게차 | G18: 87주8410 | H18: 배민국 | I18: 010-9110-0126 | J18: 스크랩 | K18: 15720 | L18: 14140 | N18: 1580 | O18: 삼성전자 온양사업장 철거
A19: =ROW()-3 -> 16 | B19: 3-1 | C19: 46066 | D19: 삼성_대도_온양 | E19: 원방 | F19: 암롤트럭 | G19: 86노1445 | I19: 010-5899-9660 | J19: 스크랩 | K19: 29410 | L19: 20080 | N19: =9330-2070 -> 7260 | O19: 삼성전자 온양사업장 철거, 분류 차감
A20: =ROW()-3 -> 17 | B20: 3-2 | C20: 46066 | D20: 삼성_대도_온양 | E20: 원방 | F20: 지게차 | J20: STS304 | N20: =1520+550 -> 2070 | O20: 삼성전자 온양사업장 철거, 6/25 분류
A21: =ROW()-3 -> 18 | B21: 4 | C21: 46066 | D21: 삼성_대도_온양 | E21: 선진알앤디 | F21: 집게차 | G21: 87주8410 | H21: 배민국 | I21: 010-9110-0126 | J21: 스크랩 | K21: 18380 | L21: 14140 | N21: 4240 | O21: 삼성전자 온양사업장 철거
A22: =ROW()-3 -> 19 | B22: 1 | C22: 46076 | D22: 삼성_대도_온양 | E22: 원방 | F22: 1톤트럭 | G22: 81구6225 | H22: 배민국 | I22: 010-9110-0126 | J22: 전선 등 | K22: 2890 | L22: 2160 | N22: 730 | O22: 삼성전자 온양사업장 철거
A23: =ROW()-3 -> 20 | B23: 1 | C23: 46077 | D23: 삼성_대도_온양 | E23: 원방 | F23: 3.5톤트럭 | G23: 820우7928 | H23: 이원영 | I23: 010-9992-4447 | J23: 전선 등 | K23: 5030 | L23: 4180 | N23: 850 | O23: 삼성전자 온양사업장 철거
A24: =ROW()-3 -> 21 | B24: 1 | C24: 46077 | D24: 삼성바이오_대도_송도 | E24: 대호스틸 | F24: 방통차 | G24: 7274 | J24: 고철(중량) | K24: 30420 | L24: 18210 | N24: 12210 | O24: 남동계량소에서 계근 후 직납
A25: =ROW()-3 -> 22 | B25: 2 | C25: 46077 | D25: 삼성바이오_대도_송도 | E25: 대호스틸 | F25: 집게차 | G25: 7018집게차 | J25: 고철(경량) | K25: 22540 | L25: 13670 | N25: 8870 | O25: 남동계량소에서 계근 후 직납
A26: =ROW()-3 -> 23 | B26: 1 | C26: 46078 | D26: 삼성바이오_대도_송도 | E26: 선진알앤디 | F26: 집게차 | G26: 87주8410 | H26: 배민국 | I26: 010-9110-0126 | J26: 고철(경량) | K26: 17960 | L26: 14150 | N26: 3810 | O26: 원방에서 계근 후 직납
A27: =ROW()-3 -> 24 | B27: 1-1 | C27: 46086 | D27: 잠실동 실내철거 | E27: 원방 | F27: 3.5톤트럭 | G27: 820우7928 | H27: 이원영 | I27: 010-8282-5885 | J27: 스크랩 | K27: 4940 | L27: 4210 | N27: 730 | O27: 잠실동 실내철거, 3/6하차, AL분류 340kg 차감
A28: =ROW()-3 -> 25 | B28: 1-2 | C28: 46086 | D28: 잠실동 실내철거 | E28: 원방 | F28: 3.5톤트럭 | G28: 820우7928 | H28: 이원영 | I28: 010-8282-5885 | J28: 알루미늄 | K28: 12320 | L28: 10940 | M28: 1040 | N28: 340 | O28: 잠실동 실내철거, 흰 양중박스 1개 감량
A29: =ROW()-3 -> 26 | B29: 1 | C29: 46086 | D29: 삼성_대도_온양 | E29: 선진알앤디 | F29: 집게차 | G29: 82모8185 | H29: 최명동 | I29: 010-7997-2485 | J29: 고철(경B) | K29: 15340 | L29: 12780 | N29: 2560 | O29: 삼성전자 온양사업장 철거
A30: =ROW()-3 -> 27 | B30: 2 | C30: 46086 | D30: 삼성_대도_온양 | E30: 선진알앤디 | F30: 집게차 | G30: 82모8185 | H30: 최명동 | I30: 010-7997-2485 | J30: 고철(경B) | K30: 15330 | L30: 12820 | N30: 2510 | O30: 삼성전자 온양사업장 철거
A31: =ROW()-3 -> 28 | B31: 1 | C31: 46087 | D31: 삼성_대도_온양 | E31: 세화철강 | F31: 집게차 | G31: 82모8185 | H31: 최명동 | I31: 010-7997-2485 | J31: 고철(경량) | K31: 15270 | L31: 12910 | N31: 2360 | O31: 삼성전자 온양사업장 철거
A32: =ROW()-3 -> 29 | B32: 2 | C32: 46087 | D32: 삼성_대도_온양 | E32: 세화철강 | F32: 집게차 | G32: 91노1087 | H32: 세화철강 | I32: 041-552-5791 | J32: 고철(경량) | K32: 25900 | L32: 22040 | N32: 3860 | O32: 삼성전자 온양사업장 철거
A33: =ROW()-3 -> 30 | B33: 1 | C33: 46088 | D33: 삼성_대도_온양 | E33: 세화철강 | F33: 집게차 | G33: 91노1087 | H33: 세화철강 | I33: 041-552-5791 | J33: 고철(H빔) | K33: 40030 | L33: 22000 | N33: 18030 | O33: 삼성전자 온양사업장 철거
A34: =ROW()-3 -> 31 | B34: 1 | C34: 46090 | D34: 삼성_대도_온양 | E34: 세화철강 | F34: 집게차 | G34: 91노1087 | H34: 세화철강 | I34: 041-552-5791 | J34: 고철(H빔) | K34: 28520 | L34: 25280 | N34: 3240 | O34: 삼성전자 온양사업장 철거
A35: =ROW()-3 -> 32 | B35: 2 | C35: 46090 | D35: 삼성_대도_온양 | E35: 세화철강 | F35: 집게차 | G35: 91노1087 | H35: 세화철강 | I35: 041-552-5791 | J35: 고철(경량) | K35: 25280 | L35: 22110 | N35: 3170 | O35: 삼성전자 온양사업장 철거
A36: =ROW()-3 -> 33 | B36: 3 | C36: 46090 | D36: 삼성_대도_온양 | E36: 선진알앤디 | F36: 집게차 | G36: 96거5789 | H36: 이선갑 | I36: 010-5315-1508 | J36: 고철(경량) | K36: 18260 | L36: 13780 | N36: 4480 | O36: 삼성전자 온양사업장 철거
A37: =ROW()-3 -> 34 | B37: 1 | C37: 46091 | D37: 삼성_대도_온양 | E37: 세화철강 | F37: 집게차 | G37: 91노1087 | H37: 세화철강 | I37: 041-552-5791 | J37: 고철(경량) | K37: 27730 | L37: 21940 | N37: 5790 | O37: 삼성전자 온양사업장 철거
A38: =ROW()-3 -> 35 | B38: 1 | C38: 46092 | D38: 삼성_대도_온양 | E38: 세화철강 | F38: 집게차 | G38: 5998 | H38: 세화철강 | I38: 041-552-5791 | J38: 고철(경량) | K38: 28430 | L38: 21810 | N38: 6620 | O38: 삼성전자 온양사업장 철거
A39: =ROW()-3 -> 36 | B39: 1 | C39: 46093 | D39: 삼성_대도_온양 | E39: 세화철강 | F39: 집게차 | G39: 91노1087 | H39: 세화철강 | I39: 041-552-5791 | J39: 고철(경량) | K39: 27970 | L39: 22050 | N39: 5920 | O39: 삼성전자 온양사업장 철거
A40: =ROW()-3 -> 37 | B40: 1 | C40: 46094 | D40: 삼성_대도_온양 | E40: 세화철강 | F40: 집게차 | G40: 91노1087 | H40: 세화철강 | I40: 041-552-5791 | J40: 고철(경량) | K40: 27660 | L40: 22020 | N40: 5640 | O40: 삼성전자 온양사업장 철거
...

Sheet 단발성(기타 현장)
A1: □ 원방 - 기타 현장 입고 현황(2025.07.08 ~ )
N2: =SUBTOTAL(9,N4:N22) -> 19188
A3: NO(1) | B3: NO(2) | C3: 현장 | D3: 상차일자 | E3: 하차지 | F3: 차량번호 | G3: 운전자 | H3: 연락처 | I3: 차종 | J3: 제품 | K3: 총중량 | L3: 공차중량 | M3: 감량 | N3: 입고량(Kg) | O3: 비고
A4: =ROW()-4 -> 0 | B4: 1 | C4: 듀폰_천안 | D4: 46164 | E4: 세화철강 | F4: 87주8410 | G4: 배민국 | H4: 010-9110-0126 | I4: 집게차 | J4: 고철(경A) | K4: 19430 | L4: 14210 | N4: =K4-L4 -> 5220 | O4: 듀폰 천안공장, 경량, 중량, 쓰레기 포함.
A5: =ROW()-4 -> 1 | B5: 1-1 | C5: 한성상 | D5: 46168 | E5: 원방 | F5: 89누1668 | G5: 한성상 | I5: 1톤트럭 | J5: 모터 | K5: 3420 | L5: 2350 | N5: =K5-L5 -> 1070 | O5: 한성상
A6: =ROW()-4 -> 2 | B6: 1-2 | C6: 한성상 | D6: 46168 | E6: 원방 | F6: 89누1668 | G6: 한성상 | I6: 1톤트럭 | J6: 비철 및 알루미늄 | K6: 2350 | L6: 2290 | N6: =K6-L6 -> 60 | O6: 한성상
A7: =ROW()-4 -> 3 | B7: 1-3 | C7: 한성상 | D7: 46168 | E7: 원방 | F7: 89누1668 | G7: 한성상 | I7: 1톤트럭 | J7: 고철 | K7: 2290 | L7: 2060 | N7: =K7-L7 -> 230 | O7: 한성상
A8: =ROW()-4 -> 4 | B8: 1-1 | C8: 에코코리아 | D8: 46181 | E8: 원방 | F8: 81로1401 | G8: 이덕현 | I8: 집게차 | J8: AL A | K8: 15310 | L8: 13980 | M8: 24 | N8: =K8-L8-M8 -> 1306 | O8: 에코코리아, 마대 12개
A9: =ROW()-4 -> 5 | B9: 1-2 | C9: 에코코리아 | D9: 46181 | E9: 원방 | F9: 81로1401 | G9: 이덕현 | I9: 집게차 | J9: 프로파일 A | K9: 13980 | L9: 12580 | M9: 8 | N9: =K9-L9-M9 -> 1392 | O9: 에코코리아, 마대 4개
A10: =ROW()-4 -> 6 | B10: 1-1 | C10: 듀폰_천안 | D10: 46184 | E10: 원방 | F10: 96거8410 | G10: 김현수 | H10: 010-5315-1508 | I10: 집게차 | J10: 고철, 비철 | K10: 17410 | L10: 13550 | N10: =K10-L10-M10-390 -> 3470 | O10: 듀폰 천안공장, 분류 390kg 차감
A11: =ROW()-4 -> 7 | B11: 1-2 | C11: 듀폰_천안 | D11: 46184 | E11: 원방 | I11: 지게차 | J11: STS304 | K11: 12570 | L11: 11680 | M11: 500 | N11: =K11-L11-M11 -> 390 | O11: 듀폰 천안공장, 지게차 분류, 양중박스 감량
A12: =ROW()-4 -> 8 | B12: 1-1 | C12: 듀폰_천안 | D12: 46193 | E12: 원방 | F12: 96거5789 | G12: 김현수 | H12: 010-5315-1508 | I12: 집게차 | J12: 스크랩 | K12: 16710 | L12: 13580 | N12: 90 | O12: 듀폰 천안공장, 쓰레기, 수분. 3,040kg 분류 차감
A13: =ROW()-4 -> 9 | B13: 1-2 | C13: 듀폰_천안 | D13: 46193 | E13: 원방 | F13: 지게차 | H13: 이유리 | J13: 동 라지에이타 | N13: 770 | O13: 듀폰 천안공장, 6/22 지게차 분류
A14: =ROW()-4 -> 10 | B14: 1-3 | C14: 듀폰_천안 | D14: 46193 | E14: 원방 | F14: 지게차 | H14: 이유리 | J14: STS304 | N14: 170 | O14: 듀폰 천안공장, 6/22 지게차 분류
A15: =ROW()-4 -> 11 | B15: 1-4 | C15: 듀폰_천안 | D15: 46193 | E15: 원방 | F15: 지게차 | H15: 이유리 | J15: 고철(중량장척) | N15: 1850 | O15: 듀폰 천안공장, 6/22 지게차 분류
A16: =ROW()-4 -> 12 | B16: 1-5 | C16: 듀폰_천안 | D16: 46193 | E16: 원방 | F16: 지게차 | H16: 이유리 | J16: 모터 | N16: 250 | O16: 듀폰 천안공장, 6/22 지게차 분류
A17: =ROW()-4 -> 13 | B17: 1-1 | C17: 듀폰_천안 | D17: 46210 | E17: 세화철강 | F17: 96거5789 | G17: 배민국 | H17: 010-9110-0126 | I17: 집게차 | J17: 고철(경A) | K17: 16380 | L17: 13600 | N17: =K17-L17 -> 2780 | O17: 듀폰 천안공장, 모래 300kg 감량 있을 수 있음.
A18: =ROW()-4 -> 14 | B18: 1-2 | C18: 듀폰_천안 | D18: 46210 | E18: 원방 | F18: 96거5789 | G18: 배민국 | H18: 010-9110-0126 | I18: 집게차 | J18: STS304 | K18: 13770 | L18: 13630 | N18: =K18-L18 -> 140 | O18: 듀폰 천안공장, 하차 후 대신 바로 출고
A22: 2026년 소계 | O22: =SUM(N4:N21) -> 19188
A24: ※ 한양이엔지 듀폰은 듀폰 화일철에 출력 본 정리
C26: ■ 기타현장(단발성) 제품별 반입량
C28: 합계 : 입고량(Kg) | D28: 프로젝트명
C29: 제품명 | D29: 듀폰_천안 | E29: 에코코리아 | F29: 한성상 | G29: 총합계
C30: AL A | E30: 1306 | G30: 1306
C31: STS304 | D31: 700 | G31: 700
C32: 고철 | F32: 230 | G32: 230
C33: 고철(경A) | D33: 8000 | G33: 8000
C34: 고철, 비철 | D34: 3470 | G34: 3470
C35: 동 라지에이타 | D35: 770 | G35: 770
C36: 모터 | D36: 250 | F36: 1070 | G36: 1320
C37: 비철 및 알루미늄 | F37: 60 | G37: 60
C38: 스크랩 | D38: 90 | G38: 90
C39: 프로파일 A | E39: 1392 | G39: 1392
C40: 고철(중량장척) | D40: 1850 | G40: 1850
C41: 총합계 | D41: 15130 | E41: 2698 | F41: 1360 | G41: 19188

Sheet 삼성_이텍솔루션_안성
A1: □ 안성 이텍솔루션 설비 반출 스크랩 반입일보 (26/06/02~26/06/11)
M2: =SUBTOTAL(9,M4:M578) -> 0 | N2: =SUBTOTAL(9,N4:N578) -> 118420
A3: NO (1) | B3: NO (2) | C3: 상차일 | D3: 프로젝트명 | E3: 하차지 | F3: 차종 | G3: 차량번호 | H3: 운전자 | I3: 연락처 | J3: 제품명 | K3: 총중량(kg) | L3: 공차중량(kg) | M3: 감량(kg) | N3: 입고량(kg) | O3: 비고
A4: =ROW()-3 -> 1 | B4: 1 | C4: 46175 | D4: 삼성전자_이텍솔루션_안성 | E4: 원방 | F4: 윙바디 | G4: 전북91사6889 | H4: 박만순 | I4: 010-5099-9998 | J4: 설비 | K4: 15400 | L4: 9900 | N4: =K4-L4-M4 -> 5500 | O4: 7CTN, 파렛트 1개
A5: =ROW()-3 -> 2 | B5: 2 | C5: 46175 | D5: 삼성전자_이텍솔루션_안성 | E5: 원방 | F5: 윙바디 | G5: 충남80아3769 | H5: 조정철 | I5: 010-5450-1492 | J5: 설비 | K5: 14580 | L5: 9800 | N5: =K5-L5-M5 -> 4780 | O5: 15CTN, 파렛트 3개
A6: =ROW()-3 -> 3 | B6: 3 | C6: 46175 | D6: 삼성전자_이텍솔루션_안성 | E6: 원방 | F6: 윙바디 | G6: 충남80아2701 | H6: 김창남 | I6: 010-5329-6935 | J6: 설비 | K6: 14470 | L6: 9230 | N6: =K6-L6-M6 -> 5240 | O6: 13CTN, 파렛트 1개
A7: =ROW()-3 -> 4 | B7: 4 | C7: 46175 | D7: 삼성전자_이텍솔루션_안성 | E7: 원방 | F7: 카고 | G7: 충남80아1374 | H7: 김시성 | I7: 010-5421-4967 | J7: 설비 | K7: 12100 | L7: 8120 | N7: =K7-L7-M7 -> 3980 | O7: 3CTN
A8: =ROW()-3 -> 5 | B8: 5 | C8: 46175 | D8: 삼성전자_이텍솔루션_안성 | E8: 원방 | F8: 윙바디 | G8: 충북82아3517 | H8: 김성효 | I8: 010-2482-5621 | J8: 설비 | K8: 15170 | L8: 9950 | N8: =K8-L8-M8 -> 5220 | O8: 9CTN
A9: =ROW()-3 -> 6 | B9: 1 | C9: 46177 | D9: 삼성전자_이텍솔루션_안성 | E9: 원방 | F9: 윙바디 | G9: 충남83아2492 | H9: 조영현 | I9: 010-6470-0449 | J9: 설비 | K9: 18780 | L9: 13350 | N9: =K9-L9-M9 -> 5430 | O9: 9CTN, 11톤 윙바디
A10: =ROW()-3 -> 7 | B10: 2 | C10: 46177 | D10: 삼성전자_이텍솔루션_안성 | E10: 원방 | F10: 윙바디 | G10: 광주90바6581 | H10: 하창수 | I10: 010-7205-4270 | J10: 설비 | K10: 18050 | L10: 12210 | N10: =K10-L10-M10 -> 5840 | O10: 14CTN, 11톤 윙바디
A11: =ROW()-3 -> 8 | B11: 3 | C11: 46177 | D11: 삼성전자_이텍솔루션_안성 | E11: 원방 | F11: 카고 | G11: 경기85바6491 | H11: 김두식 | I11: 010-9076-4549 | J11: 설비 | K11: 12180 | L11: 9030 | N11: =K11-L11-M11 -> 3150 | O11: 7CTN
A12: =ROW()-3 -> 9 | B12: 4 | C12: 46177 | D12: 삼성전자_이텍솔루션_안성 | E12: 원방 | F12: 카고 | G12: 충남83아1957 | H12: 홍경의 | I12: 010-2416-1642 | J12: 설비 | K12: 10270 | L12: 8570 | N12: =K12-L12-M12 -> 1700 | O12: 32CTN
A13: =ROW()-3 -> 10 | B13: 1 | C13: 46178 | D13: 삼성전자_이텍솔루션_안성 | E13: 원방 | F13: 윙바디 | G13: 경기92자7869 | H13: 김보람 | I13: 010-5332-5555 | J13: 설비 | K13: 18660 | L13: 11720 | N13: =K13-L13-M13 -> 6940 | O13: 6CTN
A14: =ROW()-3 -> 11 | B14: 2 | C14: 46178 | D14: 삼성전자_이텍솔루션_안성 | E14: 원방 | F14: 윙바디 | G14: 충남80아3769 | H14: 조정철 | I14: 010-5450-1492 | J14: 설비 | K14: 15210 | L14: 9770 | N14: =K14-L14-M14 -> 5440 | O14: 7CTN
A15: =ROW()-3 -> 12 | B15: 3 | C15: 46178 | D15: 삼성전자_이텍솔루션_안성 | E15: 원방 | F15: 윙바디 | G15: 경기94아2283 | H15: 전영호 | I15: 010-8009-6002 | J15: 설비 | K15: 15610 | L15: 9580 | N15: =K15-L15-M15 -> 6030 | O15: 6CTN
... A24: =ROW()-3 -> 21 | B24: 5 | C24: 46181 | D24: 삼성전자_이텍솔루션_안성 | E24: 원방 | F24: 평카 | G24: 인천99아7178 | H24: 이동수 | I24: 010-9439-3654 | J24: 설비 | K24: 28210 | L24: 17890 | N24: =K24-L24-M24 -> 10320 | O24: 6CTN
A25: =ROW()-3 -> 22 | B25: 6 | C25: 46181 | D25: 삼성전자_이텍솔루션_안성 | E25: 원방 | F25: 3.5톤트럭 | G25: 81러3615 | H25: 강철규 | I25: 010-3807-3096 | J25: 설비 | K25: 12070 | L25: 10910 | N25: =K25-L25-M25 -> 1160
A26: =ROW()-3 -> 23 | B26: 1 | C26: 46184 | D26: 삼성전자_이텍솔루션_안성 | E26: 원방 | F26: 카고 | G26: 81러3615 | H26: 이원영 | I26: 010-9992-4447 | J26: 설비 | K26: 13440 | L26: 7910 | N26: =K26-L26-M26 -> 5530
A27: =ROW()-3 -> 24 | N27: =K27-L27-M27 -> 0
A28: =ROW()-3 -> 25 | N28: =K28-L28-M28 -> 0

Sheet 동우PL1_평택
A1: □ 동우화인켐 PL1린텍 설비 및 건축물 부분철거 스크랩 반입일보 (26/04/21~26/06/11)
M2: =SUBTOTAL(9,M4:M574) -> 0 | N2: =SUBTOTAL(9,N4:N574) -> 114240
A3: NO (1) | B3: NO (2) | C3: 상차일 | D3: 프로젝트명 | E3: 하차지 | F3: 차종 | G3: 차량번호 | H3: 운전자 | I3: 연락처 | J3: 제품명 | K3: 총중량(kg) | L3: 공차중량(kg) | M3: 감량(kg) | N3: 입고량(kg) | O3: 비고
A4: =ROW()-3 -> 1 | B4: 1 | C4: 46158 | D4: 동우PL1린텍_크로스_평택 | E4: 세화철강 | F4: 집게차 | G4: 87주8410 | H4: 배민국 | I4: 010-9110-0126 | J4: 고철(경A) | K4: 17800 | L4: 13930 | N4: 3870
A5: =ROW()-3 -> 2 | B5: 1 | C5: 46159 | D5: 동우PL1린텍_크로스_평택 | E5: 세화철강 | F5: 집게차 | G5: 84나4888 | H5: 이민규 | I5: 010-5899-9660 | J5: 고철(빔장척) | K5: 32670 | L5: 21390 | N5: 11280
A6: =ROW()-3 -> 3 | B6: 2 | C6: 46159 | D6: 동우PL1린텍_크로스_평택 | E6: 원방 | F6: 집게차 | G6: 87주8410 | H6: 배민국 | I6: 010-9110-0126 | J6: 작업철 | K6: 16860 | L6: 14100 | N6: 2760 | O6: 포스코 계근 2,740kg
A7: =ROW()-3 -> 4 | B7: 3 | C7: 46159 | D7: 동우PL1린텍_크로스_평택 | E7: 원방 | F7: 집게차 | G7: 87주8410 | H7: 배민국 | I7: 010-9110-0126 | J7: 작업철 | K7: 16780 | L7: 14090 | N7: 2690 | O7: 포스코 계근 2,680kg
A8: =ROW()-3 -> 5 | B8: 4 | C8: 46159 | D8: 동우PL1린텍_크로스_평택 | E8: 세화철강 | F8: 방통차 | G8: 경북80아9218 | H8: 정현철 | I8: 010-3873-2063 | J8: 고철(빔장척) | K8: 32120 | L8: 17930 | N8: 14190
A9: =ROW()-3 -> 6 | B9: 5 | C9: 46159 | D9: 동우PL1린텍_크로스_평택 | E9: 세화철강 | F9: 방통차 | G9: 경북80아9218 | H9: 정현철 | I9: 010-3873-2063 | J9: 고철(빔장척) | K9: 33670 | L9: 17910 | N9: 15760
A10: =ROW()-3 -> 7 | B10: 1 | C10: 46160 | D10: 동우PL1린텍_크로스_평택 | E10: 원방 | F10: 집게차 | G10: 87주8410 | H10: 배민국 | I10: 010-9110-0126 | J10: 모터 | K10: 15680 | L10: 14690 | N10: =K10-L10-M10 -> 990
A11: =ROW()-3 -> 8 | B11: 2 | C11: 46160 | D11: 동우PL1린텍_크로스_평택 | E11: 세화철강 | F11: 집게차 | G11: 87주8410 | H11: 배민국 | I11: 010-9110-0126 | J11: 고철(철근) | K11: 19660 | L11: 15570 | N11: =K11-L11-M11 -> 4090 | O11: 세화 계근량 입력
A12: =ROW()-3 -> 9 | B12: 3 | C12: 46160 | D12: 동우PL1린텍_크로스_평택 | E12: 세화철강 | F12: 집게차 | G12: 87주8410 | H12: 배민국 | I12: 010-9110-0126 | J12: 고철(경A) | N12: 600 | O12: 동우 총 계근량 5,680kg에서 철근, 모터 차감 5/19 고철이랑 합하여 출고
A13: =ROW()-3 -> 10 | B13: 4 | C13: 46160 | D13: 동우PL1린텍_크로스_평택 | E13: 세화철강 | F13: 방통차 | G13: 경북80아9218 | H13: 정현철 | I13: 010-3873-2063 | J13: 고철(경량) | K13: 26800 | L13: 18080 | N13: =K13-L13-M13 -> 8720
A14: =ROW()-3 -> 11 | B14: 5 | C14: 46160 | D14: 동우PL1린텍_크로스_평택 | E14: 세화철강 | F14: 방통차 | G14: 인천83사9675 | H14: 서재하 | I14: 010-9027-1162 | J14: 고철(경량) | K14: 25680 | L14: 18610 | N14: =K14-L14-M14 -> 7070
A15: =ROW()-3 -> 12 | B15: 6 | C15: 46160 | D15: 동우PL1린텍_크로스_평택 | E15: 세화철강 | F15: 방통차 | G15: 충남80바2810 | H15: 김상철 | I15: 010-7107-6000 | J15: 고철(중량장척) | K15: 32380 | L15: 18840 | N15: =K15-L15-M15 -> 13540
A16: =ROW()-3 -> 13 | B16: 7 | C16: 46160 | D16: 동우PL1린텍_크로스_평택 | E16: 세화철강 | F16: 방통차 | G16: 경기96자1089 | H16: 서건식 | I16: 010-9037-6416 | J16: 고철(중량장척) | K16: 31220 | L16: 18700 | N16: =K16-L16-M16 -> 12520
A17: =ROW()-3 -> 14 | B17: 1-1 | C17: 46161 | D17: 동우PL1린텍_크로스_평택 | E17: 세화철강 | F17: 집게차 | G17: 87주8410 | H17: 배민국 | I17: 010-9110-0126 | J17: 고철(경량) | K17: 21170 | L17: 14560 | N17: 3390 | O17: 동우 계근량 입력, 철근 차감
A18: =ROW()-3 -> 15 | B18: 1-2 | C18: 46161 | D18: 동우PL1린텍_크로스_평택 | E18: 세화철강 | F18: 집게차 | G18: 87주8410 | H18: 배민국 | I18: 010-9110-0126 | J18: 고철(철근) | N18: 3220 | O18: 세화 계근 중량
A19: =ROW()-3 -> 16 | B19: 1 | C19: 46162 | D19: 동우PL1린텍_크로스_평택 | E19: 세화철강 | F19: 집게차 | G19: 87주8410 | H19: 배민국 | I19: 010-9110-0126 | J19: 고철(빔장척, 경A) | K19: 20150 | L19: 14090 | N19: =K19-L19-M19 -> 6060 | O19: 세화에서 빔장척, 경A 분류계근
A20: =ROW()-3 -> 17 | B20: 1 | C20: 46168 | D20: 동우PL1린텍_크로스_평택 | E20: 원방 | F20: 집게차 | G20: 96거5789 | H20: 배민국 | I20: 010-9110-0126 | J20: 고철 | K20: 15080 | L20: 13600 | N20: =K20-L20-M20 -> 1480 | O20: 폐기물 1차 4,580kg 하차
A21: =ROW()-3 -> 18 | B21: 1 | C21: 46181 | D21: 동우PL1린텍_크로스_평택 | E21: 원방 | F21: 집게차 | G21: 87주8410 | H21: 배민국 | I21: 010-9110-0126 | J21: 고철, 폐기물 | K21: 15750 | L21: 14100 | N21: =K21-L21-M21 -> 1650 | O21: 동우 1,610kg, 폐기물 약 20kg 포함
A22: =ROW()-3 -> 19 | B22: 1 | C22: 46184 | D22: 동우PL1린텍_크로스_평택 | E22: 원방 | F22: 집게차 | G22: 87주8410 | H22: 배민국 | I22: 010-9110-0126 | J22: 고철 | K22: 17870 | L22: 17510 | N22: =K22-L22-M22 -> 360 | O22: 폐기물, 폐판넬과 함께 반출되어 분류
A23: =ROW()-3 -> 20 | N23: =K23-L23-M23 -> 0
A24: =ROW()-3 -> 21 | N24: =K24-L24-M24 -> 0
C26: ■ 동우 PL1린텍 철거 제품별 반입량
C28: 제품명 | D28: 반입량(kg) | F28: 제품 | G28: 반입량(kg) | H28: 비율
C29: 고철 | D29: 1840 | F29: 고철 | G29: =SUM(D29:D36) -> 107800 | H29: =G29/GETPIVOTDATA("입고량(kg)",$C$28) -> 0.94362745
C30: 고철(경A) | D30: 4470 | F30: 비철 | G30: =SUM(D37:D38) -> 6440 | H30: =G30/GETPIVOTDATA("입고량(kg)",$C$28) -> 0.056372549
C31: 고철(경량) | D31: 19180 | F31: 합계 | G31: =SUM(G29:G30) -> 114240 | H31: =SUM(H29:H30) -> 1
C32: 고철(빔장척) | D32: 41230
C33: 고철(빔장척, 경A) | D33: 6060
C34: 고철(중량장척) | D34: 26060
C35: 고철(철근) | D35: 7310
C36: 고철, 폐기물 | D36: 1650
C37: 모터 | D37: 990
C38: 작업철 | D38: 5450
C39: 총합계 | D39: 114240

Sheet 포스코_KM안산
A1: □ 포스코모빌리티솔루션 STS사업실 안산공장 스크랩 반입일보 (26/3/6~26/05/27)
M2: =SUBTOTAL(9,M4:M569) -> 12129 | N2: =SUBTOTAL(9,N4:N569) -> 1667471 | O2: ※ 내화벽돌, 폐기물, 글라스울, 폐판넬 별도 입력
A3: NO (1) | B3: NO (2) | C3: 상차일 | D3: 프로젝트명 | E3: 하차지 | F3: 차종 | G3: 차량번호 | H3: 운전자 | I3: 연락처 | J3: 제품명 | K3: 총중량(kg) | L3: 공차중량(kg) | M3: 감량(kg) | N3: 입고량(kg) | O3: 비고
A4: =ROW()-3 -> 1 | B4: 1 | C4: 46146 | D4: 포스코_KM_안산 | E4: 선진알앤디 | F4: 집게차 | G4: 87주8410 | H4: 배민국 | I4: 010-9110-0126 | J4: 고철(경B) | K4: 17920 | L4: 14120 | N4: 3800 | O4: 원방에서 계근 후 직납, 포스코 계근과 동일
A5: =ROW()-3 -> 2 | B5: 2-1 | C5: 46146 | D5: 포스코_KM_안산 | E5: 원방 | F5: 카고 | G5: 경기89사3442 | J5: 전선, 신주 | K5: 16250 | L5: 15120 | N5: 1130 | O5: 신주 일부 포함, 포스코 계근 7,060kg
A6: =ROW()-3 -> 3 | B6: 2-2 | C6: 46146 | D6: 포스코_KM_안산 | E6: 원방 | F6: 카고 | G6: 경기89사3442 | J6: 알루미늄 | K6: 12340 | L6: 11610 | M6: 500 | N6: 230 | O6: 양중박스 1개 감량, 분류계근
A7: =ROW()-3 -> 4 | B7: 2-3 | C7: 46146 | D7: 포스코_KM_안산 | E7: 원방 | F7: 카고 | G7: 경기89사3442 | J7: 모터 | K7: 15130 | L7: 8720 | M7: 500 | N7: 5680 | O7: 양중박스, AL 분류계근 건 차감
A8: =ROW()-3 -> 5 | B8: 1 | C8: 46147 | D8: 포스코_KM_안산 | E8: 세화철강 | F8: 집게차 | G8: 87주8410 | H8: 배민국 | I8: 010-9110-0126 | J8: 고철(경A) | K8: 17620 | L8: 14220 | N8: 3400 | O8: 세화 계근3,370kg
A9: =ROW()-3 -> 6 | B9: 1 | C9: 46148 | D9: 포스코_KM_안산 | E9: 원방 | F9: 카고 | G9: 경북86아9491 | J9: 탱크 | K9: 36330 | L9: 15890 | N9: 20440 | O9: 포스코 계근 20,440kg 동일
A10: =ROW()-3 -> 7 | B10: 2 | C10: 46148 | D10: 포스코_KM_안산 | E10: 원방 | F10: 카고 | G10: 경기91사3176 | J10: 탱크 | K10: 26120 | L10: 15780 | N10: 10340 | O10: 포스코계근 10,300kg 40kg 차이
A11: =ROW()-3 -> 8 | B11: 3 | C11: 46148 | D11: 포스코_KM_안산 | E11: 원방 | F11: 집게차 | G11: 96거5789 | H11: 배민국 | I11: 010-9110-0126 | J11: 스크랩 | K11: 17640 | L11: 13470 | N11: =K11-L11 -> 4170 | O11: 포스코 계근 4,120kg 50kg 차이, 5/7하차, sus304(1,790kg) 작업철(2,380kg)예상-분류계근 예정
A12: =ROW()-3 -> 9 | B12: 1-1 | C12: 46149 | D12: 포스코_KM_안산 | E12: 원방 | F12: 카고 | G12: 충남80아2457 | H12: 조병순 | I12: 010-8804-1441 | J12: 모터 | K12: 19470 | L12: 9240 | M12: 1000 | N12: 7400 | O12: 전선 분류계근량 1,830kg 차감, 양중박스 2개 감량
A13: =ROW()-3 -> 10 | B13: 1-2 | C13: 46149 | D13: 포스코_KM_안산 | E13: 원방 | F13: 카고 | G13: 충남80아2457 | H13: 조병순 | I13: 010-8804-1441 | J13: 전선 | K13: 13890 | L13: 11560 | M13: 500 | N13: 1830 | O13: 지게차 분류계근, 양중박스 1개 감량
A14: =ROW()-3 -> 11 | B14: 1-1 | C14: 46151 | D14: 포스코_KM_안산 | E14: 원방 | F14: 카고 | G14: 충남80아2329 | J14: 작업철 | K14: 17840 | L14: 9870 | N14: 7090
A15: =ROW()-3 -> 12 | B15: 1-2 | C15: 46151 | D15: 포스코_KM_안산 | E15: 원방 | F15: 카고 | G15: 충남80아2329 | J15: 신주 | K15: 11850 | L15: 11550 | N15: 300 | O15: 지게차 분류계근
A16: =ROW()-3 -> 13 | B16: 1-3 | C16: 46151 | D16: 포스코_KM_안산 | E16: 원방 | F16: 카고 | G16: 충남80아2329 | J16: 상동 | K16: 11730 | L16: 11550 | N16: 180 | O16: 지게차 분류계근
A17: =ROW()-3 -> 14 | B17: 1-4 | C17: 46151 | D17: 포스코_KM_안산 | E17: 원방 | F17: 카고 | G17: 충남80아2329 | J17: 전선 | K17: 11950 | L17: 11550 | N17: 400 | O17: 지게차 분류계근
A18: =ROW()-3 -> 15 | B18: 1-1 | C18: 46154 | D18: 포스코_KM_안산 | E18: 원방 | F18: 카고 | G18: 충남83아1609 | H18: 심재철 | I18: 010-9390-2824 | J18: 모터 | K18: 15480 | L18: 9520 | M18: 1500 | N18: 2020 | O18: 파란 양중박스 3개, 포스코 계근 5,940kg
A19: =ROW()-3 -> 16 | B19: 1-2 | C19: 46154 | D19: 포스코_KM_안산 | E19: 원방 | F19: 카고 | G19: 충남83아1609 | H19: 심재철 | I19: 010-9390-2824 | J19: 전선 | K19: 11730 | L19: 11520 | N19: =K19-L19-M19 -> 210 | O19: 지게차 분류계근
A20: =ROW()-3 -> 17 | B20: 1-3 | C20: 46154 | D20: 포스코_KM_안산 | E20: 원방 | F20: 카고 | G20: 충남83아1609 | H20: 심재철 | I20: 010-9390-2824 | J20: 전선 등 | K20: 13480 | L20: 11520 | M20: 500 | N20: =K20-L20-M20 -> 1460 | O20: 지게차 분류계근, 고철 일부 포함
A21: =ROW()-3 -> 18 | B21: 1-4 | C21: 46154 | D21: 포스코_KM_안산 | E21: 원방 | F21: 카고 | G21: 충남83아1609 | H21: 심재철 | I21: 010-9390-2824 | J21: 전선 등 | K21: 12790 | L21: 11520 | M21: 500 | N21: =K21-L21-M21 -> 770 | O21: 지게차 분류계근, 고철 일부 포함
A22: =ROW()-3 -> 19 | B22: 1 | C22: 46155 | D22: 포스코_KM_안산 | E22: 세화철강 | F22: 방통차 | G22: 경기90자2889 | J22: 고철(중량) | K22: 42920 | L22: 18700 | N22: 24220
A23: =ROW()-3 -> 20 | B23: 2 | C23: 46155 | D23: 포스코_KM_안산 | E23: 세화철강 | F23: 방통차 | G23: 경기80바7145 | J23: 고철(중량) | K23: 43200 | L23: 18520 | N23: 24680
A24: =ROW()-3 -> 21 | B24: 3-1 | C24: 46155 | D24: 포스코_KM_안산 | E24: 원방 | F24: 카고 | G24: 충남94바2021 | J24: 작업철 | K24: 12470 | L24: 8030 | M24: 1000 | N24: 2100 | O24: 포스코계근 동일, 전선 차감, 양중박스 2개 감량
A25: =ROW()-3 -> 22 | B25: 3-2 | C25: 46155 | D25: 포스코_KM_안산 | E25: 원방 | F25: 카고 | G25: 충남94바2021 | J25: 전선 | K25: 13390 | L25: 11550 | M25: 500 | N25: 1340 | O25: 지게차 계근, 양중박스 감량
A26: =ROW()-3 -> 23 | B26: 4 | C26: 46155 | D26: 포스코_KM_안산 | E26: 세화철강 | F26: 방통차 | G26: 충북91아2060 | J26: 고철(중량) | K26: 43960 | L26: 18140 | N26: 25820
A27: =ROW()-3 -> 24 | B27: 5 | C27: 46155 | D27: 포스코_KM_안산 | E27: 세화철강 | F27: 방통차 | G27: 서울82바4890 | J27: 고철(중량) | K27: 43520 | L27: 18460 | N27: 25060
A28: =ROW()-3 -> 25 | B28: 6 | C28: 46155 | D28: 포스코_KM_안산 | E28: 세화철강 | F28: 방통차 | G28: 서울88아4910 | J28: 고철(중량) | K28: 43200 | L28: 17940 | N28: 25260
A29: =ROW()-3 -> 26 | B29: 7 | C29: 46155 | D29: 포스코_KM_안산 | E29: 세화철강 | F29: 방통차 | G29: 인천80자1904 | H29: 배조성 | I29: 010-4737-6803 | J29: 고철(중량) | K29: 42920 | L29: 18540 | N29: 24380
A30: =ROW()-3 -> 27 | B30: 8 | C30: 46155 | D30: 포스코_KM_안산 | E30: 세화철강 | F30: 방통차 | G30: 인천80사7274 | J30: 고철(중량) | K30: 42760 | L30: 18300 | N30: 24460
A31: =ROW()-3 -> 28 | B31: 9 | C31: 46155 | D31: 포스코_KM_안산 | E31: 세화철강 | F31: 방통차 | G31: 경기90자2889 | J31: 고철(중량) | K31: 42660 | L31: 18580 | N31: 24080
A32: =ROW()-3 -> 29 | B32: 10 | C32: 46155 | D32: 포스코_KM_안산 | E32: 세화철강 | F32: 방통차 | G32: 경기80바7145 | J32: 고철(중량) | K32: 43320 | L32: 18360 | N32: 24960
A33: =ROW()-3 -> 30 | B33: 11 | C33: 46155 | D33: 포스코_KM_안산 | E33: 세화철강 | F33: 방통차 | G33: 서울87아8165 | J33: 고철(중량) | K33: 42880 | L33: 18500 | N33: 24380
A34: =ROW()-3 -> 31 | B34: 1 | C34: 46156 | D34: 포스코_KM_안산 | E34: 세화철강 | F34: 방통차 | G34: 서울87아8165 | J34: 고철(중량) | K34: 42800 | L34: 18500 | N34: =K34-L34-M34 -> 24300
A35: =ROW()-3 -> 32 | B35: 2 | C35: 46156 | D35: 포스코_KM_안산 | E35: 세화철강 | F35: 방통차 | G35: 서울82바4890 | J35: 고철(중량) | K35: 43060 | L35: 18500 | N35: =K35-L35-M35 -> 24560
A36: =ROW()-3 -> 33 | B36: 3 | C36: 46156 | D36: 포스코_KM_안산 | E36: 세화철강 | F36: 방통차 | G36: 경기80바7145 | J36: 고철(중량) | K36: 42500 | L36: 18380 | N36: =K36-L36-M36 -> 24120
A37: =ROW()-3 -> 34 | B37: 4 | C37: 46156 | D37: 포스코_KM_안산 | E37: 세화철강 | F37: 방통차 | G37: 서울88아4910 | J37: 고철(중량) | K37: 42660 | L37: 17920 | N37: =K37-L37-M37 -> 24740
A38: =ROW()-3 -> 35 | B38: 5 | C38: 46156 | D38: 포스코_KM_안산 | E38: 세화철강 | F38: 방통차 | G38: 인천80자1932 | H38: 이종화 | I38: 010-5396-9846 | J38: 고철(중량) | K38: 43580 | L38: 18400 | N38: =K38-L38-M38 -> 25180
A39: =ROW()-3 -> 36 | B39: 6 | C39: 46156 | D39: 포스코_KM_안산 | E39: 세화철강 | F39: 방통차 | G39: 인천80사7274 | J39: 고철(중량) | K39: 42360 | L39: 18420 | N39: =K39-L39-M39 -> 23940
A40: =ROW()-3 -> 37 | B40: 7 | C40: 46156 | D40: 포스코_KM_안산 | E40: 세화철강 | F40: 방통차 | G40: 경기80바6092 | J40: 고철(중량) | K40: 42060 | L40: 18800 | N40: =K40-L40-M40 -> 23260
...

Sheet 서식
A1: □ 스크랩 반입일보 (26/04/21~ )
M2: =SUBTOTAL(9,M4:M570) -> 0 | N2: =SUBTOTAL(9,N4:N570) -> 0
A3: NO (1) | B3: NO (2) | C3: 상차일 | D3: 프로젝트명 | E3: 하차지 | F3: 차종 | G3: 차량번호 | H3: 운전자 | I3: 연락처 | J3: 제품명 | K3: 총중량(kg) | L3: 공차중량(kg) | M3: 감량(kg) | N3: 입고량(kg) | O3: 비고
A4: =ROW()-3 -> 1 | B4: 1
A5: =ROW()-3 -> 2 | B5: 1
A6: =ROW()-3 -> 3 | N6: =K6-L6-M6 -> 0
A7: =ROW()-3 -> 4 | N7: =K7-L7-M7 -> 0
A8: =ROW()-3 -> 5 | N8: =K8-L8-M8 -> 0
A9: =ROW()-3 -> 6 | N9: =K9-L9-M9 -> 0
A10: =ROW()-3 -> 7 | N10: =K10-L10-M10 -> 0
A11: =ROW()-3 -> 8 | N11: =K11-L11-M11 -> 0
A12: =ROW()-3 -> 9 | N12: =K12-L12-M12 -> 0
A13: =ROW()-3 -> 10 | N13: =K13-L13-M13 -> 0
A14: =ROW()-3 -> 11 | N14: =K14-L14-M14 -> 0
A15: =ROW()-3 -> 12 | N15: =K15-L15-M15 -> 0
A16: =ROW()-3 -> 13 | N16: =K16-L16-M16 -> 0
A17: =ROW()-3 -> 14 | N17: =K17-L17-M17 -> 0
... A20: =ROW()-3 -> 17 | N20: =K20-L20-M20 -> 0
