Workbook
Name 슬라이서_거래처명: #N/A
Name 슬라이서_거래처명1: #N/A
Name 슬라이서_거래처명2: #N/A
Name 품목: [2]구분표!#REF!
Name 품목: [2]구분표!#REF!
Name 품목: [3]구분표!#REF!

Sheet 갑지
A1: ■ 월별 스크랩 출고현황 | F1: ■ 현장별 스크랩 출고 현황 | K1: ■ 현장별 폐기물 출고 현황
A3: NO. | B3: 프로젝트명 | C3: 스크랩 | H3: 스크랩 소계 | I3: 폐기물 | N3: 폐기물 소계 | O3: 총 출고량 | P3: 비고 | R3: NO. | S3: 프로젝트명 | T3: 스크랩 입고량 | U3: 스크랩 출고량 | V3: 스크랩 재고량 | W3: 스크랩 금액 | X3: 폐기물 입고량 | Y3: 폐기물 출고량 | Z3: 폐기물 재고량 | AA3: 폐기물 금액 | AB3: 총 재고량 (스크랩,폐기물) | AC3: 비 고
C4: 고철(세화, 선진) | D4: 스텐(대신) | E4: AL(다옴) | F4: 전선 외(다문) | G4: 기타 | I4: 주원 | J4: 주원(KM) | K4: 투플러스 | L4: 도솔환경 | M4: 기타
A5: =ROW()-4 -> 1 | B5: 포스코_KM_안산 | C5: =SUMIFS(스크랩출고량!$M$4:$M$287,스크랩출고량!$C$4:$C$287,갑지!$B5,스크랩출고량!$I$4:$I$287,"세화철강")+SUMIFS(스크랩출고량!$M$4:$M$287,스크랩출고량!$C$4:$C$287,갑지!$B5,스크랩출고량!$I$4:$I$287,"선진알앤디") -> 1728600 | D5: =SUMIFS(스크랩출고량!$M$4:$M$287,스크랩출고량!$C$4:$C$287,갑지!B5,스크랩출고량!$I$4:$I$287,"대신에스티에스") -> 48713 | E5: =SUMIFS(스크랩출고량!$M$4:$M$287,스크랩출고량!$C$4:$C$287,갑지!$B5,스크랩출고량!$I$4:$I$287,"다옴금속") -> 3591 | F5: =SUMIFS(스크랩출고량!$M$4:$M$287,스크랩출고량!$C$4:$C$287,갑지!$B5,스크랩출고량!$I$4:$I$287,"다문산업") -> 111200 | G5: =SUMIFS(스크랩출고량!$M$4:$M$287,스크랩출고량!$C$4:$C$287,갑지!$B5,스크랩출고량!$I$4:$I$287,"상지롤")+SUMIFS(스크랩출고량!$M$4:$M$287,스크랩출고량!$C$4:$C$287,갑지!$B5,스크랩출고량!$I$4:$I$287,"정민산업")+SUMIFS(스크랩출고량!$M$4:$M$287,스크랩출고량!$C$4:$C$287,갑지!$B5,스크랩출고량!$I$4:$I$287,"전진유압상사") -> -6740 | H5: =SUM(C5:G5) -> 1885364 | I5: =SUMIFS(#REF!,#REF!,$B5,#REF!,갑지!I$4) -> #REF! | J5: =SUMIFS(#REF!,#REF!,$B5,#REF!,갑지!J$4) -> #REF! | K5: =SUMIFS(#REF!,#REF!,$B5,#REF!,갑지!K$4) -> #REF! | L5: =SUMIFS(#REF!,#REF!,$B5,#REF!,갑지!L$4) -> #REF! | M5: =SUMIFS(#REF!,#REF!,$B5,#REF!,"화성조이켐") -> #REF! | N5: =SUM(I5:M5) -> #REF! | O5: =N5+H5 -> #REF! | R5: =ROW()-4 -> 1 | S5: 포스코_KM_안산 | T5: =[4]갑지!$E$5 -> 2184790 | U5: =H5 -> 1885364 | V5: =T5-U5 -> 299426 | W5: =SUMIF(스크랩출고량!$C$4:$C$287,갑지!$S5,스크랩출고량!$R$4:$R$287) -> 2.355549e+09 | X5: =[5]갑지!$H$5 -> 171750 | Y5: =N5 -> #REF! | Z5: =X5-Y5 -> #REF! | AA5: =SUMIF(#REF!,갑지!$S5,#REF!) -> #REF! | AB5: =V5+Z5 -> #REF!
A6: =ROW()-4 -> 2 | B6: 현대제철_대도_당진 | C6: =SUMIFS(스크랩출고량!$M$4:$M$287,스크랩출고량!$C$4:$C$287,갑지!$B6,스크랩출고량!$I$4:$I$287,"세화철강")+SUMIFS(스크랩출고량!$M$4:$M$287,스크랩출고량!$C$4:$C$287,갑지!$B6,스크랩출고량!$I$4:$I$287,"선진알앤디") -> 228610 | D6: =SUMIFS(스크랩출고량!$M$4:$M$287,스크랩출고량!$C$4:$C$287,갑지!B6,스크랩출고량!$I$4:$I$287,"대신에스티에스") -> 0 | E6: =SUMIFS(스크랩출고량!$M$4:$M$287,스크랩출고량!$C$4:$C$287,갑지!$B6,스크랩출고량!$I$4:$I$287,"다옴금속") -> 60 | F6: =SUMIFS(스크랩출고량!$M$4:$M$287,스크랩출고량!$C$4:$C$287,갑지!$B6,스크랩출고량!$I$4:$I$287,"다문산업") -> 1670 | H6: =SUM(C6:G6) -> 230340 | I6: =SUMIFS(#REF!,#REF!,$B6,#REF!,갑지!I$4) -> #REF! | J6: =SUMIFS(#REF!,#REF!,$B6,#REF!,갑지!J$4) -> #REF! | K6: =SUMIFS(#REF!,#REF!,$B6,#REF!,갑지!K$4) -> #REF! | L6: =SUMIFS(#REF!,#REF!,$B6,#REF!,갑지!L$4) -> #REF! | M6: =SUMIFS(#REF!,#REF!,$B6,#REF!,"화성조이켐") -> #REF! | N6: =SUM(I6:M6) -> #REF! | O6: =N6+H6 -> #REF! | R6: =ROW()-4 -> 2 | S6: 현대제철_대도_당진 | T6: =[4]갑지!$E$9 -> 36680 | U6: =H6 -> 230340 | V6: =T6-U6 -> -193660 | W6: =SUMIF(스크랩출고량!$C$4:$C$287,갑지!$S6,스크랩출고량!$R$4:$R$287) -> 127582860 | X6: =[5]갑지!$H$6 -> 180 | Y6: =N6 -> #REF! | Z6: =X6-Y6 -> #REF! | AA6: =SUMIF(#REF!,갑지!$S6,#REF!) -> #REF! | AB6: =V6+Z6 -> #REF!
A7: =ROW()-4 -> 3 | B7: 동우PL1린텍_크로스_평택 | C7: =SUMIFS(스크랩출고량!$M$4:$M$287,스크랩출고량!$C$4:$C$287,갑지!$B7,스크랩출고량!$I$4:$I$287,"세화철강")+SUMIFS(스크랩출고량!$M$4:$M$287,스크랩출고량!$C$4:$C$287,갑지!$B7,스크랩출고량!$I$4:$I$287,"선진알앤디") -> 127420 | D7: =SUMIFS(스크랩출고량!$M$4:$M$287,스크랩출고량!$C$4:$C$287,갑지!B7,스크랩출고량!$I$4:$I$287,"대신에스티에스") -> 16105 | E7: =SUMIFS(스크랩출고량!$M$4:$M$287,스크랩출고량!$C$4:$C$287,갑지!$B7,스크랩출고량!$I$4:$I$287,"다옴금속") -> 669 | F7: =SUMIFS(스크랩출고량!$M$4:$M$287,스크랩출고량!$C$4:$C$287,갑지!$B7,스크랩출고량!$I$4:$I$287,"다문산업") -> 0 | H7: =SUM(C7:G7) -> 144194 | I7: =SUMIFS(#REF!,#REF!,$B7,#REF!,갑지!I$4) -> #REF! | J7: =SUMIFS(#REF!,#REF!,$B7,#REF!,갑지!J$4) -> #REF! | K7: =SUMIFS(#REF!,#REF!,$B7,#REF!,갑지!K$4) -> #REF! | L7: =SUMIFS(#REF!,#REF!,$B7,#REF!,갑지!L$4) -> #REF! | M7: =SUMIFS(#REF!,#REF!,$B7,#REF!,"화성조이켐") -> #REF! | N7: =SUM(I7:M7) -> #REF! | O7: =N7+H7 -> #REF! | R7: =ROW()-4 -> 3 | S7: 동우PL1린텍_크로스_평택 | T7: =[4]갑지!$E$6 -> 92570 | U7: =H7 -> 144194 | V7: =T7-U7 -> -51624 | W7: =SUMIF(스크랩출고량!$C$4:$C$287,갑지!$S7,스크랩출고량!$R$4:$R$287) -> 93236660 | X7: =[5]갑지!$H$7 -> 17290 | Y7: =N7 -> #REF! | Z7: =X7-Y7 -> #REF! | AA7: =SUMIF(#REF!,갑지!$S7,#REF!) -> #REF! | AB7: =V7+Z7 -> #REF!
A8: =ROW()-4 -> 4 | B8: 대도_서울 상계동 | C8: =SUMIFS(스크랩출고량!$M$4:$M$287,스크랩출고량!$C$4:$C$287,"서울 상계동",스크랩출고량!$I$4:$I$287,"세화철강")+SUMIFS(스크랩출고량!$M$4:$M$287,스크랩출고량!$C$4:$C$287,"서울 상계동",스크랩출고량!$I$4:$I$287,"선진알앤디") -> 0 | D8: =SUMIFS(스크랩출고량!$M$4:$M$287,스크랩출고량!$C$4:$C$287,"서울 상계동",스크랩출고량!$I$4:$I$287,"대신에스티에스") -> 0 | E8: =SUMIFS(스크랩출고량!$M$4:$M$287,스크랩출고량!$C$4:$C$287,"서울 상계동",스크랩출고량!$I$4:$I$287,"다옴금속")+SUMIFS(스크랩출고량!$M$4:$M$287,스크랩출고량!$C$4:$C$287,"서울 상계동",스크랩출고량!$I$4:$I$287,"다옴금속_유리하이텍") -> 0 | F8: =SUMIFS(스크랩출고량!$M$4:$M$287,스크랩출고량!$C$4:$C$287,"서울 상계동",스크랩출고량!$I$4:$I$287,"다문산업") -> 0 | G8: =SUMIFS(스크랩출고량!$M$4:$M$287,스크랩출고량!$C$4:$C$287,"서울 상계동",스크랩출고량!$I$4:$I$287,"상록기전") -> 0 | H8: =SUM(C8:G8) -> 0 | I8: =SUMIFS(#REF!,#REF!,"서울 상계동",#REF!,갑지!I$4) -> #REF! | J8: =SUMIFS(#REF!,#REF!,"서울 상계동",#REF!,갑지!J$4) -> #REF! | K8: =SUMIFS(#REF!,#REF!,"서울 상계동",#REF!,갑지!K$4) -> #REF! | L8: =SUMIFS(#REF!,#REF!,"서울 상계동",#REF!,갑지!L$4) -> #REF! | M8: =SUMIFS(#REF!,#REF!,"서울 상계동",#REF!,갑지!M$4) -> #REF! | N8: =SUM(I8:M8) -> #REF! | O8: =N8+H8 -> #REF! | R8: =ROW()-4 -> 4 | S8: 대도_서울 상계동 | T8: =[4]갑지!$E$7 -> 62900 | U8: =H8 -> 0 | V8: =T8-U8 -> 62900 | W8: =SUMIF(스크랩출고량!$C$4:$C$287,"서울 상계동",스크랩출고량!$R$4:$R$287) -> 0 | X8: =[5]갑지!$H$8 -> 120 | Y8: =N8 -> #REF! | Z8: =X8-Y8 -> #REF! | AA8: =SUMIF(#REF!,갑지!$S8,#REF!) -> #REF! | AB8: =V8+Z8 -> #REF!
A9: =ROW()-4 -> 5 | B9: 현대_크로스_군산 | C9: =SUMIFS(스크랩출고량!$M$4:$M$287,스크랩출고량!$C$4:$C$287,갑지!$B9,스크랩출고량!$I$4:$I$287,"세화철강")+SUMIFS(스크랩출고량!$M$4:$M$287,스크랩출고량!$C$4:$C$287,갑지!$B9,스크랩출고량!$I$4:$I$287,"선진알앤디") -> 0 | D9: =SUMIFS(스크랩출고량!$M$4:$M$287,스크랩출고량!$C$4:$C$287,갑지!B9,스크랩출고량!$I$4:$I$287,"대신에스티에스") -> 0 | E9: =SUMIFS(스크랩출고량!$M$4:$M$287,스크랩출고량!$C$4:$C$287,갑지!$B9,스크랩출고량!$I$4:$I$287,"다옴금속") -> 0 | F9: =SUMIFS(스크랩출고량!$M$4:$M$287,스크랩출고량!$C$4:$C$287,갑지!$B9,스크랩출고량!$I$4:$I$287,"다문산업") -> 26390 | G9: =SUMIFS(스크랩출고량!$M$4:$M$287,스크랩출고량!$C$4:$C$287,갑지!$B9,스크랩출고량!$I$4:$I$287,"전진유압상사")+SUMIFS(스크랩출고량!$M$4:$M$287,스크랩출고량!$C$4:$C$287,갑지!$B9,스크랩출고량!$I$4:$I$287,"다온산업") -> 0 | H9: =SUM(C9:G9) -> 26390 | I9: =SUMIFS(#REF!,#REF!,$B9,#REF!,갑지!I$4) -> #REF! | J9: =SUMIFS(#REF!,#REF!,$B9,#REF!,갑지!J$4) -> #REF! | K9: =SUMIFS(#REF!,#REF!,$B9,#REF!,갑지!K$4) -> #REF! | L9: =SUMIFS(#REF!,#REF!,$B9,#REF!,갑지!L$4) -> #REF! | M9: =SUMIFS(#REF!,#REF!,$B9,#REF!,"화성조이켐") -> #REF! | N9: =SUM(I9:M9) -> #REF! | O9: =N9+H9 -> #REF! | R9: =ROW()-4 -> 5 | S9: 현대_크로스_군산 | T9: =[4]갑지!$E$10 -> 2244410 | U9: =H9 -> 26390 | V9: =T9-U9 -> 2218020 | W9: =SUMIF(스크랩출고량!$C$4:$C$287,갑지!$S9,스크랩출고량!$R$4:$R$287) -> 383410000 | X9: =[5]갑지!$H$9 -> 35880 | Y9: =N9 -> #REF! | Z9: =X9-Y9 -> #REF! | AA9: =SUMIF(#REF!,갑지!$S9,#REF!) -> #REF! | AB9: =V9+Z9 -> #REF!
A10: =ROW()-4 -> 6 | B10: 잠실동 실내철거 | C10: =SUMIFS(스크랩출고량!$M$4:$M$287,스크랩출고량!$C$4:$C$287,"서울 잠실동",스크랩출고량!$I$4:$I$287,"세화철강")+SUMIFS(스크랩출고량!$M$4:$M$287,스크랩출고량!$C$4:$C$287,"서울 잠실동",스크랩출고량!$I$4:$I$287,"선진알앤디") -> 2720 | D10: =SUMIFS(스크랩출고량!$M$4:$M$287,스크랩출고량!$C$4:$C$287,"서울 잠실동",스크랩출고량!$I$4:$I$287,"대신에스티에스") -> 0 | E10: =SUMIFS(스크랩출고량!$M$4:$M$287,스크랩출고량!$C$4:$C$287,"서울 잠실동",스크랩출고량!$I$4:$I$287,"다옴금속") -> 900 | F10: =SUMIFS(스크랩출고량!$M$4:$M$287,스크랩출고량!$C$4:$C$287,"서울 잠실동",스크랩출고량!$I$4:$I$287,"다문산업") -> 0 | H10: =SUM(C10:G10) -> 3620 | I10: =SUMIFS(#REF!,#REF!,"서울 잠실동",#REF!,갑지!I$4) -> #REF! | J10: =SUMIFS(#REF!,#REF!,"서울 잠실동",#REF!,갑지!J$4) -> #REF! | K10: =SUMIFS(#REF!,#REF!,"서울 잠실동",#REF!,갑지!K$4) -> #REF! | L10: =SUMIFS(#REF!,#REF!,"서울 잠실동",#REF!,갑지!L$4) -> #REF! | M10: =SUMIFS(#REF!,#REF!,"서울 잠실동",#REF!,"그린스톤산업") -> #REF! | N10: =SUM(I10:M10) -> #REF! | O10: =N10+H10 -> #REF! | P10: 기타 현장 | R10: =ROW()-4 -> 6 | S10: 잠실동 실내철거 | T10: =[4]갑지!$E$11 -> 4690 | U10: =H10 -> 3620 | V10: =T10-U10 -> 1070 | W10: =SUMIF(스크랩출고량!$C$4:$C$287,"서울 잠실동",스크랩출고량!$R$4:$R$287) -> 4597800 | X10: =[5]갑지!$H$10 -> 324930 | Y10: =N10 -> #REF! | Z10: =X10-Y10 -> #REF! | AA10: =SUMIF(#REF!,갑지!$S10,#REF!) -> #REF! | AB10: =V10+Z10 -> #REF! | AC10: 크로스에서 정산
A11: =ROW()-4 -> 7 | B11: LT메탈_대도_인천 | C11: =SUMIFS(스크랩출고량!$M$4:$M$287,스크랩출고량!$C$4:$C$287,갑지!$B11,스크랩출고량!$I$4:$I$287,"세화철강")+SUMIFS(스크랩출고량!$M$4:$M$287,스크랩출고량!$C$4:$C$287,갑지!$B11,스크랩출고량!$I$4:$I$287,"선진알앤디") -> 0 | D11: =SUMIFS(스크랩출고량!$M$4:$M$287,스크랩출고량!$C$4:$C$287,갑지!B11,스크랩출고량!$I$4:$I$287,"대신에스티에스") -> 0 | E11: =SUMIFS(스크랩출고량!$M$4:$M$287,스크랩출고량!$C$4:$C$287,갑지!$B11,스크랩출고량!$I$4:$I$287,"다옴금속")+SUMIFS(스크랩출고량!$M$4:$M$287,스크랩출고량!$C$4:$C$287,갑지!$B11,스크랩출고량!$I$4:$I$287,"다옴금속_유리하이텍") -> 0 | F11: =SUMIFS(스크랩출고량!$M$4:$M$287,스크랩출고량!$C$4:$C$287,갑지!$B11,스크랩출고량!$I$4:$I$287,"다문산업") -> 0 | H11: =SUM(C11:G11) -> 0 | I11: =SUMIFS(#REF!,#REF!,$B11,#REF!,갑지!I$4) -> #REF! | J11: =SUMIFS(#REF!,#REF!,$B11,#REF!,갑지!J$4) -> #REF! | K11: =SUMIFS(#REF!,#REF!,$B11,#REF!,갑지!K$4) -> #REF! | L11: =SUMIFS(#REF!,#REF!,$B11,#REF!,갑지!L$4) -> #REF! | M11: =SUMIFS(#REF!,#REF!,$B11,#REF!,"화성조이켐") -> #REF! | N11: =SUM(I11:M11) -> #REF! | O11: =N11+H11 -> #REF! | P11: 기타 현장 | R11: =ROW()-4 -> 7 | S11: LT메탈_대도_인천 | T11: =[4]갑지!$E$12 -> 58770 | U11: =H11 -> 0 | V11: =T11-U11 -> 58770 | W11: =SUMIF(스크랩출고량!$C$4:$C$287,갑지!$S11,스크랩출고량!$R$4:$R$287) -> 0 | X11: =[5]갑지!$H$11 -> 0 | Y11: =N11 -> #REF! | Z11: =X11-Y11 -> #REF! | AA11: =SUMIF(#REF!,갑지!$S11,#REF!) -> #REF! | AB11: =V11+Z11 -> #REF!
A12: =ROW()-4 -> 8 | B12: LT메탈 남동공장 | R12: =ROW()-4 -> 8 | S12: LT메탈 남동공장 | T12: =[4]갑지!$E$8 -> 18410
A13: =ROW()-4 -> 9 | B13: 종료 현장 | C13: =C14-SUM(C5:C11) -> 123020 | D13: =D14-SUM(D5:D11) -> 25042 | E13: =E14-SUM(E5:E11) -> 37180 | F13: =F14-SUM(F5:F11) -> 13140 | G13: =스크랩출고량!#REF!-SUM(갑지!C14:F14)-SUM(갑지!G5:G11) -> #REF! | H13: =SUM(C13:G13) -> #REF! | I13: 176770 | K13: 10750 | N13: =SUM(I13:M13) -> 187520 | O13: =N13+H13 -> #REF! | R13: =ROW()-4 -> 9 | S13: 종료 현장 | T13: =[4]갑지!$E$13 -> 2593890 | U13: =H13 -> #REF! | W13: =스크랩출고량!#REF!-SUM(갑지!W5:W11) -> #REF! | X13: =[5]갑지!$H$12 -> 0 | Y13: =N13 -> 187520 | AA13: =SUMIF(#REF!,갑지!$S13,#REF!) -> #REF! | AB13: 554401
A14: 총 합계 | C14: =SUMIF(스크랩출고량!$I$4:$I$287,"세화철강",스크랩출고량!$M$4:$M$287)+SUMIF(스크랩출고량!$I$4:$I$287,"선진알앤디",스크랩출고량!$M$4:$M$287)+SUMIF(스크랩출고량!$I$4:$I$287,"세화철강_크로스특수",스크랩출고량!$M$4:$M$287)+SUMIF(스크랩출고량!$I$4:$I$287,"세화철강_투플러스",스크랩출고량!$M$4:$M$287) -> 2210370 | D14: =SUMIF(스크랩출고량!$I$4:$I$287,"대신에스티에스",스크랩출고량!$M$4:$M$287) -> 89860 | E14: =SUMIF(스크랩출고량!$I$4:$I$287,"다옴금속",스크랩출고량!$M$4:$M$287)+SUMIF(스크랩출고량!$I$4:$I$287,"다옴금속_유리하이텍",스크랩출고량!$M$4:$M$287)+SUMIF(스크랩출고량!$I$4:$I$287,"다옴메탈",스크랩출고량!$M$4:$M$287)+SUMIF(스크랩출고량!$I$4:$I$287,"다옴메탈_유리하이텍",스크랩출고량!$M$4:$M$287) -> 42400 | F14: =SUMIF(스크랩출고량!$I$4:$I$287,"다문산업",스크랩출고량!$M$4:$M$287)+SUMIF(스크랩출고량!$I$4:$I$287,"다문산업_크로스특수",스크랩출고량!$M$4:$M$287) -> 152400 | G14: =SUM(G5:G13) -> #REF! | H14: =SUM(H5:H13) -> #REF! | I14: =SUM(I5:I13) -> #REF! | J14: =SUM(J5:J13) -> #REF! | K14: =SUM(K5:K13) -> #REF! | L14: =SUM(L5:L13) -> #REF! | M14: =SUM(M5:M13) -> #REF! | N14: =SUM(N5:N13) -> #REF! | O14: =SUM(O5:O13) -> #REF!
A15: ※ 종료된 현장 제외 | P15: 단위 : kg
A16: 거래처명 | B16: (모두) | F16: 제품명 | G16: (모두)
A17: 프로젝트명 | B17: (모두) | F17: 거래처명 | G17: (모두) | K17: 배출자 | L17: (모두)
A19: 출고일(년, 월) | B19: 원방 실중량(kg) | C19: 정산중량(kg) | D19: 정산 금액(원) | F19: 프로젝트명 | G19: 원방 실중량(kg) | H19: 정산중량(kg) | I19: 정산금액(원) | K19: 프로젝트명 | L19: 원방 실중량(kg) | M19: 정산중량(kg) | N19: 정산금액(원)
A20: 2025년 | B20: 33900 | C20: 33870 | D20: 67367470 | F20: LT메탈 남동공장 | G20: 12230 | H20: 12807 | I20: 18044700 | K20: 기타 현장 | L20: 2830 | M20: 2830 | N20: 0
A21: 9월 | B21: 33900 | C21: 33870 | D21: 67367470 | F21: 대도_서울 상계동 | G21: 41700 | H21: 41660 | I21: 41579000 | K21: 동우PL1린텍_크로스_평택 | L21: 467740 | M21: 468080 | N21: -67893500
A22: 2026년 | B22: 2525310 | C22: 2522771.5 | D22: 3.2564344e+09 | F22: 동우PL1린텍_크로스_평택 | G22: 144194 | H22: 143956 | I22: 93236660 | K22: 포스코_KM_안산 | L22: 189850 | M22: 195940 | N22: -35739925
A23: 5월 | B23: 2161310 | C23: 2160102.5 | D23: 2.3853014e+09 | F23: 삼성_대도_온양 | G23: 2070 | H23: 2070 | I23: 4243500 | K23: 혼합 | L23: 13640 | M23: 13640 | N23: -2318800
A24: 6월 | B24: 364000 | C24: 362669 | D24: 871132970 | F24: 포스코_KM_안산 | G24: 1951924 | H24: 1949057 | I24: 2.355549e+09 | K24: 삼성전자_이텍솔루션_안성 | L24: 3860 | M24: 3860 | N24: 0
A25: 총합계 | B25: 2559210 | C25: 2556641.5 | D25: 3.3238019e+09 | F25: 현대_크로스_군산 | G25: 26390 | H25: 27347 | I25: 383410000 | K25: 총합계 | L25: 677920 | M25: 684350 | N25: -105952225
F26: 현대제철_대도_당진 | G26: 230340 | H26: 230094 | I26: 127582860
F27: 듀폰 천안공장 | G27: 9130 | H27: 9130 | I27: 5285900
F28: 삼성전자_이텍솔루션_안성 | G28: 72418 | H28: 72049 | I28: 139260750
F29: 에코코리아 | G29: 2392 | H29: 2392 | I29: 10664000
F30: 총합계 | G30: 2492788 | H30: 2490562 | I30: 3.1788564e+09
F34: ■ 현장별 제품별 출고 현황 | K34: ■ 현장별 재고 현황
F36: 프로젝트명 | G36: 삼성전자_이텍솔루션_안성 | K36: 프로젝트명 | L36: 입고량 | M36: 스크랩 출고량 | N36: 폐기물 출고량 | O36: 재고량
K37: 삼성전자_이텍솔루션_안성 | L37: =[6]갑지!$I$9 -> 118420 | M37: =VLOOKUP(K37,$F$19:$H$31,2,0) -> 72418 | N37: =VLOOKUP(K37,$K$19:$M$28,2,0) -> 3860 | O37: =L37-M37-N37 -> 42142
F38: 제품명 | G38: 원방 실중량(kg) | H38: 정산중량(kg) | I38: 합계 금액(원) | K38: 대도_서울 상계동 | L38: =[7]갑지!$I$5 -> 334930 | M38: =VLOOKUP(K38,$F$19:$H$31,2,0) -> 41700 | N38: 120 | O38: =L38-M38-N38 -> 293110
F39: STS304 | G39: 9090 | H39: 8709 | I39: 17853450 | K39: LT메탈 남동공장 | L39: =[6]갑지!$I$6 -> 18410 | M39: =VLOOKUP(K39,$F$19:$H$31,2,0) -> 12230 | O39: =L39-M39-N39 -> 6180
F40: 고철(경A) | G40: 11710 | H40: 11650 | I40: 5708500 | K40: 현대제철_대도_당진 | L40: =[6]갑지!$I$7 -> 265168 | M40: =VLOOKUP(K40,$F$19:$H$31,2,0) -> 230340 | N40: 180 | O40: =L40-M40-N40 -> 34648
F41: 고철(경A+B) | G41: 11160 | H41: 11040 | I41: 5409600 | K41: 동우PL1린텍_크로스_평택 | L41: =[6]갑지!$I$11 -> 700000 | M41: =VLOOKUP(K41,$F$19:$H$31,2,0) -> 144194 | N41: =VLOOKUP(K41,$K$19:$M$28,2,0) -> 467740 | O41: =L41-M41-N41 -> 88066
F42: 고철(경B) | G42: 9030 | H42: 8970 | I42: 4215900 | K42: 포스코_KM_안산 | L42: =[6]갑지!$I$10 -> 3881601 | M42: =VLOOKUP(K42,$F$19:$H$31,2,0) -> 1951924 | N42: =VLOOKUP(K42,$K$19:$M$28,2,0) -> 189850 | O42: =L42-M42-N42 -> 1739827
F43: 고철(중량) | G43: 7700 | H43: 7700 | I43: 3882500 | K43: 에코코리아 | L43: 2698 | M43: =VLOOKUP(K43,$F$19:$H$31,2,0) -> 2392 | O43: =L43-M43-N43 -> 306
F44: 설비부품 | G44: 60 | H44: 60 | I44: 0 | K44: 듀폰 천안공장 | L44: 15130 | M44: =VLOOKUP(K44,$F$19:$H$31,2,0) -> 9130 | O44: =L44-M44-N44 -> 6000
F45: 알판재 60 | G45: 7210 | H45: 7200 | I45: 29520000
F46: 알판재 A | G46: 12120 | H46: 12092 | I46: 53204800
...

Sheet 스크랩출고량
B1: 거래처별 출고 현황 (2025.09.26 ~ )
M2: =SUBTOTAL(9,M4:M287) -> 2559210 | N2: =SUBTOTAL(9,N4:N287) -> 2111594.5 | P2: =SUBTOTAL(9,P4:P287) -> 2556641.5 | R2: =SUBTOTAL(9,R4:R287) -> 3.3238019e+09
A3: NO. | B3: 계량일 | C3: 프로젝트명 | D3: 상차지 | E3: 차종 | F3: 차량번호 | G3: 운전자 | H3: 연락처 | I3: 거래처명 | J3: 제품명 | K3: 공차중량(kg) | L3: 총중량(kg) | M3: 실중량(kg) | N3: 거래처 감량 전 실중량(kg) | O3: 감량(kg) | P3: 정산 중량(kg) | Q3: 단가(원) | R3: 금액(원) | S3: 구분 | T3: 자회사 출고
A4: =ROW()-3 -> 1 | B4: 45926 | C4: 혼합 | E4: 집게차 | F4: 81오1758 | I4: 대신에스티에스 | J4: STS304 | K4: 19200 | L4: 24190 | M4: =L4-K4 -> 4990 | N4: 4770 | P4: 4770 | Q4: 1710 | R4: =Q4*P4 -> 8156700 | S4: 출고
A5: 1 | B5: =B4 -> 45926 | C5: =C4 -> 혼합 | E5: =E4 -> 집게차 | F5: =F4 -> 81오1758 | I5: 대신에스티에스 | J5: 저니켈강 | N5: 220 | P5: 220 | Q5: 300 | R5: =Q5*P5 -> 66000 | S5: =S4 -> 출고
A6: =ROW()-4 -> 2 | B6: 45926 | C6: 혼합 | E6: 집게차 | F6: 96로8332 | I6: 다문산업 | J6: 잡선 | K6: 12630 | L6: 13000 | M6: =L6-K6 -> 370 | N6: 370 | P6: =N6-O6 -> 370 | Q6: 3890 | R6: =Q6*P6 -> 1439300 | S6: 출고
A7: =ROW()-4 -> 3 | B7: 45926 | C7: =C6 -> 혼합 | E7: =E6 -> 집게차 | F7: =F6 -> 96로8332 | I7: 다문산업 | J7: 중선 | K7: 13000 | L7: 13240 | M7: =L7-K7 -> 240 | N7: 240 | P7: =N7-O7 -> 240 | Q7: 5130 | R7: =Q7*P7 -> 1231200 | S7: =S6 -> 출고
A8: =ROW()-4 -> 4 | B8: 45926 | C8: =C7 -> 혼합 | E8: =E7 -> 집게차 | F8: =F7 -> 96로8332 | I8: 다문산업 | J8: 상선 | K8: 13240 | L8: 13320 | M8: =L8-K8 -> 80 | N8: 80 | O8: 3 | P8: =N8-O8 -> 77 | Q8: 8360 | R8: =Q8*P8 -> 643720 | S8: =S7 -> 출고
A9: =ROW()-4 -> 5 | B9: 45926 | C9: =C8 -> 혼합 | E9: =E8 -> 집게차 | F9: =F8 -> 96로8332 | I9: 다문산업 | J9: A동 | K9: 13320 | L9: 14740 | M9: =L9-K9 -> 1420 | N9: 1420 | P9: =N9-O9 -> 1420 | Q9: 13400 | R9: =Q9*P9 -> 19028000 | S9: =S8 -> 출고
A10: =ROW()-4 -> 6 | B10: 45926 | C10: =C9 -> 혼합 | E10: =E9 -> 집게차 | F10: =F9 -> 96로8332 | I10: 다문산업 | J10: 상동 | K10: 14740 | L10: 15050 | M10: =L10-K10 -> 310 | N10: 240 | P10: =N10-O10 -> 240 | Q10: 12900 | R10: =Q10*P10 -> 3096000 | S10: =S9 -> 출고
A11: =ROW()-4 -> 7 | B11: 45926 | C11: =C10 -> 혼합 | E11: =E10 -> 집게차 | F11: =F10 -> 96로8332 | I11: 다문산업 | J11: 하동 | N11: 50 | P11: =N11-O11 -> 50 | Q11: 12000 | R11: =Q11*P11 -> 600000 | S11: =S10 -> 출고
A12: =ROW()-4 -> 8 | B12: 45926 | C12: =C11 -> 혼합 | E12: =E11 -> 집게차 | F12: =F11 -> 96로8332 | I12: 다문산업 | J12: 작업철(알모터) | K12: 15050 | L12: 19230 | M12: =L12-K12 -> 4180 | N12: 4190 | O12: 25 | P12: =N12-O12 -> 4165 | Q12: 2610 | R12: =Q12*P12 -> 10870650 | S12: =S11 -> 출고
A13: =ROW()-4 -> 9 | B13: 45926 | C13: =C12 -> 혼합 | E13: =E12 -> 집게차 | F13: =F12 -> 96로8332 | I13: 다문산업 | J13: 라지에이타 | K13: 19230 | L13: 20260 | M13: =L13-K13 -> 1030 | N13: 1040 | P13: 1050 | Q13: 6400 | R13: =Q13*P13 -> 6720000 | S13: =S12 -> 출고
A14: =ROW()-4 -> 10 | B14: 45926 | C14: =C13 -> 혼합 | E14: =E13 -> 집게차 | F14: =F13 -> 96로8332 | I14: 다문산업 | J14: 신주 1(잡A) | K14: 20260 | L14: 20600 | M14: =L14-K14 -> 340 | N14: 350 | O14: 13 | P14: =N14-O14 -> 337 | Q14: 8200 | R14: =Q14*P14 -> 2763400 | S14: =S13 -> 출고
A15: =ROW()-4 -> 11 | B15: 45926 | C15: =C14 -> 혼합 | E15: =E14 -> 집게차 | F15: =F14 -> 96로8332 | I15: 다문산업 | J15: 신주 2(작업신주) | K15: 20600 | L15: 20700 | M15: =L15-K15 -> 100 | N15: 100 | O15: 3 | P15: =N15-O15 -> 97 | Q15: 6500 | R15: =Q15*P15 -> 630500 | S15: =S14 -> 출고
A16: =ROW()-4 -> 12 | B16: 45926 | C16: =C15 -> 혼합 | E16: =E15 -> 집게차 | F16: =F15 -> 96로8332 | I16: 다문산업 | J16: 트랜스 | K16: 20700 | L16: 21240 | M16: =L16-K16 -> 540 | N16: 230 | O16: 3 | P16: =N16-O16 -> 227 | Q16: 1850 | R16: =Q16*P16 -> 419950 | S16: =S15 -> 출고
A17: =ROW()-4 -> 13 | B17: 45926 | C17: =C16 -> 혼합 | E17: =E16 -> 집게차 | F17: =F16 -> 96로8332 | I17: 다문산업 | J17: 고철 | N17: 310 | O17: 3 | P17: =N17-O17 -> 307 | Q17: 500 | R17: =Q17*P17 -> 153500 | S17: =S16 -> 출고
A18: =ROW()-4 -> 14 | B18: 45929 | C18: 혼합 | E18: 집게차 | F18: 87주8410 | I18: 세화철강 | J18: 고철(중량) | K18: 14070 | L18: 23360 | M18: =L18-K18 -> 9290 | N18: 9290 | P18: 9290 | Q18: 365 | R18: =Q18*P18 -> 3390850 | S18: 출고
A19: =ROW()-4 -> 15 | B19: 45929 | C19: 혼합 | E19: 집게차 | F19: 87주8410 | I19: 세화철강 | J19: 고철(중량) | M19: 9580 | N19: 9580 | P19: 9580 | Q19: 365 | R19: =Q19*P19 -> 3496700 | S19: 출고
A20: =ROW()-4 -> 16 | B20: 45930 | C20: 혼합 | E20: 집게차 | F20: 819도9774 | I20: 다옴금속 | J20: 프로파일 A | K20: 17770 | L20: 18910 | M20: =L20-K20 -> 1140 | P20: 1140 | Q20: 3300 | R20: =Q20*P20 -> 3762000 | S20: 출고
A21: =ROW()-4 -> 17 | B21: 45930 | C21: =C20 -> 혼합 | E21: 집게차 | F21: =F20 -> 819도9774 | I21: 다옴금속 | J21: 알판재 60 | K21: 18910 | L21: 19200 | M21: =L21-K21 -> 290 | P21: 290 | Q21: 3100 | R21: =Q21*P21 -> 899000 | S21: =S20 -> 출고
A22: =ROW()-4 -> 18 | B22: 46146 | C22: 포스코_KM_안산 | D22: 현장 | E22: 집게차 | F22: 87주8410 | G22: 배민국 | H22: 010-9110-0126 | I22: 선진알앤디 | J22: 고철(경B) | K22: 14080 | L22: 17880 | M22: =L22-K22 -> 3800 | N22: 3800 | P22: =N22 -> 3800 | Q22: 410 | R22: =Q22*P22 -> 1558000 | S22: 출고
A23: =ROW()-4 -> 19 | B23: 46146 | C23: 포스코_KM_안산 | D23: 원방 | E23: 집게차 | F23: 87주8410 | G23: 배민국 | H23: 010-9110-0126 | I23: 선진알앤디 | J23: 고철(경량) | K23: 14060 | L23: 18010 | M23: =L23-K23 -> 3950 | N23: 3910 | P23: =N23 -> 3910 | Q23: 410 | R23: =Q23*P23 -> 1603100 | S23: 출고
A24: =ROW()-4 -> 20 | B24: 46146 | C24: 포스코_KM_안산 | D24: 원방 | E24: 집게차 | F24: 87주8410 | G24: 배민국 | H24: 010-9110-0126 | I24: 선진알앤디 | J24: 고철(경량) | K24: 14090 | L24: 17180 | M24: =L24-K24 -> 3090 | N24: 3130 | P24: =N24 -> 3130 | Q24: 410 | R24: =Q24*P24 -> 1283300 | S24: 출고
A25: =ROW()-4 -> 21 | B25: 46146 | C25: 포스코_KM_안산 | D25: 원방 | E25: 집게차 | F25: 87주8410 | G25: 배민국 | H25: 010-9110-0126 | I25: 선진알앤디 | J25: 고철(경량) | K25: 14020 | L25: 17780 | M25: =L25-K25 -> 3760 | N25: 3760 | P25: =N25 -> 3760 | Q25: 410 | R25: =Q25*P25 -> 1541600 | S25: 출고
A26: =ROW()-4 -> 22 | B26: 46146 | C26: 포스코_KM_안산 | D26: 원방 | E26: 집게차 | F26: 87주8410 | G26: 배민국 | H26: 010-9110-0126 | I26: 선진알앤디 | J26: 고철(경량) | K26: 14030 | L26: 17650 | M26: =L26-K26 -> 3620 | N26: 3620 | P26: =N26 -> 3620 | Q26: 410 | R26: =Q26*P26 -> 1484200 | S26: 출고
A27: =ROW()-4 -> 23 | B27: 46146 | C27: 대도_서울 상계동 | D27: 원방 | E27: 집게차 | F27: 87주8410 | G27: 배민국 | H27: 010-9110-0126 | I27: 선진알앤디 | J27: 고철(경량) | K27: 14040 | L27: 16920 | M27: =L27-K27 -> 2880 | N27: 3040 | P27: =N27 -> 3040 | Q27: 410 | R27: =Q27*P27 -> 1246400 | S27: 출고
A28: =ROW()-4 -> 24 | B28: 46146 | C28: 서울 잠실동 | D28: 원방 | E28: 집게차 | F28: 87주8410 | G28: 배민국 | H28: 010-9110-0126 | I28: 선진알앤디 | J28: 고철(철근) | K28: 16920 | L28: 19640 | M28: =L28-K28 -> 2720 | N28: 2590 | P28: =N28 -> 2590 | Q28: 420 | R28: =Q28*P28 -> 1087800 | S28: =S27 -> 출고
A29: =ROW()-4 -> 25 | B29: 46147 | C29: 포스코_KM_안산 | D29: 현장 | E29: 집게차 | F29: 87주8410 | G29: 배민국 | H29: 010-9110-0126 | I29: 세화철강 | J29: 고철(경A) | K29: 14220 | L29: 17620 | M29: =L29-K29 -> 3400 | N29: 3370 | P29: =M29 -> 3400 | Q29: 420 | R29: =Q29*P29 -> 1428000 | S29: 출고
A30: =ROW()-4 -> 26 | B30: 46147 | C30: 포스코_KM_안산 | D30: 원방 | E30: 집게차 | F30: 87주8410 | G30: 배민국 | H30: 010-9110-0126 | I30: 대신에스티에스 | J30: STS316 | K30: 14070 | L30: 21810 | M30: =(L30-K30)*0.7 -> 5418 | N30: =7710*0.7 -> 5397 | O30: 9 | P30: =N30-O30 -> 5388 | Q30: 3800 | R30: =Q30*P30 -> 20474400 | S30: 출고
A31: =ROW()-4 -> 27 | B31: 46147 | C31: 듀폰3공장 | D31: 원방 | E31: 집게차 | F31: 87주8410 | G31: 배민국 | H31: 010-9110-0126 | I31: 대신에스티에스 | J31: STS316 | M31: =(L30-K30)*0.3 -> 2322 | N31: =(7710*0.3)-N32 -> 1213 | P31: =N31 -> 1213 | Q31: 3800 | R31: =Q31*P31 -> 4609400 | S31: =S30 -> 출고
A32: =ROW()-4 -> 28 | B32: 46147 | C32: 듀폰3공장 | D32: 원방 | E32: 집게차 | F32: 87주8410 | G32: 배민국 | H32: 010-9110-0126 | I32: 대신에스티에스 | J32: STS316장척 | N32: 1100 | P32: =N32 -> 1100 | Q32: 3750 | R32: =Q32*P32 -> 4125000 | S32: =S31 -> 출고
A33: =ROW()-4 -> 29 | B33: 46149 | C33: 대도_서울 상계동 | D33: 원방 | E33: 집게차 | F33: 87주8410 | G33: 배민국 | H33: 010-9110-0126 | I33: 대신에스티에스 | J33: STS304 | M33: 510 | N33: 510 | P33: =N33-O33 -> 510 | Q33: 1920 | R33: =Q33*P33 -> 979200 | S33: 출고
A34: =ROW()-4 -> 30 | B34: 46149 | C34: 포스코_KM_안산 | D34: 원방 | E34: 집게차 | F34: 87주8410 | G34: 배민국 | H34: 010-9110-0126 | I34: 대신에스티에스 | J34: STS304 | K34: 14050 | L34: 15840 | M34: =L34-K34 -> 1790 | N34: 1790 | P34: =N34-O34 -> 1790 | Q34: 1920 | R34: =Q34*P34 -> 3436800 | S34: =S33 -> 출고
A35: =ROW()-4 -> 31 | B35: 46149 | C35: 듀폰3공장 | D35: 원방 | E35: 집게차 | F35: 87주8410 | G35: 배민국 | H35: 010-9110-0126 | I35: 대신에스티에스 | J35: STS304 | K35: 16350 | L35: 19690 | M35: =L35-K35 -> 3340 | N35: 3270 | O35: 6 | P35: =N35-O35 -> 3264 | Q35: 1920 | R35: =Q35*P35 -> 6266880 | S35: =S34 -> 출고
A36: =ROW()-4 -> 32 | B36: 46149 | C36: 삼성물산 | D36: 원방 | E36: 집게차 | F36: 87주8410 | G36: 배민국 | H36: 010-9110-0126 | I36: 대신에스티에스 | J36: STS304CU | K36: 19680 | L36: 20930 | M36: =L36-K36 -> 1250 | N36: 1230 | O36: 9 | P36: =N36-O36 -> 1221 | Q36: 1650 | R36: =Q36*P36 -> 2014650 | S36: =S35 -> 출고
A37: =ROW()-4 -> 33 | B37: 46149 | C37: 포스코_KM_안산 | D37: 원방 | E37: 집게차 | F37: 96거5789 | G37: 배민국 | H37: 010-9110-0126 | I37: 대신에스티에스 | J37: STS304 | K37: 13450 | L37: 20340 | M37: =L37-K37 -> 6890 | N37: =6840-N38 -> 2430 | P37: =N37 -> 2430 | Q37: 1920 | R37: =Q37*P37 -> 4665600 | S37: 출고
A38: =ROW()-4 -> 34 | B38: 46149 | C38: 포스코_KM_안산 | D38: 원방 | E38: 집게차 | F38: 96거5789 | G38: 배민국 | H38: 010-9110-0126 | I38: 대신에스티에스 | J38: STS304장척 | N38: =1100+720+950+810+410+420 -> 4410 | P38: =N38 -> 4410 | Q38: 1850 | R38: =Q38*P38 -> 8158500 | S38: 출고
A39: =ROW()-4 -> 35 | B39: 46150 | C39: 포스코_KM_안산 | D39: 원방 | E39: 집게차 | F39: 87주8410 | G39: 배민국 | H39: 010-9110-0126 | I39: 선진알앤디 | J39: 고철(경A) | K39: 15150 | L39: 18380 | M39: 3230 | N39: 3460 | P39: 3460 | Q39: 420 | R39: =Q39*P39 -> 1453200 | S39: 출고
A40: =ROW()-4 -> 36 | B40: 46150 | C40: 대도_서울 상계동 | D40: 원방 | E40: 집게차 | F40: 87주8410 | G40: 배민국 | H40: 010-9110-0126 | I40: 선진알앤디 | J40: 고철(경A) | K40: 14060 | L40: 15150 | M40: 1090 | N40: 1090 | P40: 1090 | Q40: 420 | R40: =Q40*P40 -> 457800 | S40: =S39 -> 출고
...

Sheet 대신에스티에스
A2: 계량일 | B2: 프로젝트명 | C2: 상차지 | D2: 차종 | E2: 차량번호 | F2: 운전자 | G2: 연락처 | H2: 거래처명 | I2: 제품명 | J2: 공차중량(kg) | K2: 총중량(kg) | L2: 실중량(kg) | M2: 거래처 감량 전 실중량(kg) | N2: 감량(kg) | O2: 정산 중량(kg) | P2: 단가(원) | Q2: 금액(원) | R2: 구분 | S2: 비고 | T2: 입금일
A3: 45926 | B3: 혼합 | E3: 81오1758 | H3: 대신에스티에스 | I3: STS304 | J3: 19200 | K3: 24190 | L3: =K3-J3 -> 4990 | M3: 4770 | O3: 4770 | P3: 1710 | Q3: =P3*O3 -> 8156700 | R3: 출고 | T3: 9/29 입금
A4: =A3 -> 45926 | E4: =E3 -> 81오1758 | H4: 대신에스티에스 | I4: 저니켈강 | M4: 220 | O4: 220 | P4: 300 | Q4: =P4*O4 -> 66000
A5: 46147 | B5: 포스코_KM_안산 | C5: 원방 | D5: 집게차 | E5: 87주8410 | F5: 배민국 | G5: 010-9110-0126 | H5: 대신에스티에스 | I5: STS316 | J5: 14070 | K5: 21810 | L5: =(K5-J5)*0.7 -> 5418 | M5: =7710*0.7 -> 5397 | N5: 9 | O5: =M5-N5 -> 5388 | P5: 3800 | Q5: =P5*O5 -> 20474400 | R5: 출고 | S5: 마대 3개 9kg 감량 | T5: 5/7 입금
A6: 46147 | B6: 듀폰3공장 | C6: 원방 | D6: 집게차 | E6: 87주8410 | F6: 배민국 | G6: 010-9110-0126 | H6: 대신에스티에스 | I6: STS316 | L6: =(K5-J5)*0.3 -> 2322 | M6: =(7710*0.3)-M7 -> 1213 | O6: =M6 -> 1213 | P6: 3800 | Q6: =P6*O6 -> 4609400 | S6: 듀폰3공장(2025년 반출물), 기타현장으로 정리(4/28 SR5 분류계근 1,810kg포함)
A7: 46147 | B7: 듀폰3공장 | C7: 원방 | D7: 집게차 | E7: 87주8410 | F7: 배민국 | G7: 010-9110-0126 | H7: 대신에스티에스 | I7: STS316장척 | M7: 1100 | O7: =M7 -> 1100 | P7: 3750 | Q7: =P7*O7 -> 4125000 | S7: 검수 316장척
A8: 46149 | B8: 대도_서울 상계동 | C8: 원방 | D8: 집게차 | E8: 87주8410 | F8: 배민국 | G8: 010-9110-0126 | H8: 대신에스티에스 | I8: STS304 | L8: 510 | M8: 510 | O8: =M8-N8 -> 510 | P8: 1920 | Q8: =P8*O8 -> 979200 | R8: 출고 | S8: 4/22 분류계근량 입력 | T8: 5/14 입금
A9: 46149 | B9: 포스코_KM_안산 | C9: 원방 | D9: 집게차 | E9: 87주8410 | F9: 배민국 | G9: 010-9110-0126 | H9: 대신에스티에스 | I9: STS304 | J9: 14050 | K9: 15840 | L9: =K9-J9 -> 1790 | M9: 1790 | O9: =M9-N9 -> 1790 | P9: 1920 | Q9: =P9*O9 -> 3436800 | S9: 총중량에서 상계동 510kg 차감
A10: 46149 | B10: 듀폰3공장 | C10: 원방 | D10: 집게차 | E10: 87주8410 | F10: 배민국 | G10: 010-9110-0126 | H10: 대신에스티에스 | I10: STS304 | J10: 16350 | K10: 19690 | L10: =K10-J10 -> 3340 | M10: 3270 | N10: 6 | O10: =M10-N10 -> 3264 | P10: 1920 | Q10: =P10*O10 -> 6266880 | S10: 작년 재고, 마대 2개 감량
A11: 46149 | B11: 삼성물산 | C11: 원방 | D11: 집게차 | E11: 87주8410 | F11: 배민국 | G11: 010-9110-0126 | H11: 대신에스티에스 | I11: STS304CU | J11: 19680 | K11: 20930 | L11: =K11-J11 -> 1250 | M11: 1230 | N11: 9 | O11: =M11-N11 -> 1221 | P11: 1650 | Q11: =P11*O11 -> 2014650 | S11: 마대3개 감량
A12: 46149 | B12: 포스코_KM_안산 | C12: 원방 | D12: 집게차 | E12: 96거5789 | F12: 배민국 | G12: 010-9110-0126 | H12: 대신에스티에스 | I12: STS304 | J12: 13450 | K12: 20340 | L12: =K12-J12 -> 6890 | M12: =6840-M13 -> 2430 | O12: =M12 -> 2430 | P12: 1920 | Q12: =P12*O12 -> 4665600 | R12: 출고
A13: 46149 | B13: 포스코_KM_안산 | C13: 원방 | D13: 집게차 | E13: 96거5789 | F13: 배민국 | G13: 010-9110-0126 | H13: 대신에스티에스 | I13: STS304장척 | M13: =1100+720+950+810+410+420 -> 4410 | O13: =M13 -> 4410 | P13: 1850 | Q13: =P13*O13 -> 8158500 | R13: 출고 | S13: 5/8, 5/12 STS304장척 검수
A14: 46155 | B14: 삼성물산 | C14: 원방 | D14: 1톤트럭 | E14: 81구6225 | F14: 김태정 | G14: 010-3311-8084 | H14: 대신에스티에스 | I14: 모넬400 | J14: 2140 | K14: 2730 | L14: 590 | M14: 563.5 | N14: 3 | O14: =M14-N14 -> 560.5 | P14: 13000 | Q14: =O14*P14 -> 7286500 | R14: 출고 | S14: 마대 1개 감량 | T14: 5/19 입금
A15: 46155 | B15: 듀폰3공장 | C15: 원방 | D15: 1톤트럭 | E15: 81구6225 | F15: 김태정 | G15: 010-3311-8084 | H15: 대신에스티에스 | I15: C-22(하스텔로이) | J15: 2730 | K15: 3050 | L15: 320 | M15: 125.5 | O15: =M15-N15 -> 125.5 | P15: 18000 | Q15: =O15*P15 -> 2259000 | S15: 2025년 재고, 하스텔로이
A16: 46155 | B16: 듀폰3공장 | C16: 원방 | D16: 1톤트럭 | E16: 81구6225 | F16: 김태정 | G16: 010-3311-8084 | H16: 대신에스티에스 | I16: STS304 | M16: 185.5 | O16: =M16-N16 -> 185.5 | P16: 1900 | Q16: =O16*P16 -> 352450 | S16: 검수 STS304
A17: 46155 | B17: 포스코_KM_안산 | C17: 원방 | D17: 1톤트럭 | E17: 81구6225 | F17: 김태정 | G17: 010-3311-8084 | H17: 대신에스티에스 | I17: MO(몰디브덴) | J17: 3050 | K17: 3170 | L17: 120 | M17: 114 | N17: 3 | O17: =M17-N17 -> 111 | P17: 50000 | Q17: =O17*P17 -> 5550000 | S17: 마대 1개 감량, 몰디브덴
A18: 46160 | B18: 포스코_KM_안산 | C18: 현장 | D18: 집게차 | E18: 87주8410 | F18: 배민국 | G18: 010-9110-0126 | H18: 대신에스티에스 | I18: STS304 | J18: 14080 | K18: 19060 | L18: =K18-J18 -> 4980 | M18: =5000-M19 -> 4490 | N18: 3 | O18: =M18-N18 -> 4487 | P18: 1920 | Q18: =O18*P18 -> 8615040 | R18: 출고 | S18: 마대 1개 감량 | T18: 5/20 입금
A19: 46160 | B19: 포스코_KM_안산 | C19: 현장 | D19: 집게차 | E19: 87주8410 | F19: 배민국 | G19: 010-9110-0126 | H19: 대신에스티에스 | I19: 고철 | M19: 510 | O19: 510 | P19: 200 | Q19: =O19*P19 -> 102000 | S19: 검수 고철
A20: 46161 | B20: 포스코_KM_안산 | C20: 원방 | D20: 암롤트럭 | E20: 86노1445 | H20: 대신에스티에스 | I20: STS304 | J20: 20020 | K20: 25820 | L20: =K20-J20 -> 5800 | M20: =5780-150-240-580 -> 4810 | N20: 6 | O20: =M20-N20 -> 4804 | P20: 1920 | Q20: =O20*P20 -> 9223680 | R20: 출고 | S20: 마대 2개 감량
A21: 46161 | B21: 현대제철_대도_당진 | C21: 원방 | D21: 암롤트럭 | E21: 86노1445 | H21: 대신에스티에스 | I21: STS304 | M21: 240 | O21: 240 | P21: 1920 | Q21: =P21*O21 -> 460800 | S21: 4/29 당진 분류 STS304
A22: 46161 | B22: LT메탈 남동공장 | C22: 원방 | D22: 암롤트럭 | E22: 86노1445 | H22: 대신에스티에스 | I22: STS304 | M22: 580 | O22: 580 | P22: 1920 | Q22: =P22*O22 -> 1113600 | S22: 기타 현장
A23: 46161 | B23: 포스코_KM_안산 | C23: 원방 | D23: 암롤트럭 | E23: 86노1445 | H23: 대신에스티에스 | I23: 저니켈강 | M23: 150 | O23: 150 | P23: 250 | Q23: =O23*P23 -> 37500 | S23: 검수 저니켈강
A24: 46164 | B24: 포스코_KM_안산 | C24: 현장 | D24: 암롤트럭 | E24: 86노1445 | F24: 이민수 | G24: 010-8282-5885 | H24: 대신에스티에스 | I24: STS304(작업철) | J24: 20720 | K24: 33160 | L24: 12440 | M24: =12440-1260-740 -> 10440 | N24: 9 | O24: =M24-N24 -> 10431 | P24: 1500 | Q24: =P24*O24 -> 15646500 | R24: 출고 | S24: 대신에서 계근, 마대3개 감량, 열교환기 포함(단가 1,500원) | T24: 5/31자 발행 6/1 입금
A25: 46164 | B25: 포스코_KM_안산 | C25: 현장 | D25: 암롤트럭 | E25: 86노1445 | F25: 이민수 | G25: 010-8282-5885 | H25: 대신에스티에스 | I25: 고철 | M25: 1260 | O25: =M25 -> 1260 | P25: 200 | Q25: =P25*O25 -> 252000 | S25: 검수 고철
A26: 46164 | B26: 포스코_KM_안산 | C26: 현장 | D26: 암롤트럭 | E26: 86노1445 | F26: 이민수 | G26: 010-8282-5885 | H26: 대신에스티에스 | I26: 저니켈강 | M26: 740 | O26: =M26 -> 740 | P26: 250 | Q26: =P26*O26 -> 185000 | S26: 검수 저니켈강
A27: 46164 | B27: 포스코_KM_안산 | C27: 원방 | D27: 집게차 | E27: 87주8410 | F27: 배민국 | G27: 010-9110-0126 | H27: 대신에스티에스 | I27: STS310 | J27: 14090 | K27: 16810 | L27: 2720 | M27: =2690-2240 -> 450 | O27: =M27 -> 450 | P27: 4500 | Q27: =P27*O27 -> 2025000 | R27: 출고 | S27: 검수 304 차감 | T27: 5/29 입금
A28: 46164 | B28: 포스코_KM_안산 | C28: 원방 | D28: 집게차 | E28: 87주8410 | F28: 배민국 | G28: 010-9110-0126 | H28: 대신에스티에스 | I28: STS304 | M28: 2240 | O28: =M28 -> 2240 | P28: 1920 | Q28: =P28*O28 -> 4300800 | S28: 검수 STS304
A29: 46164 | B29: 포스코_KM_안산 | C29: 현장 | D29: 1톤트럭 | E29: 81구3225 | F29: 김태정 | G29: 010-3311-8084 | H29: 대신에스티에스 | I29: STS304롤 | J29: 2150 | K29: 3820 | L29: 1670 | M29: 1660 | O29: 1660 | P29: 1920 | Q29: =P29*O29 -> 3187200 | R29: 출고
A30: 46167 | B30: 동우PL1린텍_크로스_평택 | C30: 원방 | D30: 집게차 | E30: 84나4888 | F30: 김태정 | G30: 010-3311-8084 | H30: 대신에스티에스 | I30: STS304 | J30: 21010 | K30: 25100 | L30: =K30-J30 -> 4090 | M30: 4040 | O30: =M30 -> 4040 | P30: 1930 | Q30: =P30*O30 -> 7797200 | R30: 출고 | S30: 5/25부 10원 인상
A31: 46167 | B31: 동우PL1린텍_크로스_평택 | C31: 원방 | D31: 암롤트럭 | E31: 86노1445 | F31: 김태정 | G31: 010-3311-8084 | H31: 대신에스티에스 | I31: STS304 | J31: 20950 | K31: 25100 | L31: =K31-J31 -> 4150 | M31: =4090-140 -> 3950 | O31: =M31 -> 3950 | P31: 1930 | Q31: =P31*O31 -> 7623500 | R31: 출고 | S31: 검수 고철 차감
A32: 46167 | B32: 동우PL1린텍_크로스_평택 | C32: 원방 | D32: 암롤트럭 | E32: 86노1445 | F32: 김태정 | G32: 010-3311-8084 | H32: 대신에스티에스 | I32: 고철 | M32: 140 | O32: =M32 -> 140 | P32: 250 | Q32: =P32*O32 -> 35000 | S32: 검수 고철
A33: 46168 | B33: 포스코_KM_안산 | C33: 원방 | D33: 암롤트럭 | E33: 86노1445 | F33: 김태정 | G33: 010-3311-8084 | H33: 대신에스티에스 | I33: STS304 | J33: 20950 | K33: 26320 | L33: =K33-J33-1500 -> 3870 | M33: =3720-400 -> 3320 | O33: =M33 -> 3320 | P33: 1930 | Q33: =P33*O33 -> 6407600 | R33: 출고 | S33: 동우와 혼합 출고분, 검수고철 차감
A34: 46168 | B34: 포스코_KM_안산 | C34: 원방 | D34: 암롤트럭 | E34: 86노1445 | F34: 김태정 | G34: 010-3311-8084 | H34: 대신에스티에스 | I34: 고철 | M34: 400 | O34: =M34 -> 400 | P34: 250 | Q34: =P34*O34 -> 100000 | S34: 검수 고철
A35: 46168 | B35: 동우PL1린텍_크로스_평택 | C35: 원방 | D35: 암롤트럭 | E35: 86노1445 | F35: 김태정 | G35: 010-3311-8084 | H35: 대신에스티에스 | I35: STS304 | L35: 1500 | M35: 1500 | O35: =M35 -> 1500 | P35: 1930 | Q35: =P35*O35 -> 2895000
A36: 46174 | B36: 포스코_KM_안산 | C36: 원방 | D36: 집게차 | E36: 96거5789 | F36: 배민국 | G36: 010-9110-0126 | H36: 대신에스티에스 | I36: STS304 | J36: 13600 | K36: 14810 | L36: =(K36-J36)/2 -> 605 | M36: =1220/2 -> 610 | N36: 3 | O36: =M36-N36 -> 607 | P36: 2030 | Q36: =P36*O36 -> 1232210 | R36: 출고 | S36: 마대 1개 감량, 6/1부 100원 인상 | T36: 6/9 입금
A37: 46174 | B37: 동우PL1린텍_크로스_평택 | C37: 원방 | D37: 집게차 | E37: 96거5789 | F37: 배민국 | G37: 010-9110-0126 | H37: 대신에스티에스 | I37: STS304 | L37: =(K36-J36)/2 -> 605 | M37: =(1220/2)-210 -> 400 | N37: 3 | O37: =M37-N37 -> 397 | P37: 2030 | Q37: =P37*O37 -> 805910 | S37: 마대 1개 감량
A38: 46174 | B38: 동우PL1린텍_크로스_평택 | C38: 원방 | D38: 집게차 | E38: 96거5789 | F38: 배민국 | G38: 010-9110-0126 | H38: 대신에스티에스 | I38: 저니켈강 | M38: 210 | O38: 210 | P38: 250 | Q38: =P38*O38 -> 52500 | S38: 검수 저니켈강
A39: 46175 | B39: 포스코_KM_안산 | C39: 원방 | D39: 집게차 | E39: 87주8410 | F39: 배민국 | G39: 010-9110-0126 | H39: 대신에스티에스 | I39: STS400 | J39: 14400 | K39: 14700 | L39: =K39-J39 -> 300 | M39: 250 | O39: =M39-N39 -> 250 | P39: 700 | Q39: =P39*O39 -> 175000 | R39: 출고
A40: 46175 | B40: 포스코_KM_안산 | C40: 원방 | D40: 집게차 | E40: 87주8410 | F40: 배민국 | G40: 010-9110-0126 | H40: 대신에스티에스 | I40: STS316 | J40: 14700 | K40: 15390 | L40: =K40-J40 -> 690 | M40: 700 | N40: 3 | O40: =M40-N40 -> 697 | P40: 3900 | Q40: =P40*O40 -> 2718300 | S40: 마대 1개
A41: 46175 | B41: 포스코_KM_안산 | C41: 원방 | D41: 집게차 | E41: 87주8410 | F41: 배민국 | G41: 010-9110-0126 | H41: 대신에스티에스 | I41: STS310 | J41: 15390 | K41: 15700 | L41: =K41-J41 -> 310 | M41: 304 | N41: 3 | O41: =M41-N41 -> 301 | P41: 5100 | Q41: =P41*O41 -> 1535100 | S41: 마대 1개, 6/1 안산 분류계근
...

Sheet 다옴금속
A2: 계량일 | B2: 프로젝트명 | C2: 상차지 | D2: 차종 | E2: 차량번호 | F2: 운전자 | G2: 연락처 | H2: 거래처명 | I2: 제품명 | J2: 공차중량(kg) | K2: 총중량(kg) | L2: 실중량(kg) | M2: 거래처 감량 전 실중량(kg) | N2: 감량(kg) | O2: 정산 중량(kg) | P2: 단가(원) | Q2: 금액(원) | R2: 구분 | S2: 비고 | T2: 입금일
A3: 45930 | B3: 혼합 | E3: 819도9774 | H3: 다옴금속 | I3: 프로파일 A | J3: 17770 | K3: 18910 | L3: =K3-J3 -> 1140 | O3: 1140 | P3: 3300 | Q3: =P3*O3 -> 3762000 | R3: 출고 | T3: 9/30 입금
H4: 다옴금속 | I4: 알판재 60 | J4: 18910 | K4: 19200 | L4: =K4-J4 -> 290 | O4: 290 | P4: 3100 | Q4: =P4*O4 -> 899000
A5: 46153 | B5: 포스코_KM_안산 | C5: 원방 | D5: 최명동 집게차 | E5: 82모8185 | F5: 최명동 | H5: 다옴금속 | I5: 알루미늄 B | J5: 12930 | K5: 16020 | L5: =K5-J5-L6-L7-L8 -> 2030 | M5: 2030 | N5: 10 | O5: =M5-N5 -> 2020 | P5: 3900 | Q5: =P5*O5 -> 7878000 | R5: 출고 | S5: 분류계근 4/25 710kg, 5/4 230kg외 마대 5개 10kg 감량 | T5: 5/11 입금
A6: 46153 | B6: 서울 잠실동 | C6: 원방 | D6: 최명동 집게차 | E6: 82모8185 | F6: 최명동 | H6: 다옴금속 | I6: 알루미늄 B | L6: =120+780 -> 900 | M6: 900 | O6: 900 | P6: 3900 | Q6: =P6*O6 -> 3510000 | S6: 분류계근 4/29 120kg, 4/29 780kg예상
A7: 46153 | B7: 서울 상계동 | C7: 원방 | D7: 최명동 집게차 | E7: 82모8185 | F7: 최명동 | H7: 다옴금속 | I7: 알루미늄 B | L7: 100 | M7: 100 | O7: 100 | P7: 3900 | Q7: =P7*O7 -> 390000 | S7: 분류계근 4/23 10kg, 5/8 90kg
A8: 46153 | B8: 현대제철_대도_당진 | C8: 원방 | D8: 최명동 집게차 | E8: 82모8185 | F8: 최명동 | H8: 다옴금속 | I8: 알루미늄 B | L8: 60 | M8: 60 | O8: 60 | P8: 3900 | Q8: =P8*O8 -> 234000 | S8: 분류계근 5/9 60kg
A9: 46174 | B9: 포스코_KM_안산 | C9: 원방 | D9: 최명동 집게차 | E9: 82모8185 | F9: 최명동 | H9: 다옴금속 | I9: 알루미늄 B | J9: 13230 | K9: 15460 | L9: =(K9-J9)*0.7 -> 1561 | M9: 1561 | N9: 10 | O9: =M9-N9 -> 1551 | P9: 3900 | Q9: =P9*O9 -> 6048900 | R9: 출고 | S9: 일괄 안산으로 마대 5개 10kg 감량 | T9: 6/1 입금
A10: 46174 | B10: 동우PL1린텍_크로스_평택 | C10: 원방 | D10: 최명동 집게차 | E10: 82모8185 | F10: 최명동 | H10: 다옴금속 | I10: 알루미늄 B | L10: =(K9-J9)*0.3 -> 669 | M10: 669 | O10: =M10-N10 -> 669 | P10: 3900 | Q10: =P10*O10 -> 2609100
A11: 46191 | B11: 삼성전자_이텍솔루션_안성 | C11: 원방 | D11: 방통차 | E11: 전북86사3075 | F11: 이창민 | G11: 010-8369-1270 | H11: 다옴금속 | I11: 알판재 A | J11: 18740 | K11: 31860 | L11: =K11-J11-1000 -> 12120 | M11: 12120 | N11: 28 | O11: =M11-N11 -> 12092 | P11: 4400 | Q11: =O11*P11 -> 53204800 | R11: 출고 | S11: 마대 14개 28kg 감량 | T11: 6/18 입금
A12: 46191 | B12: 에코코리아 | C12: 원방 | D12: 방통차 | E12: 전북86사3075 | F12: 이창민 | G12: 010-8369-1270 | H12: 다옴금속 | I12: 알판재 A | L12: 1000 | M12: 1000 | O12: =M12-N12 -> 1000 | P12: 4400 | Q12: =O12*P12 -> 4400000
A13: 46191 | B13: 혼합 | C13: 원방 | D13: 방통차 | E13: 전북86사3075 | F13: 이창민 | G13: 010-8369-1270 | H13: 다옴금속 | I13: 알판재 B | J13: 31850 | K13: 34090 | L13: =K13-J13 -> 2240 | M13: 2240 | N13: 4 | O13: =M13-N13 -> 2236 | P13: 3900 | Q13: =O13*P13 -> 8720400 | R13: 출고 | S13: 마대 2개 4kg 감량
A14: 46198 | B14: 혼합 | C14: 원방 | D14: 집게차 | E14: 87주8410 | H14: 다옴메탈 | I14: A 샷시 | J14: 14200 | K14: 21550 | L14: =K14-J14 -> 7350 | M14: 7350 | N14: 26 | O14: =M14-N14 -> 7324 | P14: 4300 | Q14: =P14*O14 -> 31493200 | R14: 출고 | S14: 마대 13개 26kg 감량, 투플 물량 | T14: 7/2 입금
A15: 46203 | B15: 에코코리아 | C15: 원방 | D15: 카고 | E15: 경기84아5691 | F15: 이필선 | G15: 010-5877-2833 | H15: 다옴금속 | I15: 프로파일 A | L15: 1392 | M15: 1392 | O15: =M15-N15 -> 1392 | P15: 4500 | Q15: =O15*P15 -> 6264000 | R15: 출고 | S15: 삼성 이텍 3,808kg 차감 | T15: 6/30 입금
A16: 46203 | B16: 삼성전자_이텍솔루션_안성 | C16: 원방 | D16: 카고 | E16: 경기84아5691 | F16: 이필선 | G16: 010-5877-2833 | H16: 다옴금속 | I16: 프로파일 A | J16: 8550 | K16: 14280 | L16: =K16-J16-1392 -> 4338 | M16: 4338 | N16: 30 | O16: =M16-N16 -> 4308 | P16: 4500 | Q16: =O16*P16 -> 19386000 | S16: 마대 15개 30kg 감량, 에코코리아 1,392kg 차감
A17: 46203 | B17: 삼성전자_이텍솔루션_안성 | C17: 원방 | D17: 집게차 | E17: 82모8185 | F17: 최명동 | G17: 010-7997-2485 | H17: 다옴금속 | I17: 알판재 60 | J17: 13360 | K17: 20570 | L17: 7210 | M17: 7210 | N17: 10 | O17: =M17-N17 -> 7200 | P17: 4100 | Q17: =O17*P17 -> 29520000 | R17: 출고 | S17: 마대 5개 10kg 감량
S18: 6/30-451000
L19: =SUBTOTAL(9,L3:L18) -> 42400 | Q19: =SUBTOTAL(9,Q3:Q18) -> 178319400

Sheet 다문산업
A2: 계량일 | B2: 프로젝트명 | C2: 상차지 | D2: 차종 | E2: 차량번호 | F2: 운전자 | G2: 연락처 | H2: 거래처명 | I2: 제품명 | J2: 공차중량(kg) | K2: 총중량(kg) | L2: 실중량(kg) | M2: 거래처 감량 전 실중량(kg) | N2: 감량(kg) | O2: 정산 중량(kg) | P2: 단가(원) | Q2: 금액(원) | R2: 구분 | S2: 비고 | T2: 입금일
A3: 45926 | B3: 혼합 | E3: 96로8332 | H3: 다문산업 | I3: 잡선 | J3: 12630 | K3: 13000 | L3: =K3-J3 -> 370 | M3: 370 | O3: =M3-N3 -> 370 | P3: 3890 | Q3: =P3*O3 -> 1439300 | R3: 출고 | T3: 10/2 입금
H4: 다문산업 | I4: 중선 | J4: 13000 | K4: 13240 | L4: =K4-J4 -> 240 | M4: 240 | O4: =M4-N4 -> 240 | P4: 5130 | Q4: =P4*O4 -> 1231200
H5: 다문산업 | I5: 상선 | J5: 13240 | K5: 13320 | L5: =K5-J5 -> 80 | M5: 80 | N5: 3 | O5: =M5-N5 -> 77 | P5: 8360 | Q5: =P5*O5 -> 643720 | S5: 자루 1개
H6: 다문산업 | I6: A동 | J6: 13320 | K6: 14740 | L6: =K6-J6 -> 1420 | M6: 1420 | O6: =M6-N6 -> 1420 | P6: 13400 | Q6: =P6*O6 -> 19028000
H7: 다문산업 | I7: 상동 | J7: 14740 | K7: 15050 | L7: =K7-J7 -> 310 | M7: 240 | O7: =M7-N7 -> 240 | P7: 12900 | Q7: =P7*O7 -> 3096000
H8: 다문산업 | I8: 하동 | M8: 50 | O8: =M8-N8 -> 50 | P8: 12000 | Q8: =P8*O8 -> 600000 | S8: 업체 검수 계근
H9: 다문산업 | I9: 작업철(알모터) | J9: 15050 | K9: 19230 | L9: =K9-J9 -> 4180 | M9: 4190 | N9: 25 | O9: =M9-N9 -> 4165 | P9: 2610 | Q9: =P9*O9 -> 10870650 | S9: 자루 5개, 정산 시 차이 10kg 감량
H10: 다문산업 | I10: 라지에이타 | J10: 19230 | K10: 20260 | L10: =K10-J10 -> 1030 | M10: 1040 | O10: 1050 | P10: 6400 | Q10: =P10*O10 -> 6720000 | S10: 정산 시 차이 10kg 증량 정산
H11: 다문산업 | I11: 신주 1(잡A) | J11: 20260 | K11: 20600 | L11: =K11-J11 -> 340 | M11: 350 | N11: 13 | O11: =M11-N11 -> 337 | P11: 8200 | Q11: =P11*O11 -> 2763400 | S11: 자루 1개, 정산 시 차이 10kg 감량
H12: 다문산업 | I12: 신주 2(작업신주) | J12: 20600 | K12: 20700 | L12: =K12-J12 -> 100 | M12: 100 | N12: 3 | O12: =M12-N12 -> 97 | P12: 6500 | Q12: =P12*O12 -> 630500 | S12: 자루 1개
H13: 다문산업 | I13: 트랜스 | J13: 20700 | K13: 21240 | L13: =K13-J13 -> 540 | M13: 230 | N13: 3 | O13: =M13-N13 -> 227 | P13: 1850 | Q13: =P13*O13 -> 419950 | S13: 자루 1개
H14: 다문산업 | I14: 고철 | M14: 310 | N14: 3 | O14: =M14-N14 -> 307 | P14: 500 | Q14: =P14*O14 -> 153500 | S14: 자루 1개, 업체 검수 계근
A15: 46154 | B15: 포스코_KM_안산 | C15: 원방 | D15: 방통차 | E15: 충남94바3450 | F15: 구형서 | G15: 010-4889-4456 | H15: 다문산업 | I15: A동 | J15: 18360 | K15: 42030 | L15: =21620-2200 -> 19420 | M15: 19430 | O15: =L15 -> 19420 | P15: 19600 | Q15: =P15*O15 -> 380632000 | R15: 출고 | S15: 상계동, 군산 차감 후 | T15: 5/15 발행 5/15 5억 입금 5/18 4억 입금 외 분할 입금완료
A16: 46154 | B16: 대도_서울 상계동 | C16: 원방 | D16: 방통차 | E16: 충남94바3450 | F16: 구형서 | G16: 010-4889-4456 | H16: 다문산업 | I16: A동 | L16: 800 | M16: 800 | O16: 800 | P16: 19600 | Q16: =P16*O16 -> 15680000 | S16: 4/3 분류, 4/22 입고분 반영
A17: 46154 | B17: 현대_크로스_군산 | C17: 원방 | D17: 방통차 | E17: 충남94바3450 | F17: 구형서 | G17: 010-4889-4456 | H17: 다문산업 | I17: A동 | L17: =1250+2200 -> 3450 | M17: 3450 | O17: =L17 -> 3450 | P17: 19600 | Q17: =P17*O17 -> 67620000 | S17: 3/26, 4/1, 4/20 분류계근, 4/9 이동 재고 반영
A18: 46154 | B18: 포스코_KM_안산 | C18: 원방 | D18: 방통차 | E18: 충남94바3450 | F18: 구형서 | G18: 010-4889-4456 | H18: 다문산업 | I18: A동 | J18: 42030 | K18: 42970 | L18: 940 | M18: 940 | O18: 940 | P18: 19600 | Q18: =P18*O18 -> 18424000
A19: 46154 | B19: 포스코_KM_안산 | C19: 원방 | D19: 방통차 | E19: 전남80바2667 | F19: 김기용 | G19: 010-2811-2300 | H19: 다문산업 | I19: 캔디 | J19: 18780 | K19: 24690 | L19: 5910 | M19: 4930 | N19: 18 | O19: =M19-N19 -> 4912 | P19: 19200 | Q19: =P19*O19 -> 94310400 | R19: 출고 | S19: 자루 2개->6개
A20: 46154 | B20: 현대_크로스_군산 | C20: 원방 | D20: 방통차 | E20: 전남80바2667 | F20: 김기용 | G20: 010-2811-2300 | H20: 다문산업 | I20: 상동 | J20: 24690 | K20: 39200 | L20: 12080 | M20: =15500-M21-M22 -> 13070 | N20: 21 | O20: =M20-N20 -> 13049 | P20: 18800 | Q20: =P20*O20 -> 245321200 | S20: 3/23 ~ 4/9 분류계근 건 일부, 자루7개
A21: 46154 | B21: 포스코_KM_안산 | C21: 원방 | E21: 전남80바2667 | F21: 김기용 | G21: 010-2811-2300 | H21: 다문산업 | I21: 상동 | L21: 2150 | M21: 2150 | O21: 2150 | P21: 18800 | Q21: =P21*O21 -> 40420000 | S21: 4/8, 5/9 분류계근
A22: 46154 | B22: 대도_서울 상계동 | C22: 원방 | D22: 방통차 | E22: 전남80바2667 | F22: 김기용 | G22: 010-2811-2300 | H22: 다문산업 | I22: 상동 | L22: 280 | M22: 280 | O22: 280 | P22: 18800 | Q22: =P22*O22 -> 5264000 | S22: 4/3 분류계근 반영
A23: 46154 | B23: 포스코_KM_안산 | C23: 원방 | D23: 방통차 | E23: 전남86바1578 | F23: 김영윤 | G23: 010-3999-1056 | H23: 다문산업 | I23: 폐전선 | J23: 18160 | K23: 42940 | L23: 24780 | M23: 24960 | O23: 24780 | P23: =18000*0.47-500 -> 7960 | Q23: =P23*O23 -> 197248800 | R23: 출고 | S23: 수율 47%
A24: 46154 | B24: 현대_크로스_군산 | C24: 원방 | D24: 집게차 | E24: 89러0134 | F24: 다문산업 | H24: 다문산업 | I24: 잡선(47%) | J24: 12900 | K24: 16640 | L24: 1500 | M24: 1500 | O24: 1500 | P24: =18000*0.47-500 -> 7960 | Q24: =P24*O24 -> 11940000 | R24: 출고 | S24: 중동기준 단가
A25: 46154 | B25: 포스코_KM_안산 | C25: 원방 | D25: 집게차 | E25: 89러0134 | F25: 다문산업 | H25: 다문산업 | I25: 잡선(47%) | L25: 1230 | M25: 1250 | O25: 1230 | P25: =18000*0.47-500 -> 7960 | Q25: =P25*O25 -> 9790800 | S25: 군산, 당진 차감 후
A26: 46154 | B26: 현대제철_대도_당진 | C26: 원방 | D26: 집게차 | E26: 89러0134 | F26: 다문산업 | H26: 다문산업 | I26: 잡선(47%) | L26: 1010 | M26: 1010 | O26: 1010 | P26: =18000*0.47-500 -> 7960 | Q26: =P26*O26 -> 8039600 | S26: 5/11 분류계근 건
A27: 46154 | B27: 현대_크로스_군산 | C27: 원방 | D27: 집게차 | E27: 89러0134 | F27: 다문산업 | H27: 다문산업 | I27: 잡선(47%) | J27: 16640 | K27: 22260 | L27: 5620 | M27: 5620 | O27: 5620 | P27: =18000*0.47-500 -> 7960 | Q27: =P27*O27 -> 44735200 | S27: 현장에서 알려 줌
A28: 46154 | B28: 현대제철_대도_당진 | C28: 원방 | D28: 집게차 | E28: 89러0134 | F28: 다문산업 | H28: 다문산업 | I28: 단선_2mm선(65%) | J28: 22260 | K28: 23590 | L28: 660 | M28: 660 | N28: 6 | O28: 654 | P28: =19600*0.65-400 -> 12340 | Q28: =P28*O28 -> 8070360 | S28: 안산꺼 차감, 자루2개
A29: 46154 | B29: 포스코_KM_안산 | C29: 원방 | D29: 집게차 | E29: 89러0134 | F29: 다문산업 | H29: 다문산업 | I29: 단선_2mm선(65%) | L29: 670 | M29: 670 | N29: 21 | O29: 649 | P29: =19600*0.65-400 -> 12340 | Q29: =P29*O29 -> 8008660 | S29: 안산 반정도씩 담긴 7자루
A30: 46156 | B30: 포스코_KM_안산 | C30: 원방 | D30: 집게차 | E30: 89러0134 | F30: 다문산업 | H30: 다문산업 | I30: 트렌스 작업철 | J30: 12920 | K30: 22270 | L30: 5610 | M30: 5610 | N30: 21 | O30: 5589 | P30: 3700 | Q30: =P30*O30 -> 20679300 | R30: 출고 | S30: 안산 60%, 자루 7개 감량 | T30: 5/19 입금
A31: 46156 | B31: 현대_크로스_군산 | C31: 원방 | D31: 집게차 | E31: 89러0134 | F31: 다문산업 | H31: 다문산업 | I31: 트렌스 작업철 | L31: 3740 | M31: 3740 | N31: 12 | O31: 3728 | P31: 3700 | Q31: =P31*O31 -> 13793600 | S31: 군산 40%, 자루 4개 감량
A32: 46156 | B32: 포스코_KM_안산 | C32: 원방 | D32: 집게차 | E32: 89러0134 | F32: 다문산업 | H32: 다문산업 | I32: 중선 | J32: 22260 | K32: 25170 | L32: 2910 | M32: 2910 | N32: 39 | O32: 2871 | P32: 10600 | Q32: =P32*O32 -> 30432600 | S32: 자루 13개 감량
A33: 46156 | B33: 포스코_KM_안산 | C33: 원방 | D33: 집게차 | E33: 89러0134 | F33: 다문산업 | H33: 다문산업 | I33: 중동 | J33: 25170 | K33: 26770 | L33: 1600 | M33: 1620 | O33: 1600 | P33: 18200 | Q33: =P33*O33 -> 29120000
A34: 46175 | B34: 포스코_KM_안산 | C34: 원방 | D34: 집게차 | E34: 89러0134 | F34: 다문산업 | H34: 다문산업 | I34: A동 | J34: 12950 | K34: 15370 | L34: =K34-J34 -> 2420 | M34: 2420 | N34: 6 | O34: =L34-N34 -> 2414 | P34: 20100 | Q34: =P34*O34 -> 48521400 | R34: 출고 | S34: 자루 2개 | T34: 6/4 입금
A35: 46175 | B35: 포스코_KM_안산 | C35: 원방 | D35: 집게차 | E35: 89러0134 | F35: 다문산업 | H35: 다문산업 | I35: 캔디 | J35: 15370 | K35: 16130 | L35: =K35-J35-60 -> 700 | M35: 750 | N35: 3 | O35: =L35-N35 -> 697 | P35: 19700 | Q35: =P35*O35 -> 13730900 | S35: 자루 1개, 캔디에 상동 60kg 포함 상차
A36: 46175 | B36: 포스코_KM_안산 | C36: 원방 | D36: 집게차 | E36: 89러0134 | F36: 다문산업 | H36: 다문산업 | I36: 상동 | J36: 16130 | K36: 18970 | L36: =K36-J36+60 -> 2900 | M36: 2840 | N36: 27 | O36: =L36-N36 -> 2873 | P36: 19300 | Q36: =P36*O36 -> 55448900 | S36: 자루 9개, 캔디 상차 분 추가
A37: 46175 | B37: 포스코_KM_안산 | C37: 원방 | D37: 집게차 | E37: 89러0134 | F37: 다문산업 | H37: 다문산업 | I37: 잡선 | J37: 18970 | K37: 20930 | L37: =K37-J37 -> 1960 | M37: 1950 | N37: 15 | O37: =L37-N37 -> 1945 | P37: 6400 | Q37: =P37*O37 -> 12448000 | S37: 자루 5개, 중동 37% 작업비 450원 차감
A38: 46175 | B38: 포스코_KM_안산 | C38: 원방 | D38: 집게차 | E38: 89러0134 | F38: 다문산업 | H38: 다문산업 | I38: AL 라지에이타 | J38: 20930 | K38: 22810 | L38: =K38-J38 -> 1880 | M38: 1880 | N38: 6 | O38: =L38-N38 -> 1874 | P38: 9600 | Q38: =P38*O38 -> 17990400 | S38: 마대 2개
A39: 46176 | B39: 포스코_KM_안산 | C39: 원방 | D39: 집게차 | E39: 89러0134 | F39: 다문산업 | H39: 다문산업 | I39: 상동 | J39: 12920 | K39: 24130 | L39: =K39-J39 -> 11210 | M39: 11210 | N39: 3 | O39: =L39-N39 -> 11207 | P39: 19000 | Q39: =P39*O39 -> 212933000 | R39: 출고 | S39: 5/27~6/1 모터 분류 분, 자루 1개 | T39: 6/5 발행 6/8 입금
A40: 46176 | B40: 포스코_KM_안산 | C40: 원방 | D40: 집게차 | E40: 89러0134 | F40: 다문산업 | H40: 다문산업 | I40: 상동 | J40: 24130 | K40: 24180 | L40: =K40-J40 -> 50 | M40: 50 | N40: 3 | O40: =L40-N40 -> 47 | P40: 19000 | Q40: =P40*O40 -> 893000 | S40: 자루 1개
A41: 46176 | B41: 포스코_KM_안산 | C41: 원방 | D41: 카고 | E41: 경북82아6875 | H41: 다문산업 | I41: 아마추어 | J41: 15720 | K41: 29570 | L41: =K41-J41 -> 13850 | M41: 13850 | N41: 500 | O41: =L41-N41 -> 13350 | P41: 3700 | Q41: =P41*O41 -> 49395000 | R41: 출고
...

Sheet 세화철강
A2: 계량일 | B2: 프로젝트명 | C2: 상차지 | D2: 차종 | E2: 차량번호 | F2: 운전자 | G2: 연락처 | H2: 거래처명 | I2: 제품명 | J2: 공차중량(kg) | K2: 총중량(kg) | L2: 실중량(kg) | M2: 거래처 감량 전 실중량(kg) | N2: 감량(kg) | O2: 정산 중량(kg) | P2: 단가(원) | Q2: 금액(원) | R2: 구분 | S2: 비고 | T2: 입금일
A3: 45929 | B3: 혼합 | E3: 87주8410 | H3: 세화철강 | I3: 고철(중량) | J3: 14070 | K3: 23360 | L3: =K3-J3 -> 9290 | M3: 9350 | O3: 9290 | P3: 365 | Q3: =P3*O3 -> 3390850 | R3: 출고 | T3: 9/30 입금
A4: 45929 | B4: 혼합 | E4: 87주8410 | H4: 세화철강 | I4: 고철(중량) | L4: 9580 | M4: 9580 | O4: 9580 | P4: 365 | Q4: =P4*O4 -> 3496700 | R4: 출고 | S4: 원방 계근대 검사 중으로 업체 계근으로 정산
A5: 46147 | B5: 포스코_KM_안산 | C5: 현장 | D5: 집게차 | E5: 87주8410 | F5: 배민국 | G5: 010-9110-0126 | H5: 세화철강 | I5: 고철(경A) | J5: 14220 | K5: 17620 | L5: =K5-J5 -> 3400 | M5: 3370 | O5: =L5 -> 3400 | P5: 420 | Q5: =P5*O5 -> 1428000 | R5: 출고 | S5: 5/4부 중, 경량 10원, 5/7 10원 인상 | T5: 5/6 입금
A6: 46155 | B6: 포스코_KM_안산 | C6: 현장 | D6: 방통차 | E6: 경기90자2889 | H6: 세화철강 | I6: 고철(중량) | J6: 18700 | K6: 42920 | L6: =K6-J6 -> 24220 | M6: 24130 | O6: =L6 -> 24220 | P6: 480 | Q6: =P6*O6 -> 11625600 | R6: 출고 | S6: 5/12부 15원 인상 경량 455원, 중량 480원 | T6: 5/14 입금
A7: 46155 | B7: 포스코_KM_안산 | C7: 현장 | D7: 방통차 | E7: 경기80바7145 | H7: 세화철강 | I7: 고철(중량) | J7: 18520 | K7: 43200 | L7: =K7-J7 -> 24680 | M7: 24570 | O7: =L7 -> 24680 | P7: 480 | Q7: =P7*O7 -> 11846400 | R7: 출고
A8: 46155 | B8: 포스코_KM_안산 | C8: 현장 | D8: 방통차 | E8: 충북91아2060 | H8: 세화철강 | I8: 고철(중량) | J8: 18140 | K8: 43960 | L8: =K8-J8 -> 25820 | M8: 25720 | O8: =L8 -> 25820 | P8: 480 | Q8: =P8*O8 -> 12393600 | R8: 출고
A9: 46155 | B9: 포스코_KM_안산 | C9: 현장 | D9: 방통차 | E9: 서울82바4890 | H9: 세화철강 | I9: 고철(중량) | J9: 18460 | K9: 43520 | L9: =K9-J9 -> 25060 | M9: 24960 | O9: =L9 -> 25060 | P9: 480 | Q9: =P9*O9 -> 12028800 | R9: 출고
A10: 46155 | B10: 포스코_KM_안산 | C10: 현장 | D10: 방통차 | E10: 서울88아4910 | H10: 세화철강 | I10: 고철(중량) | J10: 17940 | K10: 43200 | L10: =K10-J10 -> 25260 | M10: 25150 | O10: =L10 -> 25260 | P10: 480 | Q10: =P10*O10 -> 12124800 | R10: 출고
A11: 46155 | B11: 포스코_KM_안산 | C11: 현장 | D11: 방통차 | E11: 인천80자1904 | F11: 배조성 | G11: 010-4737-6803 | H11: 세화철강 | I11: 고철(중량) | J11: 18540 | K11: 42920 | L11: =K11-J11 -> 24380 | M11: 24370 | O11: =L11 -> 24380 | P11: 480 | Q11: =P11*O11 -> 11702400 | R11: 출고
A12: 46155 | B12: 포스코_KM_안산 | C12: 현장 | D12: 방통차 | E12: 인천80사7274 | H12: 세화철강 | I12: 고철(중량) | J12: 18300 | K12: 42760 | L12: =K12-J12 -> 24460 | M12: 24400 | O12: =L12 -> 24460 | P12: 480 | Q12: =P12*O12 -> 11740800 | R12: 출고
A13: 46155 | B13: 포스코_KM_안산 | C13: 현장 | D13: 방통차 | E13: 경기90자2889 | H13: 세화철강 | I13: 고철(중량) | J13: 18580 | K13: 42660 | L13: =K13-J13 -> 24080 | M13: 23900 | O13: =L13 -> 24080 | P13: 480 | Q13: =P13*O13 -> 11558400 | R13: 출고
A14: 46155 | B14: 포스코_KM_안산 | C14: 현장 | D14: 방통차 | E14: 경기80바7145 | H14: 세화철강 | I14: 고철(중량) | J14: 18360 | K14: 43320 | L14: =K14-J14 -> 24960 | M14: 24940 | O14: =L14 -> 24960 | P14: 480 | Q14: =P14*O14 -> 11980800 | R14: 출고
A15: 46155 | B15: 포스코_KM_안산 | C15: 현장 | D15: 방통차 | E15: 서울87아8165 | H15: 세화철강 | I15: 고철(중량) | J15: 18500 | K15: 42880 | L15: =K15-J15 -> 24380 | M15: 24240 | O15: =L15 -> 24380 | P15: 480 | Q15: =P15*O15 -> 11702400 | R15: 출고
A16: 46156 | B16: 포스코_KM_안산 | C16: 현장 | D16: 방통차 | E16: 서울87아8165 | H16: 세화철강 | I16: 고철(중량) | J16: 18500 | K16: 42800 | L16: =K16-J16 -> 24300 | M16: 24260 | O16: =L16 -> 24300 | P16: 480 | Q16: =P16*O16 -> 11664000 | R16: 출고 | T16: 5/15 입금
A17: 46156 | B17: 포스코_KM_안산 | C17: 현장 | D17: 방통차 | E17: 서울82바4890 | H17: 세화철강 | I17: 고철(중량) | J17: 18500 | K17: 43060 | L17: =K17-J17 -> 24560 | M17: 24540 | O17: =L17 -> 24560 | P17: 480 | Q17: =P17*O17 -> 11788800 | R17: 출고
A18: 46156 | B18: 포스코_KM_안산 | C18: 현장 | D18: 방통차 | E18: 경기80바7145 | H18: 세화철강 | I18: 고철(중량) | J18: 18380 | K18: 42500 | L18: =K18-J18 -> 24120 | M18: 23950 | O18: =L18 -> 24120 | P18: 480 | Q18: =P18*O18 -> 11577600 | R18: 출고
A19: 46156 | B19: 포스코_KM_안산 | C19: 현장 | D19: 방통차 | E19: 서울88아4910 | H19: 세화철강 | I19: 고철(중량) | J19: 17920 | K19: 42660 | L19: =K19-J19 -> 24740 | M19: 24630 | O19: =L19 -> 24740 | P19: 480 | Q19: =P19*O19 -> 11875200 | R19: 출고
A20: 46156 | B20: 포스코_KM_안산 | C20: 현장 | D20: 방통차 | E20: 인천80자1932 | F20: 이종화 | G20: 010-5396-9846 | H20: 세화철강 | I20: 고철(중량) | J20: 18400 | K20: 43580 | L20: =K20-J20 -> 25180 | M20: 25110 | O20: =L20 -> 25180 | P20: 480 | Q20: =P20*O20 -> 12086400 | R20: 출고
A21: 46156 | B21: 포스코_KM_안산 | C21: 현장 | D21: 방통차 | E21: 인천80사7274 | H21: 세화철강 | I21: 고철(중량) | J21: 18420 | K21: 42360 | L21: =K21-J21 -> 23940 | M21: 23900 | O21: =L21 -> 23940 | P21: 480 | Q21: =P21*O21 -> 11491200 | R21: 출고
A22: 46156 | B22: 포스코_KM_안산 | C22: 현장 | D22: 방통차 | E22: 경기80바6092 | H22: 세화철강 | I22: 고철(중량) | J22: 18800 | K22: 42060 | L22: =K22-J22 -> 23260 | M22: 23220 | O22: =L22 -> 23260 | P22: 480 | Q22: =P22*O22 -> 11164800 | R22: 출고
A23: 46156 | B23: 포스코_KM_안산 | C23: 현장 | D23: 방통차 | E23: 서울87아8165 | H23: 세화철강 | I23: 고철(중량) | J23: 18460 | K23: 42120 | L23: =K23-J23 -> 23660 | M23: 23650 | O23: =L23 -> 23660 | P23: 480 | Q23: =P23*O23 -> 11356800 | R23: 출고
A24: 46156 | B24: 포스코_KM_안산 | C24: 현장 | D24: 방통차 | E24: 서울82바4890 | H24: 세화철강 | I24: 고철(중량) | J24: 18700 | K24: 43040 | L24: =K24-J24 -> 24340 | M24: 24290 | O24: =L24 -> 24340 | P24: 480 | Q24: =P24*O24 -> 11683200 | R24: 출고
A25: 46156 | B25: 포스코_KM_안산 | C25: 현장 | D25: 방통차 | E25: 경기80바7145 | H25: 세화철강 | I25: 고철(중량) | J25: 18500 | K25: 42840 | L25: =K25-J25 -> 24340 | M25: 24270 | O25: =L25 -> 24340 | P25: 480 | Q25: =P25*O25 -> 11683200 | R25: 출고
A26: 46157 | B26: 포스코_KM_안산 | C26: 현장 | D26: 방통차 | E26: 인천80자1904 | F26: 배조성 | G26: 010-4737-6803 | H26: 세화철강 | I26: 고철(중량) | J26: 18560 | K26: 43580 | L26: =K26-J26 -> 25020 | M26: 25010 | O26: =L26 -> 25020 | P26: 480 | Q26: =P26*O26 -> 12009600 | R26: 출고 | T26: 5/18 입금
A27: 46157 | B27: 포스코_KM_안산 | C27: 현장 | D27: 방통차 | E27: 인천85아5409 | F27: 김문중 | G27: 010-6667-8255 | H27: 세화철강 | I27: 고철(중량) | J27: 18240 | K27: 42480 | L27: =K27-J27 -> 24240 | M27: 24120 | O27: =L27 -> 24240 | P27: 480 | Q27: =P27*O27 -> 11635200 | R27: 출고
A28: 46157 | B28: 포스코_KM_안산 | C28: 현장 | D28: 방통차 | E28: 인천80자1932 | F28: 이종화 | G28: 010-5396-9846 | H28: 세화철강 | I28: 고철(중량) | J28: 18400 | K28: 43240 | L28: =K28-J28 -> 24840 | M28: 24800 | O28: =L28 -> 24840 | P28: 480 | Q28: =P28*O28 -> 11923200 | R28: 출고
A29: 46157 | B29: 포스코_KM_안산 | C29: 현장 | D29: 방통차 | E29: 서울87아7712 | F29: 김기범 | G29: 010-7700-7041 | H29: 세화철강 | I29: 고철(중량) | J29: 18740 | K29: 43220 | L29: =K29-J29 -> 24480 | M29: 24430 | O29: =L29 -> 24480 | P29: 480 | Q29: =P29*O29 -> 11750400 | R29: 출고
A30: 46157 | B30: 포스코_KM_안산 | C30: 현장 | D30: 방통차 | E30: 대구84아9559 | F30: 임상현 | G30: 010-4714-8294 | H30: 세화철강 | I30: 고철(중량) | J30: 18760 | K30: 42460 | L30: =K30-J30 -> 23700 | M30: 23610 | O30: =L30 -> 23700 | P30: 480 | Q30: =P30*O30 -> 11376000 | R30: 출고 | S30: 계근차 90kg
A31: 46157 | B31: 포스코_KM_안산 | C31: 현장 | D31: 방통차 | E31: 인천85바3859 | F31: 김태동 | G31: 010-7504-1068 | H31: 세화철강 | I31: 고철(중량) | J31: 18420 | K31: 43020 | L31: =K31-J31 -> 24600 | M31: 24510 | O31: =L31 -> 24600 | P31: 480 | Q31: =P31*O31 -> 11808000 | R31: 출고 | S31: 계근차 90kg
A32: 46158 | B32: 동우PL1린텍_크로스_평택 | C32: 현장 | D32: 집게차 | E32: 87주8410 | F32: 배민국 | G32: 010-9110-0126 | H32: 세화철강 | I32: 고철(경A) | J32: 13930 | K32: 17800 | L32: =K32-J32 -> 3870 | M32: 3850 | O32: =L32 -> 3870 | P32: 445 | Q32: =P32*O32 -> 1722150 | R32: 출고
A33: 46158 | B33: 포스코_KM_안산 | C33: 현장 | D33: 방통차 | E33: 서울88아3514 | F33: 박인규 | G33: 010-5332-9890 | H33: 세화철강 | I33: 고철(중량장척) | J33: 18520 | K33: 33300 | L33: =K33-J33 -> 14780 | M33: 14630 | O33: =L33 -> 14780 | P33: 460 | Q33: =P33*O33 -> 6798800 | R33: 출고
A34: 46158 | B34: 포스코_KM_안산 | C34: 현장 | D34: 방통차 | E34: 인천95바4643 | F34: 홍정희 | G34: 010-6224-9825 | H34: 세화철강 | I34: 고철(중량) | J34: 19060 | K34: 42140 | L34: =K34-J34 -> 23080 | M34: 23020 | O34: =L34 -> 23080 | P34: 480 | Q34: =P34*O34 -> 11078400 | R34: 출고
A35: 46158 | B35: 포스코_KM_안산 | C35: 현장 | D35: 방통차 | E35: 경기93자8201 | H35: 세화철강 | I35: 고철(중량장척) | J35: 18840 | K35: 33780 | L35: =K35-J35 -> 14940 | M35: 13460 | O35: =L35 -> 14940 | P35: 460 | Q35: =P35*O35 -> 6872400 | R35: 출고
A36: 46158 | B36: 포스코_KM_안산 | C36: 현장 | D36: 방통차 | E36: 경기80바6092 | H36: 세화철강 | I36: 고철(중량) | J36: 18840 | K36: 41780 | L36: =K36-J36 -> 22940 | M36: 22810 | O36: =L36 -> 22940 | P36: 480 | Q36: =P36*O36 -> 11011200 | R36: 출고
A37: 46158 | B37: 포스코_KM_안산 | C37: 현장 | D37: 방통차 | E37: 서울87아7712 | F37: 김기범 | G37: 010-7700-7041 | H37: 세화철강 | I37: 고철(중량장척) | J37: 18740 | K37: 31080 | L37: =K37-J37 -> 12340 | M37: 12320 | O37: =L37 -> 12340 | P37: 460 | Q37: =P37*O37 -> 5676400 | R37: 출고
A38: 46158 | B38: 포스코_KM_안산 | C38: 현장 | D38: 방통차 | E38: 대전89아7686 | F38: 김민욱 | G38: 010-7139-2998 | H38: 세화철강 | I38: 고철(중량장척) | J38: 18640 | K38: 32020 | L38: =K38-J38 -> 13380 | M38: 13340 | O38: =L38 -> 13380 | P38: 460 | Q38: =P38*O38 -> 6154800 | R38: 출고
A39: 46158 | B39: 포스코_KM_안산 | C39: 현장 | D39: 방통차 | E39: 인천85바9168 | F39: 최원곤 | G39: 010-6495-2983 | H39: 세화철강 | I39: 고철(중량장척) | J39: 18440 | K39: 33500 | L39: =K39-J39 -> 15060 | M39: 14890 | O39: =L39 -> 15060 | P39: 460 | Q39: =P39*O39 -> 6927600 | R39: 출고
A40: 46158 | B40: 포스코_KM_안산 | C40: 현장 | D40: 방통차 | E40: 충북91아2060 | H40: 세화철강 | I40: 고철(중량) | J40: 17960 | K40: 43060 | L40: =K40-J40 -> 25100 | M40: 25060 | O40: =L40 -> 25100 | P40: 480 | Q40: =P40*O40 -> 12048000 | R40: 출고
A41: 46158 | B41: 포스코_KM_안산 | C41: 현장 | D41: 방통차 | E41: 인천80아8306 | F41: 이용화 | G41: 010-3323-9265 | H41: 세화철강 | I41: 고철(중량장척) | J41: 18320 | K41: 33460 | L41: =K41-J41 -> 15140 | M41: 15000 | O41: =L41 -> 15140 | P41: 460 | Q41: =P41*O41 -> 6964400 | R41: 출고
...

Sheet 선진알앤디
A2: 계량일 | B2: 프로젝트명 | C2: 상차지 | D2: 차종 | E2: 차량번호 | F2: 운전자 | G2: 연락처 | H2: 거래처명 | I2: 제품명 | J2: 공차중량(kg) | K2: 총중량(kg) | L2: 실중량(kg) | M2: 거래처 감량 전 실중량(kg) | N2: 감량(kg) | O2: 정산 중량(kg) | P2: 단가(원) | Q2: 금액(원) | R2: 구분 | S2: 비고 | T2: 입금일
A3: 46146 | B3: 포스코_KM_안산 | C3: 포스코_KM_안산 | D3: 집게차 | E3: 87주8410 | F3: 배민국 | G3: 010-9110-0126 | H3: 선진알앤디 | I3: 고철(경B) | J3: 14080 | K3: 17880 | L3: =K3-J3 -> 3800 | M3: 3800 | O3: =M3 -> 3800 | P3: 410 | Q3: =P3*O3 -> 1558000 | R3: 출고 | S3: 원방에서 계근 후 직납 | T3: 5/6 입금
A4: 46146 | B4: 포스코_KM_안산 | C4: 원방 | D4: 집게차 | E4: 87주8410 | F4: 배민국 | G4: 010-9110-0126 | H4: 선진알앤디 | I4: 고철(경량) | J4: 14060 | K4: 18010 | L4: =K4-J4 -> 3950 | M4: 3910 | O4: =M4 -> 3910 | P4: 410 | Q4: =P4*O4 -> 1603100 | R4: 출고
A5: 46146 | B5: 포스코_KM_안산 | C5: 원방 | D5: 집게차 | E5: 87주8410 | F5: 배민국 | G5: 010-9110-0126 | H5: 선진알앤디 | I5: 고철(경량) | J5: 14090 | K5: 17180 | L5: =K5-J5 -> 3090 | M5: 3130 | O5: =M5 -> 3130 | P5: 410 | Q5: =P5*O5 -> 1283300 | R5: 출고
A6: 46146 | B6: 포스코_KM_안산 | C6: 원방 | D6: 집게차 | E6: 87주8410 | F6: 배민국 | G6: 010-9110-0126 | H6: 선진알앤디 | I6: 고철(경량) | J6: 14020 | K6: 17780 | L6: =K6-J6 -> 3760 | M6: 3760 | O6: =M6 -> 3760 | P6: 410 | Q6: =P6*O6 -> 1541600 | R6: 출고
A7: 46146 | B7: 포스코_KM_안산 | C7: 원방 | D7: 집게차 | E7: 87주8410 | F7: 배민국 | G7: 010-9110-0126 | H7: 선진알앤디 | I7: 고철(경량) | J7: 14030 | K7: 17650 | L7: =K7-J7 -> 3620 | M7: 3620 | O7: =M7 -> 3620 | P7: 410 | Q7: =P7*O7 -> 1484200 | R7: 출고
A8: 46146 | B8: 서울 상계동 | C8: 원방 | D8: 집게차 | E8: 87주8410 | F8: 배민국 | G8: 010-9110-0126 | H8: 선진알앤디 | I8: 고철(경량) | J8: 14040 | K8: 16920 | L8: =K8-J8 -> 2880 | M8: 3040 | O8: =M8 -> 3040 | P8: 410 | Q8: =P8*O8 -> 1246400 | R8: 출고
A9: 46146 | B9: 서울 잠실동 | C9: 원방 | D9: 집게차 | E9: 87주8410 | F9: 배민국 | G9: 010-9110-0126 | H9: 선진알앤디 | I9: 고철(철근) | J9: 16920 | K9: 19640 | L9: =K9-J9 -> 2720 | M9: 2590 | O9: =M9 -> 2590 | P9: 420 | Q9: =P9*O9 -> 1087800
A10: 46150 | B10: 포스코_KM_안산 | C10: 원방 | D10: 집게차 | E10: 87주8410 | F10: 배민국 | G10: 010-9110-0126 | H10: 선진알앤디 | I10: 고철(경A) | J10: 15150 | K10: 18380 | L10: 3230 | M10: 3460 | O10: 3460 | P10: 420 | Q10: =P10*O10 -> 1453200 | R10: 출고 | S10: 5/8 분류계근 건 입력, 5/9 출고 | T10: 5/12 입금
A11: 46150 | B11: 서울 상계동 | C11: 원방 | D11: 집게차 | E11: 87주8410 | F11: 배민국 | G11: 010-9110-0126 | H11: 선진알앤디 | I11: 고철(경A) | J11: 14060 | K11: 15150 | L11: 1090 | M11: 1090 | O11: 1090 | P11: 420 | Q11: =P11*O11 -> 457800 | S11: 5/8 분류계근 건 입력, 5/9 출고
A12: 46151 | B12: 포스코_KM_안산 | C12: 원방 | D12: 집게차 | E12: 87주8410 | F12: 배민국 | G12: 010-9110-0126 | H12: 선진알앤디 | I12: 고철(경A) | J12: 14160 | K12: 16830 | L12: =K12-J12 -> 2670 | M12: 3000 | O12: =M12 -> 3000 | P12: 420 | Q12: =P12*O12 -> 1260000 | R12: 출고 | S12: 5/7부 10원 인상
A13: 46151 | B13: 포스코_KM_안산 | C13: 원방 | D13: 집게차 | E13: 87주8410 | F13: 배민국 | G13: 010-9110-0126 | H13: 선진알앤디 | I13: 고철(경A) | J13: 14090 | K13: 17700 | L13: =K13-J13 -> 3610 | M13: 3600 | O13: =M13 -> 3600 | P13: 420 | Q13: =P13*O13 -> 1512000
A14: 46151 | B14: 현대제철_대도_당진 | C14: 원방 | D14: 집게차 | E14: 96거5789 | F14: 배민국 | G14: 010-9110-0126 | H14: 선진알앤디 | I14: 고철(경B) | J14: 14050 | K14: 15750 | L14: =K14-J14 -> 1700 | M14: 1720 | O14: =M14 -> 1720 | P14: 410 | Q14: =P14*O14 -> 705200
A15: 46164 | B15: 포스코_KM_안산 | C15: 원방 | D15: 집게차 | E15: 87주8410 | F15: 배민국 | G15: 010-9110-0126 | H15: 선진알앤디 | I15: 고철(경A) | J15: 14090 | K15: 19390 | L15: =K15-J15 -> 5300 | M15: 5280 | O15: =M15 -> 5280 | P15: 460 | Q15: =P15*O15 -> 2428800 | R15: 출고 | S15: 현장 혼합, 5/12 부 전품목 15원 인상 후 추가 인상 | T15: 5/26 입금
A16: 46167 | B16: 동우PL1린텍_크로스_평택 | C16: 원방 | D16: 집게차 | E16: 96거5789 | F16: 김현수 | G16: 010-5315-1508 | H16: 선진알앤디 | I16: 고철(경A) | J16: 13490 | K16: 18960 | L16: =K16-J16 -> 5470 | M16: 5450 | O16: =M16 -> 5450 | P16: 460 | Q16: =P16*O16 -> 2507000 | R16: 출고 | T16: 5/27 입금
